[2024-07-22T18:39:24.807+0000] {taskinstance.py:1979} INFO - Dependencies all met for dep_context=non-requeueable deps ti=<TaskInstance: stagingtodv.film_actor scheduled__2024-07-16T00:00:00+00:00 [queued]>
[2024-07-22T18:39:24.846+0000] {taskinstance.py:1979} INFO - Dependencies all met for dep_context=requeueable deps ti=<TaskInstance: stagingtodv.film_actor scheduled__2024-07-16T00:00:00+00:00 [queued]>
[2024-07-22T18:39:24.866+0000] {taskinstance.py:2193} INFO - Starting attempt 1 of 1
[2024-07-22T18:39:24.928+0000] {taskinstance.py:2217} INFO - Executing <Task(PythonOperator): film_actor> on 2024-07-16 00:00:00+00:00
[2024-07-22T18:39:24.945+0000] {standard_task_runner.py:60} INFO - Started process 95 to run task
[2024-07-22T18:39:24.971+0000] {standard_task_runner.py:87} INFO - Running: ['***', 'tasks', 'run', 'stagingtodv', 'film_actor', 'scheduled__2024-07-16T00:00:00+00:00', '--job-id', '32', '--raw', '--subdir', 'DAGS_FOLDER/dag.py', '--cfg-path', '/tmp/tmp37ejr249']
[2024-07-22T18:39:24.988+0000] {standard_task_runner.py:88} INFO - Job 32: Subtask film_actor
[2024-07-22T18:39:25.309+0000] {task_command.py:423} INFO - Running <TaskInstance: stagingtodv.film_actor scheduled__2024-07-16T00:00:00+00:00 [running]> on host ef8b8dee6045
[2024-07-22T18:39:26.866+0000] {taskinstance.py:2513} INFO - Exporting env vars: AIRFLOW_CTX_DAG_OWNER='***' AIRFLOW_CTX_DAG_ID='stagingtodv' AIRFLOW_CTX_TASK_ID='film_actor' AIRFLOW_CTX_EXECUTION_DATE='2024-07-16T00:00:00+00:00' AIRFLOW_CTX_TRY_NUMBER='1' AIRFLOW_CTX_DAG_RUN_ID='scheduled__2024-07-16T00:00:00+00:00'
[2024-07-22T18:39:26.870+0000] {logging_mixin.py:188} INFO - -------------------------------------------- select *  from etlconf.Etl_Process_Mapping where SourceTableName = 'film_actor' and Stage = 'stagingtodv'
[2024-07-22T18:39:26.950+0000] {taskinstance.py:2731} ERROR - Task failed with exception
Traceback (most recent call last):
  File "/home/airflow/.local/lib/python3.8/site-packages/airflow/models/taskinstance.py", line 444, in _execute_task
    result = _execute_callable(context=context, **execute_callable_kwargs)
  File "/home/airflow/.local/lib/python3.8/site-packages/airflow/models/taskinstance.py", line 414, in _execute_callable
    return execute_callable(context=context, **execute_callable_kwargs)
  File "/home/airflow/.local/lib/python3.8/site-packages/airflow/operators/python.py", line 200, in execute
    return_value = self.execute_callable()
  File "/home/airflow/.local/lib/python3.8/site-packages/airflow/operators/python.py", line 217, in execute_callable
    return self.python_callable(*self.op_args, **self.op_kwargs)
  File "/opt/airflow/dags/dag.py", line 41, in process_table
    tabletype = get_data_from_conf_table(table,stage)['tabletype'].values[0]
  File "/opt/airflow/dags/dag.py", line 34, in get_data_from_conf_table
    df.columns = [desc[0] for desc in cur.description]
  File "/home/airflow/.local/lib/python3.8/site-packages/pandas/core/generic.py", line 6002, in __setattr__
    return object.__setattr__(self, name, value)
  File "pandas/_libs/properties.pyx", line 69, in pandas._libs.properties.AxisProperty.__set__
  File "/home/airflow/.local/lib/python3.8/site-packages/pandas/core/generic.py", line 730, in _set_axis
    self._mgr.set_axis(axis, labels)
  File "/home/airflow/.local/lib/python3.8/site-packages/pandas/core/internals/managers.py", line 225, in set_axis
    self._validate_set_axis(axis, new_labels)
  File "/home/airflow/.local/lib/python3.8/site-packages/pandas/core/internals/base.py", line 70, in _validate_set_axis
    raise ValueError(
ValueError: Length mismatch: Expected axis has 0 elements, new values have 15 elements
[2024-07-22T18:39:26.986+0000] {taskinstance.py:1149} INFO - Marking task as FAILED. dag_id=stagingtodv, task_id=film_actor, execution_date=20240716T000000, start_date=20240722T183924, end_date=20240722T183926
[2024-07-22T18:39:27.058+0000] {standard_task_runner.py:107} ERROR - Failed to execute job 32 for task film_actor (Length mismatch: Expected axis has 0 elements, new values have 15 elements; 95)
[2024-07-22T18:39:27.102+0000] {local_task_job_runner.py:234} INFO - Task exited with return code 1
[2024-07-22T18:39:27.143+0000] {taskinstance.py:3312} INFO - 0 downstream tasks scheduled from follow-on schedule check
