[2024-07-16T17:23:42.497+0000] {taskinstance.py:1979} INFO - Dependencies all met for dep_context=non-requeueable deps ti=<TaskInstance: stagingtodv.film_actor scheduled__2024-07-15T00:00:00+00:00 [queued]>
[2024-07-16T17:23:42.534+0000] {taskinstance.py:1979} INFO - Dependencies all met for dep_context=requeueable deps ti=<TaskInstance: stagingtodv.film_actor scheduled__2024-07-15T00:00:00+00:00 [queued]>
[2024-07-16T17:23:42.538+0000] {taskinstance.py:2193} INFO - Starting attempt 1 of 1
[2024-07-16T17:23:42.563+0000] {taskinstance.py:2217} INFO - Executing <Task(PythonOperator): film_actor> on 2024-07-15 00:00:00+00:00
[2024-07-16T17:23:42.598+0000] {standard_task_runner.py:60} INFO - Started process 391 to run task
[2024-07-16T17:23:42.616+0000] {standard_task_runner.py:87} INFO - Running: ['***', 'tasks', 'run', 'stagingtodv', 'film_actor', 'scheduled__2024-07-15T00:00:00+00:00', '--job-id', '39', '--raw', '--subdir', 'DAGS_FOLDER/dag.py', '--cfg-path', '/tmp/tmpswynuchm']
[2024-07-16T17:23:42.629+0000] {standard_task_runner.py:88} INFO - Job 39: Subtask film_actor
[2024-07-16T17:23:42.823+0000] {task_command.py:423} INFO - Running <TaskInstance: stagingtodv.film_actor scheduled__2024-07-15T00:00:00+00:00 [running]> on host a8165c4616a2
[2024-07-16T17:23:43.017+0000] {taskinstance.py:2513} INFO - Exporting env vars: AIRFLOW_CTX_DAG_OWNER='***' AIRFLOW_CTX_DAG_ID='stagingtodv' AIRFLOW_CTX_TASK_ID='film_actor' AIRFLOW_CTX_EXECUTION_DATE='2024-07-15T00:00:00+00:00' AIRFLOW_CTX_TRY_NUMBER='1' AIRFLOW_CTX_DAG_RUN_ID='scheduled__2024-07-15T00:00:00+00:00'
[2024-07-16T17:23:43.030+0000] {logging_mixin.py:188} INFO - -------------------------------------------- select *  from etlconf.Etl_Process_Mapping where SourceTableName = 'film_actor' and Stage = 'stagingtodv'
[2024-07-16T17:23:43.109+0000] {taskinstance.py:2731} ERROR - Task failed with exception
Traceback (most recent call last):
  File "/home/airflow/.local/lib/python3.8/site-packages/airflow/models/taskinstance.py", line 444, in _execute_task
    result = _execute_callable(context=context, **execute_callable_kwargs)
  File "/home/airflow/.local/lib/python3.8/site-packages/airflow/models/taskinstance.py", line 414, in _execute_callable
    return execute_callable(context=context, **execute_callable_kwargs)
  File "/home/airflow/.local/lib/python3.8/site-packages/airflow/operators/python.py", line 200, in execute
    return_value = self.execute_callable()
  File "/home/airflow/.local/lib/python3.8/site-packages/airflow/operators/python.py", line 217, in execute_callable
    return self.python_callable(*self.op_args, **self.op_kwargs)
  File "/opt/airflow/dags/dag.py", line 41, in process_table
    tabletype = get_data_from_conf_table(table,stage)['tabletype'].values[0]
  File "/opt/airflow/dags/dag.py", line 34, in get_data_from_conf_table
    df.columns = [desc[0] for desc in cur.description]
  File "/home/airflow/.local/lib/python3.8/site-packages/pandas/core/generic.py", line 6002, in __setattr__
    return object.__setattr__(self, name, value)
  File "pandas/_libs/properties.pyx", line 69, in pandas._libs.properties.AxisProperty.__set__
  File "/home/airflow/.local/lib/python3.8/site-packages/pandas/core/generic.py", line 730, in _set_axis
    self._mgr.set_axis(axis, labels)
  File "/home/airflow/.local/lib/python3.8/site-packages/pandas/core/internals/managers.py", line 225, in set_axis
    self._validate_set_axis(axis, new_labels)
  File "/home/airflow/.local/lib/python3.8/site-packages/pandas/core/internals/base.py", line 70, in _validate_set_axis
    raise ValueError(
ValueError: Length mismatch: Expected axis has 0 elements, new values have 15 elements
[2024-07-16T17:23:44.757+0000] {taskinstance.py:1149} INFO - Marking task as FAILED. dag_id=stagingtodv, task_id=film_actor, execution_date=20240715T000000, start_date=20240716T172342, end_date=20240716T172344
[2024-07-16T17:23:44.824+0000] {standard_task_runner.py:107} ERROR - Failed to execute job 39 for task film_actor (Length mismatch: Expected axis has 0 elements, new values have 15 elements; 391)
[2024-07-16T17:23:44.926+0000] {local_task_job_runner.py:234} INFO - Task exited with return code 1
[2024-07-16T17:23:44.961+0000] {taskinstance.py:3312} INFO - 0 downstream tasks scheduled from follow-on schedule check
[2024-07-16T17:33:46.070+0000] {taskinstance.py:1979} INFO - Dependencies all met for dep_context=non-requeueable deps ti=<TaskInstance: stagingtodv.film_actor scheduled__2024-07-15T00:00:00+00:00 [queued]>
[2024-07-16T17:33:46.092+0000] {taskinstance.py:1979} INFO - Dependencies all met for dep_context=requeueable deps ti=<TaskInstance: stagingtodv.film_actor scheduled__2024-07-15T00:00:00+00:00 [queued]>
[2024-07-16T17:33:46.098+0000] {taskinstance.py:2193} INFO - Starting attempt 1 of 1
[2024-07-16T17:33:46.145+0000] {taskinstance.py:2217} INFO - Executing <Task(PythonOperator): film_actor> on 2024-07-15 00:00:00+00:00
[2024-07-16T17:33:46.150+0000] {standard_task_runner.py:60} INFO - Started process 121 to run task
[2024-07-16T17:33:46.175+0000] {standard_task_runner.py:87} INFO - Running: ['***', 'tasks', 'run', 'stagingtodv', 'film_actor', 'scheduled__2024-07-15T00:00:00+00:00', '--job-id', '14', '--raw', '--subdir', 'DAGS_FOLDER/dag.py', '--cfg-path', '/tmp/tmpu0eeechh']
[2024-07-16T17:33:46.206+0000] {standard_task_runner.py:88} INFO - Job 14: Subtask film_actor
[2024-07-16T17:33:46.446+0000] {task_command.py:423} INFO - Running <TaskInstance: stagingtodv.film_actor scheduled__2024-07-15T00:00:00+00:00 [running]> on host e9bb94dbac8b
[2024-07-16T17:33:47.848+0000] {taskinstance.py:2513} INFO - Exporting env vars: AIRFLOW_CTX_DAG_OWNER='***' AIRFLOW_CTX_DAG_ID='stagingtodv' AIRFLOW_CTX_TASK_ID='film_actor' AIRFLOW_CTX_EXECUTION_DATE='2024-07-15T00:00:00+00:00' AIRFLOW_CTX_TRY_NUMBER='1' AIRFLOW_CTX_DAG_RUN_ID='scheduled__2024-07-15T00:00:00+00:00'
[2024-07-16T17:33:47.852+0000] {logging_mixin.py:188} INFO - -------------------------------------------- select *  from etlconf.Etl_Process_Mapping where SourceTableName = 'film_actor' and Stage = 'stagingtodv'
[2024-07-16T17:33:47.903+0000] {taskinstance.py:2731} ERROR - Task failed with exception
Traceback (most recent call last):
  File "/home/airflow/.local/lib/python3.8/site-packages/airflow/models/taskinstance.py", line 444, in _execute_task
    result = _execute_callable(context=context, **execute_callable_kwargs)
  File "/home/airflow/.local/lib/python3.8/site-packages/airflow/models/taskinstance.py", line 414, in _execute_callable
    return execute_callable(context=context, **execute_callable_kwargs)
  File "/home/airflow/.local/lib/python3.8/site-packages/airflow/operators/python.py", line 200, in execute
    return_value = self.execute_callable()
  File "/home/airflow/.local/lib/python3.8/site-packages/airflow/operators/python.py", line 217, in execute_callable
    return self.python_callable(*self.op_args, **self.op_kwargs)
  File "/opt/airflow/dags/dag.py", line 41, in process_table
    tabletype = get_data_from_conf_table(table,stage)['tabletype'].values[0]
  File "/opt/airflow/dags/dag.py", line 34, in get_data_from_conf_table
    df.columns = [desc[0] for desc in cur.description]
  File "/home/airflow/.local/lib/python3.8/site-packages/pandas/core/generic.py", line 6002, in __setattr__
    return object.__setattr__(self, name, value)
  File "pandas/_libs/properties.pyx", line 69, in pandas._libs.properties.AxisProperty.__set__
  File "/home/airflow/.local/lib/python3.8/site-packages/pandas/core/generic.py", line 730, in _set_axis
    self._mgr.set_axis(axis, labels)
  File "/home/airflow/.local/lib/python3.8/site-packages/pandas/core/internals/managers.py", line 225, in set_axis
    self._validate_set_axis(axis, new_labels)
  File "/home/airflow/.local/lib/python3.8/site-packages/pandas/core/internals/base.py", line 70, in _validate_set_axis
    raise ValueError(
ValueError: Length mismatch: Expected axis has 0 elements, new values have 15 elements
[2024-07-16T17:33:47.936+0000] {taskinstance.py:1149} INFO - Marking task as FAILED. dag_id=stagingtodv, task_id=film_actor, execution_date=20240715T000000, start_date=20240716T173346, end_date=20240716T173347
[2024-07-16T17:33:47.989+0000] {standard_task_runner.py:107} ERROR - Failed to execute job 14 for task film_actor (Length mismatch: Expected axis has 0 elements, new values have 15 elements; 121)
[2024-07-16T17:33:48.034+0000] {local_task_job_runner.py:234} INFO - Task exited with return code 1
[2024-07-16T17:33:48.066+0000] {taskinstance.py:3312} INFO - 0 downstream tasks scheduled from follow-on schedule check
[2024-07-16T17:36:01.181+0000] {taskinstance.py:1979} INFO - Dependencies all met for dep_context=non-requeueable deps ti=<TaskInstance: stagingtodv.film_actor scheduled__2024-07-15T00:00:00+00:00 [queued]>
[2024-07-16T17:36:01.213+0000] {taskinstance.py:1979} INFO - Dependencies all met for dep_context=requeueable deps ti=<TaskInstance: stagingtodv.film_actor scheduled__2024-07-15T00:00:00+00:00 [queued]>
[2024-07-16T17:36:01.215+0000] {taskinstance.py:2193} INFO - Starting attempt 1 of 1
[2024-07-16T17:36:01.255+0000] {taskinstance.py:2217} INFO - Executing <Task(PythonOperator): film_actor> on 2024-07-15 00:00:00+00:00
[2024-07-16T17:36:01.271+0000] {standard_task_runner.py:60} INFO - Started process 98 to run task
[2024-07-16T17:36:01.285+0000] {standard_task_runner.py:87} INFO - Running: ['***', 'tasks', 'run', 'stagingtodv', 'film_actor', 'scheduled__2024-07-15T00:00:00+00:00', '--job-id', '13', '--raw', '--subdir', 'DAGS_FOLDER/dag.py', '--cfg-path', '/tmp/tmptgl7csb7']
[2024-07-16T17:36:01.292+0000] {standard_task_runner.py:88} INFO - Job 13: Subtask film_actor
[2024-07-16T17:36:01.504+0000] {task_command.py:423} INFO - Running <TaskInstance: stagingtodv.film_actor scheduled__2024-07-15T00:00:00+00:00 [running]> on host e1ba87a2fe19
[2024-07-16T17:36:02.794+0000] {taskinstance.py:2513} INFO - Exporting env vars: AIRFLOW_CTX_DAG_OWNER='***' AIRFLOW_CTX_DAG_ID='stagingtodv' AIRFLOW_CTX_TASK_ID='film_actor' AIRFLOW_CTX_EXECUTION_DATE='2024-07-15T00:00:00+00:00' AIRFLOW_CTX_TRY_NUMBER='1' AIRFLOW_CTX_DAG_RUN_ID='scheduled__2024-07-15T00:00:00+00:00'
[2024-07-16T17:36:02.798+0000] {logging_mixin.py:188} INFO - -------------------------------------------- select *  from etlconf.Etl_Process_Mapping where SourceTableName = 'film_actor' and Stage = 'stagingtodv'
[2024-07-16T17:36:02.826+0000] {taskinstance.py:2731} ERROR - Task failed with exception
Traceback (most recent call last):
  File "/home/airflow/.local/lib/python3.8/site-packages/airflow/models/taskinstance.py", line 444, in _execute_task
    result = _execute_callable(context=context, **execute_callable_kwargs)
  File "/home/airflow/.local/lib/python3.8/site-packages/airflow/models/taskinstance.py", line 414, in _execute_callable
    return execute_callable(context=context, **execute_callable_kwargs)
  File "/home/airflow/.local/lib/python3.8/site-packages/airflow/operators/python.py", line 200, in execute
    return_value = self.execute_callable()
  File "/home/airflow/.local/lib/python3.8/site-packages/airflow/operators/python.py", line 217, in execute_callable
    return self.python_callable(*self.op_args, **self.op_kwargs)
  File "/opt/airflow/dags/dag.py", line 41, in process_table
    tabletype = get_data_from_conf_table(table,stage)['tabletype'].values[0]
  File "/opt/airflow/dags/dag.py", line 34, in get_data_from_conf_table
    df.columns = [desc[0] for desc in cur.description]
  File "/home/airflow/.local/lib/python3.8/site-packages/pandas/core/generic.py", line 6002, in __setattr__
    return object.__setattr__(self, name, value)
  File "pandas/_libs/properties.pyx", line 69, in pandas._libs.properties.AxisProperty.__set__
  File "/home/airflow/.local/lib/python3.8/site-packages/pandas/core/generic.py", line 730, in _set_axis
    self._mgr.set_axis(axis, labels)
  File "/home/airflow/.local/lib/python3.8/site-packages/pandas/core/internals/managers.py", line 225, in set_axis
    self._validate_set_axis(axis, new_labels)
  File "/home/airflow/.local/lib/python3.8/site-packages/pandas/core/internals/base.py", line 70, in _validate_set_axis
    raise ValueError(
ValueError: Length mismatch: Expected axis has 0 elements, new values have 15 elements
[2024-07-16T17:36:02.844+0000] {taskinstance.py:1149} INFO - Marking task as FAILED. dag_id=stagingtodv, task_id=film_actor, execution_date=20240715T000000, start_date=20240716T173601, end_date=20240716T173602
[2024-07-16T17:36:02.915+0000] {standard_task_runner.py:107} ERROR - Failed to execute job 13 for task film_actor (Length mismatch: Expected axis has 0 elements, new values have 15 elements; 98)
[2024-07-16T17:36:02.955+0000] {local_task_job_runner.py:234} INFO - Task exited with return code 1
[2024-07-16T17:36:02.969+0000] {taskinstance.py:3312} INFO - 0 downstream tasks scheduled from follow-on schedule check
[2024-07-16T17:45:34.781+0000] {taskinstance.py:1979} INFO - Dependencies all met for dep_context=non-requeueable deps ti=<TaskInstance: stagingtodv.film_actor scheduled__2024-07-15T00:00:00+00:00 [queued]>
[2024-07-16T17:45:34.807+0000] {taskinstance.py:1979} INFO - Dependencies all met for dep_context=requeueable deps ti=<TaskInstance: stagingtodv.film_actor scheduled__2024-07-15T00:00:00+00:00 [queued]>
[2024-07-16T17:45:34.809+0000] {taskinstance.py:2193} INFO - Starting attempt 1 of 1
[2024-07-16T17:45:34.875+0000] {taskinstance.py:2217} INFO - Executing <Task(PythonOperator): film_actor> on 2024-07-15 00:00:00+00:00
[2024-07-16T17:45:34.879+0000] {standard_task_runner.py:60} INFO - Started process 91 to run task
[2024-07-16T17:45:34.897+0000] {standard_task_runner.py:87} INFO - Running: ['***', 'tasks', 'run', 'stagingtodv', 'film_actor', 'scheduled__2024-07-15T00:00:00+00:00', '--job-id', '3', '--raw', '--subdir', 'DAGS_FOLDER/dag.py', '--cfg-path', '/tmp/tmpx9fk113w']
[2024-07-16T17:45:34.907+0000] {standard_task_runner.py:88} INFO - Job 3: Subtask film_actor
[2024-07-16T17:45:35.115+0000] {task_command.py:423} INFO - Running <TaskInstance: stagingtodv.film_actor scheduled__2024-07-15T00:00:00+00:00 [running]> on host bba7487a60b5
[2024-07-16T17:45:36.527+0000] {taskinstance.py:2513} INFO - Exporting env vars: AIRFLOW_CTX_DAG_OWNER='***' AIRFLOW_CTX_DAG_ID='stagingtodv' AIRFLOW_CTX_TASK_ID='film_actor' AIRFLOW_CTX_EXECUTION_DATE='2024-07-15T00:00:00+00:00' AIRFLOW_CTX_TRY_NUMBER='1' AIRFLOW_CTX_DAG_RUN_ID='scheduled__2024-07-15T00:00:00+00:00'
[2024-07-16T17:45:36.529+0000] {logging_mixin.py:188} INFO - -------------------------------------------- select *  from etlconf.Etl_Process_Mapping where SourceTableName = 'film_actor' and Stage = 'stagingtodv'
[2024-07-16T17:45:36.650+0000] {taskinstance.py:2731} ERROR - Task failed with exception
Traceback (most recent call last):
  File "/home/airflow/.local/lib/python3.8/site-packages/airflow/models/taskinstance.py", line 444, in _execute_task
    result = _execute_callable(context=context, **execute_callable_kwargs)
  File "/home/airflow/.local/lib/python3.8/site-packages/airflow/models/taskinstance.py", line 414, in _execute_callable
    return execute_callable(context=context, **execute_callable_kwargs)
  File "/home/airflow/.local/lib/python3.8/site-packages/airflow/operators/python.py", line 200, in execute
    return_value = self.execute_callable()
  File "/home/airflow/.local/lib/python3.8/site-packages/airflow/operators/python.py", line 217, in execute_callable
    return self.python_callable(*self.op_args, **self.op_kwargs)
  File "/opt/airflow/dags/dag.py", line 41, in process_table
    tabletype = get_data_from_conf_table(table,stage)['tabletype'].values[0]
  File "/opt/airflow/dags/dag.py", line 34, in get_data_from_conf_table
    df.columns = [desc[0] for desc in cur.description]
  File "/home/airflow/.local/lib/python3.8/site-packages/pandas/core/generic.py", line 6002, in __setattr__
    return object.__setattr__(self, name, value)
  File "pandas/_libs/properties.pyx", line 69, in pandas._libs.properties.AxisProperty.__set__
  File "/home/airflow/.local/lib/python3.8/site-packages/pandas/core/generic.py", line 730, in _set_axis
    self._mgr.set_axis(axis, labels)
  File "/home/airflow/.local/lib/python3.8/site-packages/pandas/core/internals/managers.py", line 225, in set_axis
    self._validate_set_axis(axis, new_labels)
  File "/home/airflow/.local/lib/python3.8/site-packages/pandas/core/internals/base.py", line 70, in _validate_set_axis
    raise ValueError(
ValueError: Length mismatch: Expected axis has 0 elements, new values have 15 elements
[2024-07-16T17:45:36.694+0000] {taskinstance.py:1149} INFO - Marking task as FAILED. dag_id=stagingtodv, task_id=film_actor, execution_date=20240715T000000, start_date=20240716T174534, end_date=20240716T174536
[2024-07-16T17:45:36.774+0000] {standard_task_runner.py:107} ERROR - Failed to execute job 3 for task film_actor (Length mismatch: Expected axis has 0 elements, new values have 15 elements; 91)
[2024-07-16T17:45:36.824+0000] {local_task_job_runner.py:234} INFO - Task exited with return code 1
[2024-07-16T17:45:36.940+0000] {taskinstance.py:3312} INFO - 0 downstream tasks scheduled from follow-on schedule check
[2024-07-16T17:58:24.781+0000] {taskinstance.py:1979} INFO - Dependencies all met for dep_context=non-requeueable deps ti=<TaskInstance: stagingtodv.film_actor scheduled__2024-07-15T00:00:00+00:00 [queued]>
[2024-07-16T17:58:24.796+0000] {taskinstance.py:1979} INFO - Dependencies all met for dep_context=requeueable deps ti=<TaskInstance: stagingtodv.film_actor scheduled__2024-07-15T00:00:00+00:00 [queued]>
[2024-07-16T17:58:24.799+0000] {taskinstance.py:2193} INFO - Starting attempt 1 of 1
[2024-07-16T17:58:24.843+0000] {taskinstance.py:2217} INFO - Executing <Task(PythonOperator): film_actor> on 2024-07-15 00:00:00+00:00
[2024-07-16T17:58:24.869+0000] {standard_task_runner.py:60} INFO - Started process 93 to run task
[2024-07-16T17:58:24.882+0000] {standard_task_runner.py:87} INFO - Running: ['***', 'tasks', 'run', 'stagingtodv', 'film_actor', 'scheduled__2024-07-15T00:00:00+00:00', '--job-id', '16', '--raw', '--subdir', 'DAGS_FOLDER/dag.py', '--cfg-path', '/tmp/tmpxpbn5bk1']
[2024-07-16T17:58:24.897+0000] {standard_task_runner.py:88} INFO - Job 16: Subtask film_actor
[2024-07-16T17:58:25.079+0000] {task_command.py:423} INFO - Running <TaskInstance: stagingtodv.film_actor scheduled__2024-07-15T00:00:00+00:00 [running]> on host 9d71ede51657
[2024-07-16T17:58:26.423+0000] {taskinstance.py:2513} INFO - Exporting env vars: AIRFLOW_CTX_DAG_OWNER='***' AIRFLOW_CTX_DAG_ID='stagingtodv' AIRFLOW_CTX_TASK_ID='film_actor' AIRFLOW_CTX_EXECUTION_DATE='2024-07-15T00:00:00+00:00' AIRFLOW_CTX_TRY_NUMBER='1' AIRFLOW_CTX_DAG_RUN_ID='scheduled__2024-07-15T00:00:00+00:00'
[2024-07-16T17:58:26.424+0000] {logging_mixin.py:188} INFO - -------------------------------------------- select *  from etlconf.Etl_Process_Mapping where SourceTableName = 'film_actor' and Stage = 'stagingtodv'
[2024-07-16T17:58:26.472+0000] {taskinstance.py:2731} ERROR - Task failed with exception
Traceback (most recent call last):
  File "/home/airflow/.local/lib/python3.8/site-packages/airflow/models/taskinstance.py", line 444, in _execute_task
    result = _execute_callable(context=context, **execute_callable_kwargs)
  File "/home/airflow/.local/lib/python3.8/site-packages/airflow/models/taskinstance.py", line 414, in _execute_callable
    return execute_callable(context=context, **execute_callable_kwargs)
  File "/home/airflow/.local/lib/python3.8/site-packages/airflow/operators/python.py", line 200, in execute
    return_value = self.execute_callable()
  File "/home/airflow/.local/lib/python3.8/site-packages/airflow/operators/python.py", line 217, in execute_callable
    return self.python_callable(*self.op_args, **self.op_kwargs)
  File "/opt/airflow/dags/dag.py", line 41, in process_table
    tabletype = get_data_from_conf_table(table,stage)['tabletype'].values[0]
  File "/opt/airflow/dags/dag.py", line 34, in get_data_from_conf_table
    df.columns = [desc[0] for desc in cur.description]
  File "/home/airflow/.local/lib/python3.8/site-packages/pandas/core/generic.py", line 6002, in __setattr__
    return object.__setattr__(self, name, value)
  File "pandas/_libs/properties.pyx", line 69, in pandas._libs.properties.AxisProperty.__set__
  File "/home/airflow/.local/lib/python3.8/site-packages/pandas/core/generic.py", line 730, in _set_axis
    self._mgr.set_axis(axis, labels)
  File "/home/airflow/.local/lib/python3.8/site-packages/pandas/core/internals/managers.py", line 225, in set_axis
    self._validate_set_axis(axis, new_labels)
  File "/home/airflow/.local/lib/python3.8/site-packages/pandas/core/internals/base.py", line 70, in _validate_set_axis
    raise ValueError(
ValueError: Length mismatch: Expected axis has 0 elements, new values have 15 elements
[2024-07-16T17:58:26.492+0000] {taskinstance.py:1149} INFO - Marking task as FAILED. dag_id=stagingtodv, task_id=film_actor, execution_date=20240715T000000, start_date=20240716T175824, end_date=20240716T175826
[2024-07-16T17:58:26.502+0000] {standard_task_runner.py:107} ERROR - Failed to execute job 16 for task film_actor (Length mismatch: Expected axis has 0 elements, new values have 15 elements; 93)
[2024-07-16T17:58:26.534+0000] {local_task_job_runner.py:234} INFO - Task exited with return code 1
[2024-07-16T17:58:26.561+0000] {taskinstance.py:3312} INFO - 0 downstream tasks scheduled from follow-on schedule check
[2024-07-16T18:12:19.376+0000] {taskinstance.py:1979} INFO - Dependencies all met for dep_context=non-requeueable deps ti=<TaskInstance: stagingtodv.film_actor scheduled__2024-07-15T00:00:00+00:00 [queued]>
[2024-07-16T18:12:19.413+0000] {taskinstance.py:1979} INFO - Dependencies all met for dep_context=requeueable deps ti=<TaskInstance: stagingtodv.film_actor scheduled__2024-07-15T00:00:00+00:00 [queued]>
[2024-07-16T18:12:19.414+0000] {taskinstance.py:2193} INFO - Starting attempt 1 of 1
[2024-07-16T18:12:19.456+0000] {taskinstance.py:2217} INFO - Executing <Task(PythonOperator): film_actor> on 2024-07-15 00:00:00+00:00
[2024-07-16T18:12:19.481+0000] {standard_task_runner.py:87} INFO - Running: ['***', 'tasks', 'run', 'stagingtodv', 'film_actor', 'scheduled__2024-07-15T00:00:00+00:00', '--job-id', '4', '--raw', '--subdir', 'DAGS_FOLDER/dag.py', '--cfg-path', '/tmp/tmpsa0lftn3']
[2024-07-16T18:12:19.477+0000] {standard_task_runner.py:60} INFO - Started process 107 to run task
[2024-07-16T18:12:19.494+0000] {standard_task_runner.py:88} INFO - Job 4: Subtask film_actor
[2024-07-16T18:12:19.669+0000] {task_command.py:423} INFO - Running <TaskInstance: stagingtodv.film_actor scheduled__2024-07-15T00:00:00+00:00 [running]> on host 9f18461f6153
[2024-07-16T18:12:21.324+0000] {taskinstance.py:2513} INFO - Exporting env vars: AIRFLOW_CTX_DAG_OWNER='***' AIRFLOW_CTX_DAG_ID='stagingtodv' AIRFLOW_CTX_TASK_ID='film_actor' AIRFLOW_CTX_EXECUTION_DATE='2024-07-15T00:00:00+00:00' AIRFLOW_CTX_TRY_NUMBER='1' AIRFLOW_CTX_DAG_RUN_ID='scheduled__2024-07-15T00:00:00+00:00'
[2024-07-16T18:12:21.327+0000] {logging_mixin.py:188} INFO - -------------------------------------------- select *  from etlconf.Etl_Process_Mapping where SourceTableName = 'film_actor' and Stage = 'stagingtodv'
[2024-07-16T18:12:21.352+0000] {taskinstance.py:2731} ERROR - Task failed with exception
Traceback (most recent call last):
  File "/home/airflow/.local/lib/python3.8/site-packages/airflow/models/taskinstance.py", line 444, in _execute_task
    result = _execute_callable(context=context, **execute_callable_kwargs)
  File "/home/airflow/.local/lib/python3.8/site-packages/airflow/models/taskinstance.py", line 414, in _execute_callable
    return execute_callable(context=context, **execute_callable_kwargs)
  File "/home/airflow/.local/lib/python3.8/site-packages/airflow/operators/python.py", line 200, in execute
    return_value = self.execute_callable()
  File "/home/airflow/.local/lib/python3.8/site-packages/airflow/operators/python.py", line 217, in execute_callable
    return self.python_callable(*self.op_args, **self.op_kwargs)
  File "/opt/airflow/dags/dag.py", line 41, in process_table
    tabletype = get_data_from_conf_table(table,stage)['tabletype'].values[0]
  File "/opt/airflow/dags/dag.py", line 34, in get_data_from_conf_table
    df.columns = [desc[0] for desc in cur.description]
  File "/home/airflow/.local/lib/python3.8/site-packages/pandas/core/generic.py", line 6002, in __setattr__
    return object.__setattr__(self, name, value)
  File "pandas/_libs/properties.pyx", line 69, in pandas._libs.properties.AxisProperty.__set__
  File "/home/airflow/.local/lib/python3.8/site-packages/pandas/core/generic.py", line 730, in _set_axis
    self._mgr.set_axis(axis, labels)
  File "/home/airflow/.local/lib/python3.8/site-packages/pandas/core/internals/managers.py", line 225, in set_axis
    self._validate_set_axis(axis, new_labels)
  File "/home/airflow/.local/lib/python3.8/site-packages/pandas/core/internals/base.py", line 70, in _validate_set_axis
    raise ValueError(
ValueError: Length mismatch: Expected axis has 0 elements, new values have 15 elements
[2024-07-16T18:12:21.377+0000] {taskinstance.py:1149} INFO - Marking task as FAILED. dag_id=stagingtodv, task_id=film_actor, execution_date=20240715T000000, start_date=20240716T181219, end_date=20240716T181221
[2024-07-16T18:12:21.413+0000] {standard_task_runner.py:107} ERROR - Failed to execute job 4 for task film_actor (Length mismatch: Expected axis has 0 elements, new values have 15 elements; 107)
[2024-07-16T18:12:21.454+0000] {local_task_job_runner.py:234} INFO - Task exited with return code 1
[2024-07-16T18:12:21.528+0000] {taskinstance.py:3312} INFO - 0 downstream tasks scheduled from follow-on schedule check
[2024-07-16T18:29:51.934+0000] {taskinstance.py:1979} INFO - Dependencies all met for dep_context=non-requeueable deps ti=<TaskInstance: stagingtodv.film_actor scheduled__2024-07-15T00:00:00+00:00 [queued]>
[2024-07-16T18:29:51.991+0000] {taskinstance.py:1979} INFO - Dependencies all met for dep_context=requeueable deps ti=<TaskInstance: stagingtodv.film_actor scheduled__2024-07-15T00:00:00+00:00 [queued]>
[2024-07-16T18:29:52.010+0000] {taskinstance.py:2193} INFO - Starting attempt 1 of 1
[2024-07-16T18:29:52.082+0000] {taskinstance.py:2217} INFO - Executing <Task(PythonOperator): film_actor> on 2024-07-15 00:00:00+00:00
[2024-07-16T18:29:52.123+0000] {standard_task_runner.py:60} INFO - Started process 97 to run task
[2024-07-16T18:29:52.310+0000] {standard_task_runner.py:87} INFO - Running: ['***', 'tasks', 'run', 'stagingtodv', 'film_actor', 'scheduled__2024-07-15T00:00:00+00:00', '--job-id', '11', '--raw', '--subdir', 'DAGS_FOLDER/dag.py', '--cfg-path', '/tmp/tmpdcd9khmu']
[2024-07-16T18:29:52.323+0000] {standard_task_runner.py:88} INFO - Job 11: Subtask film_actor
[2024-07-16T18:29:52.749+0000] {task_command.py:423} INFO - Running <TaskInstance: stagingtodv.film_actor scheduled__2024-07-15T00:00:00+00:00 [running]> on host 6c99a2e38d27
[2024-07-16T18:29:58.497+0000] {taskinstance.py:2513} INFO - Exporting env vars: AIRFLOW_CTX_DAG_OWNER='***' AIRFLOW_CTX_DAG_ID='stagingtodv' AIRFLOW_CTX_TASK_ID='film_actor' AIRFLOW_CTX_EXECUTION_DATE='2024-07-15T00:00:00+00:00' AIRFLOW_CTX_TRY_NUMBER='1' AIRFLOW_CTX_DAG_RUN_ID='scheduled__2024-07-15T00:00:00+00:00'
[2024-07-16T18:29:58.528+0000] {logging_mixin.py:188} INFO - -------------------------------------------- select *  from etlconf.Etl_Process_Mapping where SourceTableName = 'film_actor' and Stage = 'stagingtodv'
[2024-07-16T18:29:58.720+0000] {taskinstance.py:2731} ERROR - Task failed with exception
Traceback (most recent call last):
  File "/home/airflow/.local/lib/python3.8/site-packages/airflow/models/taskinstance.py", line 444, in _execute_task
    result = _execute_callable(context=context, **execute_callable_kwargs)
  File "/home/airflow/.local/lib/python3.8/site-packages/airflow/models/taskinstance.py", line 414, in _execute_callable
    return execute_callable(context=context, **execute_callable_kwargs)
  File "/home/airflow/.local/lib/python3.8/site-packages/airflow/operators/python.py", line 200, in execute
    return_value = self.execute_callable()
  File "/home/airflow/.local/lib/python3.8/site-packages/airflow/operators/python.py", line 217, in execute_callable
    return self.python_callable(*self.op_args, **self.op_kwargs)
  File "/opt/airflow/dags/dag.py", line 41, in process_table
    tabletype = get_data_from_conf_table(table,stage)['tabletype'].values[0]
  File "/opt/airflow/dags/dag.py", line 34, in get_data_from_conf_table
    df.columns = [desc[0] for desc in cur.description]
  File "/home/airflow/.local/lib/python3.8/site-packages/pandas/core/generic.py", line 6002, in __setattr__
    return object.__setattr__(self, name, value)
  File "pandas/_libs/properties.pyx", line 69, in pandas._libs.properties.AxisProperty.__set__
  File "/home/airflow/.local/lib/python3.8/site-packages/pandas/core/generic.py", line 730, in _set_axis
    self._mgr.set_axis(axis, labels)
  File "/home/airflow/.local/lib/python3.8/site-packages/pandas/core/internals/managers.py", line 225, in set_axis
    self._validate_set_axis(axis, new_labels)
  File "/home/airflow/.local/lib/python3.8/site-packages/pandas/core/internals/base.py", line 70, in _validate_set_axis
    raise ValueError(
ValueError: Length mismatch: Expected axis has 0 elements, new values have 15 elements
[2024-07-16T18:29:58.972+0000] {taskinstance.py:1149} INFO - Marking task as FAILED. dag_id=stagingtodv, task_id=film_actor, execution_date=20240715T000000, start_date=20240716T182951, end_date=20240716T182958
[2024-07-16T18:29:59.533+0000] {standard_task_runner.py:107} ERROR - Failed to execute job 11 for task film_actor (Length mismatch: Expected axis has 0 elements, new values have 15 elements; 97)
[2024-07-16T18:29:59.678+0000] {local_task_job_runner.py:234} INFO - Task exited with return code 1
[2024-07-16T18:29:59.841+0000] {taskinstance.py:3312} INFO - 0 downstream tasks scheduled from follow-on schedule check
[2024-07-16T18:33:54.440+0000] {taskinstance.py:1979} INFO - Dependencies all met for dep_context=non-requeueable deps ti=<TaskInstance: stagingtodv.film_actor scheduled__2024-07-15T00:00:00+00:00 [queued]>
[2024-07-16T18:33:54.473+0000] {taskinstance.py:1979} INFO - Dependencies all met for dep_context=requeueable deps ti=<TaskInstance: stagingtodv.film_actor scheduled__2024-07-15T00:00:00+00:00 [queued]>
[2024-07-16T18:33:54.483+0000] {taskinstance.py:2193} INFO - Starting attempt 1 of 1
[2024-07-16T18:33:54.532+0000] {taskinstance.py:2217} INFO - Executing <Task(PythonOperator): film_actor> on 2024-07-15 00:00:00+00:00
[2024-07-16T18:33:54.571+0000] {standard_task_runner.py:60} INFO - Started process 113 to run task
[2024-07-16T18:33:54.607+0000] {standard_task_runner.py:87} INFO - Running: ['***', 'tasks', 'run', 'stagingtodv', 'film_actor', 'scheduled__2024-07-15T00:00:00+00:00', '--job-id', '9', '--raw', '--subdir', 'DAGS_FOLDER/dag.py', '--cfg-path', '/tmp/tmp_iqp1cbr']
[2024-07-16T18:33:54.650+0000] {standard_task_runner.py:88} INFO - Job 9: Subtask film_actor
[2024-07-16T18:33:54.915+0000] {task_command.py:423} INFO - Running <TaskInstance: stagingtodv.film_actor scheduled__2024-07-15T00:00:00+00:00 [running]> on host b7021158e377
[2024-07-16T18:33:56.456+0000] {taskinstance.py:2513} INFO - Exporting env vars: AIRFLOW_CTX_DAG_OWNER='***' AIRFLOW_CTX_DAG_ID='stagingtodv' AIRFLOW_CTX_TASK_ID='film_actor' AIRFLOW_CTX_EXECUTION_DATE='2024-07-15T00:00:00+00:00' AIRFLOW_CTX_TRY_NUMBER='1' AIRFLOW_CTX_DAG_RUN_ID='scheduled__2024-07-15T00:00:00+00:00'
[2024-07-16T18:33:56.468+0000] {logging_mixin.py:188} INFO - -------------------------------------------- select *  from etlconf.Etl_Process_Mapping where SourceTableName = 'film_actor' and Stage = 'stagingtodv'
[2024-07-16T18:33:56.495+0000] {taskinstance.py:2731} ERROR - Task failed with exception
Traceback (most recent call last):
  File "/home/airflow/.local/lib/python3.8/site-packages/airflow/models/taskinstance.py", line 444, in _execute_task
    result = _execute_callable(context=context, **execute_callable_kwargs)
  File "/home/airflow/.local/lib/python3.8/site-packages/airflow/models/taskinstance.py", line 414, in _execute_callable
    return execute_callable(context=context, **execute_callable_kwargs)
  File "/home/airflow/.local/lib/python3.8/site-packages/airflow/operators/python.py", line 200, in execute
    return_value = self.execute_callable()
  File "/home/airflow/.local/lib/python3.8/site-packages/airflow/operators/python.py", line 217, in execute_callable
    return self.python_callable(*self.op_args, **self.op_kwargs)
  File "/opt/airflow/dags/dag.py", line 41, in process_table
    tabletype = get_data_from_conf_table(table,stage)['tabletype'].values[0]
  File "/opt/airflow/dags/dag.py", line 34, in get_data_from_conf_table
    df.columns = [desc[0] for desc in cur.description]
  File "/home/airflow/.local/lib/python3.8/site-packages/pandas/core/generic.py", line 6002, in __setattr__
    return object.__setattr__(self, name, value)
  File "pandas/_libs/properties.pyx", line 69, in pandas._libs.properties.AxisProperty.__set__
  File "/home/airflow/.local/lib/python3.8/site-packages/pandas/core/generic.py", line 730, in _set_axis
    self._mgr.set_axis(axis, labels)
  File "/home/airflow/.local/lib/python3.8/site-packages/pandas/core/internals/managers.py", line 225, in set_axis
    self._validate_set_axis(axis, new_labels)
  File "/home/airflow/.local/lib/python3.8/site-packages/pandas/core/internals/base.py", line 70, in _validate_set_axis
    raise ValueError(
ValueError: Length mismatch: Expected axis has 0 elements, new values have 15 elements
[2024-07-16T18:33:56.527+0000] {taskinstance.py:1149} INFO - Marking task as FAILED. dag_id=stagingtodv, task_id=film_actor, execution_date=20240715T000000, start_date=20240716T183354, end_date=20240716T183356
[2024-07-16T18:33:56.602+0000] {standard_task_runner.py:107} ERROR - Failed to execute job 9 for task film_actor (Length mismatch: Expected axis has 0 elements, new values have 15 elements; 113)
[2024-07-16T18:33:56.653+0000] {local_task_job_runner.py:234} INFO - Task exited with return code 1
[2024-07-16T18:33:56.696+0000] {taskinstance.py:3312} INFO - 0 downstream tasks scheduled from follow-on schedule check
[2024-07-16T18:45:24.010+0000] {taskinstance.py:1979} INFO - Dependencies all met for dep_context=non-requeueable deps ti=<TaskInstance: stagingtodv.film_actor scheduled__2024-07-15T00:00:00+00:00 [queued]>
[2024-07-16T18:45:24.036+0000] {taskinstance.py:1979} INFO - Dependencies all met for dep_context=requeueable deps ti=<TaskInstance: stagingtodv.film_actor scheduled__2024-07-15T00:00:00+00:00 [queued]>
[2024-07-16T18:45:24.039+0000] {taskinstance.py:2193} INFO - Starting attempt 1 of 1
[2024-07-16T18:45:24.066+0000] {taskinstance.py:2217} INFO - Executing <Task(PythonOperator): film_actor> on 2024-07-15 00:00:00+00:00
[2024-07-16T18:45:24.110+0000] {standard_task_runner.py:60} INFO - Started process 143 to run task
[2024-07-16T18:45:24.128+0000] {standard_task_runner.py:87} INFO - Running: ['***', 'tasks', 'run', 'stagingtodv', 'film_actor', 'scheduled__2024-07-15T00:00:00+00:00', '--job-id', '27', '--raw', '--subdir', 'DAGS_FOLDER/dag.py', '--cfg-path', '/tmp/tmpr8ghe006']
[2024-07-16T18:45:24.151+0000] {standard_task_runner.py:88} INFO - Job 27: Subtask film_actor
[2024-07-16T18:45:24.450+0000] {task_command.py:423} INFO - Running <TaskInstance: stagingtodv.film_actor scheduled__2024-07-15T00:00:00+00:00 [running]> on host 2e3dbb9eb862
[2024-07-16T18:45:24.736+0000] {taskinstance.py:2513} INFO - Exporting env vars: AIRFLOW_CTX_DAG_OWNER='***' AIRFLOW_CTX_DAG_ID='stagingtodv' AIRFLOW_CTX_TASK_ID='film_actor' AIRFLOW_CTX_EXECUTION_DATE='2024-07-15T00:00:00+00:00' AIRFLOW_CTX_TRY_NUMBER='1' AIRFLOW_CTX_DAG_RUN_ID='scheduled__2024-07-15T00:00:00+00:00'
[2024-07-16T18:45:24.756+0000] {logging_mixin.py:188} INFO - -------------------------------------------- select *  from etlconf.Etl_Process_Mapping where SourceTableName = 'film_actor' and Stage = 'stagingtodv'
[2024-07-16T18:45:25.638+0000] {taskinstance.py:2731} ERROR - Task failed with exception
Traceback (most recent call last):
  File "/home/airflow/.local/lib/python3.8/site-packages/airflow/models/taskinstance.py", line 444, in _execute_task
    result = _execute_callable(context=context, **execute_callable_kwargs)
  File "/home/airflow/.local/lib/python3.8/site-packages/airflow/models/taskinstance.py", line 414, in _execute_callable
    return execute_callable(context=context, **execute_callable_kwargs)
  File "/home/airflow/.local/lib/python3.8/site-packages/airflow/operators/python.py", line 200, in execute
    return_value = self.execute_callable()
  File "/home/airflow/.local/lib/python3.8/site-packages/airflow/operators/python.py", line 217, in execute_callable
    return self.python_callable(*self.op_args, **self.op_kwargs)
  File "/opt/airflow/dags/dag.py", line 41, in process_table
    tabletype = get_data_from_conf_table(table,stage)['tabletype'].values[0]
  File "/opt/airflow/dags/dag.py", line 34, in get_data_from_conf_table
    df.columns = [desc[0] for desc in cur.description]
  File "/home/airflow/.local/lib/python3.8/site-packages/pandas/core/generic.py", line 6002, in __setattr__
    return object.__setattr__(self, name, value)
  File "pandas/_libs/properties.pyx", line 69, in pandas._libs.properties.AxisProperty.__set__
  File "/home/airflow/.local/lib/python3.8/site-packages/pandas/core/generic.py", line 730, in _set_axis
    self._mgr.set_axis(axis, labels)
  File "/home/airflow/.local/lib/python3.8/site-packages/pandas/core/internals/managers.py", line 225, in set_axis
    self._validate_set_axis(axis, new_labels)
  File "/home/airflow/.local/lib/python3.8/site-packages/pandas/core/internals/base.py", line 70, in _validate_set_axis
    raise ValueError(
ValueError: Length mismatch: Expected axis has 0 elements, new values have 15 elements
[2024-07-16T18:45:25.688+0000] {taskinstance.py:1149} INFO - Marking task as FAILED. dag_id=stagingtodv, task_id=film_actor, execution_date=20240715T000000, start_date=20240716T184524, end_date=20240716T184525
[2024-07-16T18:45:25.744+0000] {standard_task_runner.py:107} ERROR - Failed to execute job 27 for task film_actor (Length mismatch: Expected axis has 0 elements, new values have 15 elements; 143)
[2024-07-16T18:45:25.870+0000] {local_task_job_runner.py:234} INFO - Task exited with return code 1
[2024-07-16T18:45:25.934+0000] {taskinstance.py:3312} INFO - 0 downstream tasks scheduled from follow-on schedule check
[2024-07-16T18:56:45.755+0000] {taskinstance.py:1979} INFO - Dependencies all met for dep_context=non-requeueable deps ti=<TaskInstance: stagingtodv.film_actor scheduled__2024-07-15T00:00:00+00:00 [queued]>
[2024-07-16T18:56:45.770+0000] {taskinstance.py:1979} INFO - Dependencies all met for dep_context=requeueable deps ti=<TaskInstance: stagingtodv.film_actor scheduled__2024-07-15T00:00:00+00:00 [queued]>
[2024-07-16T18:56:45.772+0000] {taskinstance.py:2193} INFO - Starting attempt 1 of 1
[2024-07-16T18:56:45.857+0000] {taskinstance.py:2217} INFO - Executing <Task(PythonOperator): film_actor> on 2024-07-15 00:00:00+00:00
[2024-07-16T18:56:45.866+0000] {standard_task_runner.py:60} INFO - Started process 147 to run task
[2024-07-16T18:56:45.884+0000] {standard_task_runner.py:87} INFO - Running: ['***', 'tasks', 'run', 'stagingtodv', 'film_actor', 'scheduled__2024-07-15T00:00:00+00:00', '--job-id', '23', '--raw', '--subdir', 'DAGS_FOLDER/dag.py', '--cfg-path', '/tmp/tmpwqwdovb6']
[2024-07-16T18:56:45.895+0000] {standard_task_runner.py:88} INFO - Job 23: Subtask film_actor
[2024-07-16T18:56:46.130+0000] {task_command.py:423} INFO - Running <TaskInstance: stagingtodv.film_actor scheduled__2024-07-15T00:00:00+00:00 [running]> on host 1733eeb0def3
[2024-07-16T18:56:46.521+0000] {taskinstance.py:2513} INFO - Exporting env vars: AIRFLOW_CTX_DAG_OWNER='***' AIRFLOW_CTX_DAG_ID='stagingtodv' AIRFLOW_CTX_TASK_ID='film_actor' AIRFLOW_CTX_EXECUTION_DATE='2024-07-15T00:00:00+00:00' AIRFLOW_CTX_TRY_NUMBER='1' AIRFLOW_CTX_DAG_RUN_ID='scheduled__2024-07-15T00:00:00+00:00'
[2024-07-16T18:56:46.529+0000] {logging_mixin.py:188} INFO - -------------------------------------------- select *  from etlconf.Etl_Process_Mapping where SourceTableName = 'film_actor' and Stage = 'stagingtodv'
[2024-07-16T18:56:47.059+0000] {taskinstance.py:2731} ERROR - Task failed with exception
Traceback (most recent call last):
  File "/home/airflow/.local/lib/python3.8/site-packages/airflow/models/taskinstance.py", line 444, in _execute_task
    result = _execute_callable(context=context, **execute_callable_kwargs)
  File "/home/airflow/.local/lib/python3.8/site-packages/airflow/models/taskinstance.py", line 414, in _execute_callable
    return execute_callable(context=context, **execute_callable_kwargs)
  File "/home/airflow/.local/lib/python3.8/site-packages/airflow/operators/python.py", line 200, in execute
    return_value = self.execute_callable()
  File "/home/airflow/.local/lib/python3.8/site-packages/airflow/operators/python.py", line 217, in execute_callable
    return self.python_callable(*self.op_args, **self.op_kwargs)
  File "/opt/airflow/dags/dag.py", line 41, in process_table
    tabletype = get_data_from_conf_table(table,stage)['tabletype'].values[0]
  File "/opt/airflow/dags/dag.py", line 34, in get_data_from_conf_table
    df.columns = [desc[0] for desc in cur.description]
  File "/home/airflow/.local/lib/python3.8/site-packages/pandas/core/generic.py", line 6002, in __setattr__
    return object.__setattr__(self, name, value)
  File "pandas/_libs/properties.pyx", line 69, in pandas._libs.properties.AxisProperty.__set__
  File "/home/airflow/.local/lib/python3.8/site-packages/pandas/core/generic.py", line 730, in _set_axis
    self._mgr.set_axis(axis, labels)
  File "/home/airflow/.local/lib/python3.8/site-packages/pandas/core/internals/managers.py", line 225, in set_axis
    self._validate_set_axis(axis, new_labels)
  File "/home/airflow/.local/lib/python3.8/site-packages/pandas/core/internals/base.py", line 70, in _validate_set_axis
    raise ValueError(
ValueError: Length mismatch: Expected axis has 0 elements, new values have 15 elements
[2024-07-16T18:56:47.104+0000] {taskinstance.py:1149} INFO - Marking task as FAILED. dag_id=stagingtodv, task_id=film_actor, execution_date=20240715T000000, start_date=20240716T185645, end_date=20240716T185647
[2024-07-16T18:56:47.134+0000] {standard_task_runner.py:107} ERROR - Failed to execute job 23 for task film_actor (Length mismatch: Expected axis has 0 elements, new values have 15 elements; 147)
[2024-07-16T18:56:47.171+0000] {local_task_job_runner.py:234} INFO - Task exited with return code 1
[2024-07-16T18:56:47.204+0000] {taskinstance.py:3312} INFO - 0 downstream tasks scheduled from follow-on schedule check
[2024-07-16T19:01:11.949+0000] {taskinstance.py:1979} INFO - Dependencies all met for dep_context=non-requeueable deps ti=<TaskInstance: stagingtodv.film_actor scheduled__2024-07-15T00:00:00+00:00 [queued]>
[2024-07-16T19:01:11.974+0000] {taskinstance.py:1979} INFO - Dependencies all met for dep_context=requeueable deps ti=<TaskInstance: stagingtodv.film_actor scheduled__2024-07-15T00:00:00+00:00 [queued]>
[2024-07-16T19:01:11.987+0000] {taskinstance.py:2193} INFO - Starting attempt 1 of 1
[2024-07-16T19:01:12.039+0000] {taskinstance.py:2217} INFO - Executing <Task(PythonOperator): film_actor> on 2024-07-15 00:00:00+00:00
[2024-07-16T19:01:12.049+0000] {standard_task_runner.py:60} INFO - Started process 89 to run task
[2024-07-16T19:01:12.069+0000] {standard_task_runner.py:87} INFO - Running: ['***', 'tasks', 'run', 'stagingtodv', 'film_actor', 'scheduled__2024-07-15T00:00:00+00:00', '--job-id', '11', '--raw', '--subdir', 'DAGS_FOLDER/dag.py', '--cfg-path', '/tmp/tmpa9mvwzke']
[2024-07-16T19:01:12.082+0000] {standard_task_runner.py:88} INFO - Job 11: Subtask film_actor
[2024-07-16T19:01:12.293+0000] {task_command.py:423} INFO - Running <TaskInstance: stagingtodv.film_actor scheduled__2024-07-15T00:00:00+00:00 [running]> on host ef8b8dee6045
[2024-07-16T19:01:13.285+0000] {taskinstance.py:2513} INFO - Exporting env vars: AIRFLOW_CTX_DAG_OWNER='***' AIRFLOW_CTX_DAG_ID='stagingtodv' AIRFLOW_CTX_TASK_ID='film_actor' AIRFLOW_CTX_EXECUTION_DATE='2024-07-15T00:00:00+00:00' AIRFLOW_CTX_TRY_NUMBER='1' AIRFLOW_CTX_DAG_RUN_ID='scheduled__2024-07-15T00:00:00+00:00'
[2024-07-16T19:01:13.290+0000] {logging_mixin.py:188} INFO - -------------------------------------------- select *  from etlconf.Etl_Process_Mapping where SourceTableName = 'film_actor' and Stage = 'stagingtodv'
[2024-07-16T19:01:13.354+0000] {taskinstance.py:2731} ERROR - Task failed with exception
Traceback (most recent call last):
  File "/home/airflow/.local/lib/python3.8/site-packages/airflow/models/taskinstance.py", line 444, in _execute_task
    result = _execute_callable(context=context, **execute_callable_kwargs)
  File "/home/airflow/.local/lib/python3.8/site-packages/airflow/models/taskinstance.py", line 414, in _execute_callable
    return execute_callable(context=context, **execute_callable_kwargs)
  File "/home/airflow/.local/lib/python3.8/site-packages/airflow/operators/python.py", line 200, in execute
    return_value = self.execute_callable()
  File "/home/airflow/.local/lib/python3.8/site-packages/airflow/operators/python.py", line 217, in execute_callable
    return self.python_callable(*self.op_args, **self.op_kwargs)
  File "/opt/airflow/dags/dag.py", line 41, in process_table
    tabletype = get_data_from_conf_table(table,stage)['tabletype'].values[0]
  File "/opt/airflow/dags/dag.py", line 34, in get_data_from_conf_table
    df.columns = [desc[0] for desc in cur.description]
  File "/home/airflow/.local/lib/python3.8/site-packages/pandas/core/generic.py", line 6002, in __setattr__
    return object.__setattr__(self, name, value)
  File "pandas/_libs/properties.pyx", line 69, in pandas._libs.properties.AxisProperty.__set__
  File "/home/airflow/.local/lib/python3.8/site-packages/pandas/core/generic.py", line 730, in _set_axis
    self._mgr.set_axis(axis, labels)
  File "/home/airflow/.local/lib/python3.8/site-packages/pandas/core/internals/managers.py", line 225, in set_axis
    self._validate_set_axis(axis, new_labels)
  File "/home/airflow/.local/lib/python3.8/site-packages/pandas/core/internals/base.py", line 70, in _validate_set_axis
    raise ValueError(
ValueError: Length mismatch: Expected axis has 0 elements, new values have 15 elements
[2024-07-16T19:01:13.414+0000] {taskinstance.py:1149} INFO - Marking task as FAILED. dag_id=stagingtodv, task_id=film_actor, execution_date=20240715T000000, start_date=20240716T190111, end_date=20240716T190113
[2024-07-16T19:01:13.451+0000] {standard_task_runner.py:107} ERROR - Failed to execute job 11 for task film_actor (Length mismatch: Expected axis has 0 elements, new values have 15 elements; 89)
[2024-07-16T19:01:13.534+0000] {local_task_job_runner.py:234} INFO - Task exited with return code 1
[2024-07-16T19:01:13.621+0000] {taskinstance.py:3312} INFO - 0 downstream tasks scheduled from follow-on schedule check
