[2024-07-16T16:54:48.930+0000] {taskinstance.py:1979} INFO - Dependencies all met for dep_context=non-requeueable deps ti=<TaskInstance: staigingtodv.payment scheduled__2024-07-15T00:00:00+00:00 [queued]>
[2024-07-16T16:54:48.952+0000] {taskinstance.py:1979} INFO - Dependencies all met for dep_context=requeueable deps ti=<TaskInstance: staigingtodv.payment scheduled__2024-07-15T00:00:00+00:00 [queued]>
[2024-07-16T16:54:48.955+0000] {taskinstance.py:2193} INFO - Starting attempt 1 of 1
[2024-07-16T16:54:48.993+0000] {taskinstance.py:2217} INFO - Executing <Task(PythonOperator): payment> on 2024-07-15 00:00:00+00:00
[2024-07-16T16:54:49.022+0000] {standard_task_runner.py:60} INFO - Started process 96 to run task
[2024-07-16T16:54:49.031+0000] {standard_task_runner.py:87} INFO - Running: ['***', 'tasks', 'run', 'staigingtodv', 'payment', 'scheduled__2024-07-15T00:00:00+00:00', '--job-id', '11', '--raw', '--subdir', 'DAGS_FOLDER/dag.py', '--cfg-path', '/tmp/tmp4hcucxcm']
[2024-07-16T16:54:49.046+0000] {standard_task_runner.py:88} INFO - Job 11: Subtask payment
[2024-07-16T16:54:49.171+0000] {task_command.py:423} INFO - Running <TaskInstance: staigingtodv.payment scheduled__2024-07-15T00:00:00+00:00 [running]> on host d9cb41fade7e
[2024-07-16T16:54:49.397+0000] {taskinstance.py:2513} INFO - Exporting env vars: AIRFLOW_CTX_DAG_OWNER='***' AIRFLOW_CTX_DAG_ID='staigingtodv' AIRFLOW_CTX_TASK_ID='payment' AIRFLOW_CTX_EXECUTION_DATE='2024-07-15T00:00:00+00:00' AIRFLOW_CTX_TRY_NUMBER='1' AIRFLOW_CTX_DAG_RUN_ID='scheduled__2024-07-15T00:00:00+00:00'
[2024-07-16T16:54:50.464+0000] {taskinstance.py:2731} ERROR - Task failed with exception
Traceback (most recent call last):
  File "/home/airflow/.local/lib/python3.8/site-packages/airflow/models/taskinstance.py", line 444, in _execute_task
    result = _execute_callable(context=context, **execute_callable_kwargs)
  File "/home/airflow/.local/lib/python3.8/site-packages/airflow/models/taskinstance.py", line 414, in _execute_callable
    return execute_callable(context=context, **execute_callable_kwargs)
  File "/home/airflow/.local/lib/python3.8/site-packages/airflow/operators/python.py", line 200, in execute
    return_value = self.execute_callable()
  File "/home/airflow/.local/lib/python3.8/site-packages/airflow/operators/python.py", line 217, in execute_callable
    return self.python_callable(*self.op_args, **self.op_kwargs)
  File "/opt/airflow/dags/dag.py", line 40, in process_table
    tabletype = get_data_from_conf_table(table,stage)['tabletype'].values[0]
  File "/opt/airflow/dags/dag.py", line 33, in get_data_from_conf_table
    df.columns = [desc[0] for desc in cur.description]
  File "/home/airflow/.local/lib/python3.8/site-packages/pandas/core/generic.py", line 6002, in __setattr__
    return object.__setattr__(self, name, value)
  File "pandas/_libs/properties.pyx", line 69, in pandas._libs.properties.AxisProperty.__set__
  File "/home/airflow/.local/lib/python3.8/site-packages/pandas/core/generic.py", line 730, in _set_axis
    self._mgr.set_axis(axis, labels)
  File "/home/airflow/.local/lib/python3.8/site-packages/pandas/core/internals/managers.py", line 225, in set_axis
    self._validate_set_axis(axis, new_labels)
  File "/home/airflow/.local/lib/python3.8/site-packages/pandas/core/internals/base.py", line 70, in _validate_set_axis
    raise ValueError(
ValueError: Length mismatch: Expected axis has 0 elements, new values have 15 elements
[2024-07-16T16:54:50.476+0000] {taskinstance.py:1149} INFO - Marking task as FAILED. dag_id=staigingtodv, task_id=payment, execution_date=20240715T000000, start_date=20240716T165448, end_date=20240716T165450
[2024-07-16T16:54:50.510+0000] {standard_task_runner.py:107} ERROR - Failed to execute job 11 for task payment (Length mismatch: Expected axis has 0 elements, new values have 15 elements; 96)
[2024-07-16T16:54:50.555+0000] {local_task_job_runner.py:234} INFO - Task exited with return code 1
[2024-07-16T16:54:50.581+0000] {taskinstance.py:3312} INFO - 0 downstream tasks scheduled from follow-on schedule check
[2024-07-16T16:58:22.142+0000] {taskinstance.py:1979} INFO - Dependencies all met for dep_context=non-requeueable deps ti=<TaskInstance: staigingtodv.payment scheduled__2024-07-15T00:00:00+00:00 [queued]>
[2024-07-16T16:58:22.164+0000] {taskinstance.py:1979} INFO - Dependencies all met for dep_context=requeueable deps ti=<TaskInstance: staigingtodv.payment scheduled__2024-07-15T00:00:00+00:00 [queued]>
[2024-07-16T16:58:22.168+0000] {taskinstance.py:2193} INFO - Starting attempt 1 of 1
[2024-07-16T16:58:22.199+0000] {taskinstance.py:2217} INFO - Executing <Task(PythonOperator): payment> on 2024-07-15 00:00:00+00:00
[2024-07-16T16:58:22.207+0000] {standard_task_runner.py:60} INFO - Started process 106 to run task
[2024-07-16T16:58:22.225+0000] {standard_task_runner.py:87} INFO - Running: ['***', 'tasks', 'run', 'staigingtodv', 'payment', 'scheduled__2024-07-15T00:00:00+00:00', '--job-id', '15', '--raw', '--subdir', 'DAGS_FOLDER/dag.py', '--cfg-path', '/tmp/tmp6u0d6cu5']
[2024-07-16T16:58:22.238+0000] {standard_task_runner.py:88} INFO - Job 15: Subtask payment
[2024-07-16T16:58:22.369+0000] {task_command.py:423} INFO - Running <TaskInstance: staigingtodv.payment scheduled__2024-07-15T00:00:00+00:00 [running]> on host bd70e8223b94
[2024-07-16T16:58:23.521+0000] {taskinstance.py:2513} INFO - Exporting env vars: AIRFLOW_CTX_DAG_OWNER='***' AIRFLOW_CTX_DAG_ID='staigingtodv' AIRFLOW_CTX_TASK_ID='payment' AIRFLOW_CTX_EXECUTION_DATE='2024-07-15T00:00:00+00:00' AIRFLOW_CTX_TRY_NUMBER='1' AIRFLOW_CTX_DAG_RUN_ID='scheduled__2024-07-15T00:00:00+00:00'
[2024-07-16T16:58:23.612+0000] {taskinstance.py:2731} ERROR - Task failed with exception
Traceback (most recent call last):
  File "/home/airflow/.local/lib/python3.8/site-packages/airflow/models/taskinstance.py", line 444, in _execute_task
    result = _execute_callable(context=context, **execute_callable_kwargs)
  File "/home/airflow/.local/lib/python3.8/site-packages/airflow/models/taskinstance.py", line 414, in _execute_callable
    return execute_callable(context=context, **execute_callable_kwargs)
  File "/home/airflow/.local/lib/python3.8/site-packages/airflow/operators/python.py", line 200, in execute
    return_value = self.execute_callable()
  File "/home/airflow/.local/lib/python3.8/site-packages/airflow/operators/python.py", line 217, in execute_callable
    return self.python_callable(*self.op_args, **self.op_kwargs)
  File "/opt/airflow/dags/dag.py", line 40, in process_table
    tabletype = get_data_from_conf_table(table,stage)['tabletype'].values[0]
  File "/opt/airflow/dags/dag.py", line 33, in get_data_from_conf_table
    df.columns = [desc[0] for desc in cur.description]
  File "/home/airflow/.local/lib/python3.8/site-packages/pandas/core/generic.py", line 6002, in __setattr__
    return object.__setattr__(self, name, value)
  File "pandas/_libs/properties.pyx", line 69, in pandas._libs.properties.AxisProperty.__set__
  File "/home/airflow/.local/lib/python3.8/site-packages/pandas/core/generic.py", line 730, in _set_axis
    self._mgr.set_axis(axis, labels)
  File "/home/airflow/.local/lib/python3.8/site-packages/pandas/core/internals/managers.py", line 225, in set_axis
    self._validate_set_axis(axis, new_labels)
  File "/home/airflow/.local/lib/python3.8/site-packages/pandas/core/internals/base.py", line 70, in _validate_set_axis
    raise ValueError(
ValueError: Length mismatch: Expected axis has 0 elements, new values have 15 elements
[2024-07-16T16:58:23.676+0000] {taskinstance.py:1149} INFO - Marking task as FAILED. dag_id=staigingtodv, task_id=payment, execution_date=20240715T000000, start_date=20240716T165822, end_date=20240716T165823
[2024-07-16T16:58:23.713+0000] {standard_task_runner.py:107} ERROR - Failed to execute job 15 for task payment (Length mismatch: Expected axis has 0 elements, new values have 15 elements; 106)
[2024-07-16T16:58:23.786+0000] {local_task_job_runner.py:234} INFO - Task exited with return code 1
[2024-07-16T16:58:23.834+0000] {taskinstance.py:3312} INFO - 0 downstream tasks scheduled from follow-on schedule check
[2024-07-16T17:06:16.383+0000] {taskinstance.py:1979} INFO - Dependencies all met for dep_context=non-requeueable deps ti=<TaskInstance: staigingtodv.payment scheduled__2024-07-15T00:00:00+00:00 [queued]>
[2024-07-16T17:06:16.417+0000] {taskinstance.py:1979} INFO - Dependencies all met for dep_context=requeueable deps ti=<TaskInstance: staigingtodv.payment scheduled__2024-07-15T00:00:00+00:00 [queued]>
[2024-07-16T17:06:16.420+0000] {taskinstance.py:2193} INFO - Starting attempt 1 of 1
[2024-07-16T17:06:16.467+0000] {taskinstance.py:2217} INFO - Executing <Task(PythonOperator): payment> on 2024-07-15 00:00:00+00:00
[2024-07-16T17:06:16.483+0000] {standard_task_runner.py:60} INFO - Started process 91 to run task
[2024-07-16T17:06:16.495+0000] {standard_task_runner.py:87} INFO - Running: ['***', 'tasks', 'run', 'staigingtodv', 'payment', 'scheduled__2024-07-15T00:00:00+00:00', '--job-id', '6', '--raw', '--subdir', 'DAGS_FOLDER/dag.py', '--cfg-path', '/tmp/tmp0v5i90gx']
[2024-07-16T17:06:16.503+0000] {standard_task_runner.py:88} INFO - Job 6: Subtask payment
[2024-07-16T17:06:16.694+0000] {task_command.py:423} INFO - Running <TaskInstance: staigingtodv.payment scheduled__2024-07-15T00:00:00+00:00 [running]> on host d972e0703431
[2024-07-16T17:06:17.556+0000] {taskinstance.py:2513} INFO - Exporting env vars: AIRFLOW_CTX_DAG_OWNER='***' AIRFLOW_CTX_DAG_ID='staigingtodv' AIRFLOW_CTX_TASK_ID='payment' AIRFLOW_CTX_EXECUTION_DATE='2024-07-15T00:00:00+00:00' AIRFLOW_CTX_TRY_NUMBER='1' AIRFLOW_CTX_DAG_RUN_ID='scheduled__2024-07-15T00:00:00+00:00'
[2024-07-16T17:06:17.629+0000] {taskinstance.py:2731} ERROR - Task failed with exception
Traceback (most recent call last):
  File "/home/airflow/.local/lib/python3.8/site-packages/airflow/models/taskinstance.py", line 444, in _execute_task
    result = _execute_callable(context=context, **execute_callable_kwargs)
  File "/home/airflow/.local/lib/python3.8/site-packages/airflow/models/taskinstance.py", line 414, in _execute_callable
    return execute_callable(context=context, **execute_callable_kwargs)
  File "/home/airflow/.local/lib/python3.8/site-packages/airflow/operators/python.py", line 200, in execute
    return_value = self.execute_callable()
  File "/home/airflow/.local/lib/python3.8/site-packages/airflow/operators/python.py", line 217, in execute_callable
    return self.python_callable(*self.op_args, **self.op_kwargs)
  File "/opt/airflow/dags/dag.py", line 40, in process_table
    tabletype = get_data_from_conf_table(table,stage)['tabletype'].values[0]
  File "/opt/airflow/dags/dag.py", line 33, in get_data_from_conf_table
    df.columns = [desc[0] for desc in cur.description]
  File "/home/airflow/.local/lib/python3.8/site-packages/pandas/core/generic.py", line 6002, in __setattr__
    return object.__setattr__(self, name, value)
  File "pandas/_libs/properties.pyx", line 69, in pandas._libs.properties.AxisProperty.__set__
  File "/home/airflow/.local/lib/python3.8/site-packages/pandas/core/generic.py", line 730, in _set_axis
    self._mgr.set_axis(axis, labels)
  File "/home/airflow/.local/lib/python3.8/site-packages/pandas/core/internals/managers.py", line 225, in set_axis
    self._validate_set_axis(axis, new_labels)
  File "/home/airflow/.local/lib/python3.8/site-packages/pandas/core/internals/base.py", line 70, in _validate_set_axis
    raise ValueError(
ValueError: Length mismatch: Expected axis has 0 elements, new values have 15 elements
[2024-07-16T17:06:17.691+0000] {taskinstance.py:1149} INFO - Marking task as FAILED. dag_id=staigingtodv, task_id=payment, execution_date=20240715T000000, start_date=20240716T170616, end_date=20240716T170617
[2024-07-16T17:06:17.752+0000] {standard_task_runner.py:107} ERROR - Failed to execute job 6 for task payment (Length mismatch: Expected axis has 0 elements, new values have 15 elements; 91)
[2024-07-16T17:06:17.805+0000] {local_task_job_runner.py:234} INFO - Task exited with return code 1
[2024-07-16T17:06:17.848+0000] {taskinstance.py:3312} INFO - 0 downstream tasks scheduled from follow-on schedule check
[2024-07-16T17:10:13.512+0000] {taskinstance.py:1979} INFO - Dependencies all met for dep_context=non-requeueable deps ti=<TaskInstance: staigingtodv.payment scheduled__2024-07-15T00:00:00+00:00 [queued]>
[2024-07-16T17:10:13.584+0000] {taskinstance.py:1979} INFO - Dependencies all met for dep_context=requeueable deps ti=<TaskInstance: staigingtodv.payment scheduled__2024-07-15T00:00:00+00:00 [queued]>
[2024-07-16T17:10:13.591+0000] {taskinstance.py:2193} INFO - Starting attempt 1 of 1
[2024-07-16T17:10:13.670+0000] {taskinstance.py:2217} INFO - Executing <Task(PythonOperator): payment> on 2024-07-15 00:00:00+00:00
[2024-07-16T17:10:13.702+0000] {standard_task_runner.py:87} INFO - Running: ['***', 'tasks', 'run', 'staigingtodv', 'payment', 'scheduled__2024-07-15T00:00:00+00:00', '--job-id', '12', '--raw', '--subdir', 'DAGS_FOLDER/dag.py', '--cfg-path', '/tmp/tmpqx96pn08']
[2024-07-16T17:10:13.707+0000] {standard_task_runner.py:88} INFO - Job 12: Subtask payment
[2024-07-16T17:10:13.695+0000] {standard_task_runner.py:60} INFO - Started process 102 to run task
[2024-07-16T17:10:14.041+0000] {task_command.py:423} INFO - Running <TaskInstance: staigingtodv.payment scheduled__2024-07-15T00:00:00+00:00 [running]> on host a8165c4616a2
[2024-07-16T17:10:15.128+0000] {taskinstance.py:2513} INFO - Exporting env vars: AIRFLOW_CTX_DAG_OWNER='***' AIRFLOW_CTX_DAG_ID='staigingtodv' AIRFLOW_CTX_TASK_ID='payment' AIRFLOW_CTX_EXECUTION_DATE='2024-07-15T00:00:00+00:00' AIRFLOW_CTX_TRY_NUMBER='1' AIRFLOW_CTX_DAG_RUN_ID='scheduled__2024-07-15T00:00:00+00:00'
[2024-07-16T17:10:15.158+0000] {taskinstance.py:2731} ERROR - Task failed with exception
Traceback (most recent call last):
  File "/home/airflow/.local/lib/python3.8/site-packages/airflow/models/taskinstance.py", line 444, in _execute_task
    result = _execute_callable(context=context, **execute_callable_kwargs)
  File "/home/airflow/.local/lib/python3.8/site-packages/airflow/models/taskinstance.py", line 414, in _execute_callable
    return execute_callable(context=context, **execute_callable_kwargs)
  File "/home/airflow/.local/lib/python3.8/site-packages/airflow/operators/python.py", line 200, in execute
    return_value = self.execute_callable()
  File "/home/airflow/.local/lib/python3.8/site-packages/airflow/operators/python.py", line 217, in execute_callable
    return self.python_callable(*self.op_args, **self.op_kwargs)
  File "/opt/airflow/dags/dag.py", line 40, in process_table
    tabletype = get_data_from_conf_table(table,stage)['tabletype'].values[0]
  File "/opt/airflow/dags/dag.py", line 33, in get_data_from_conf_table
    df.columns = [desc[0] for desc in cur.description]
  File "/home/airflow/.local/lib/python3.8/site-packages/pandas/core/generic.py", line 6002, in __setattr__
    return object.__setattr__(self, name, value)
  File "pandas/_libs/properties.pyx", line 69, in pandas._libs.properties.AxisProperty.__set__
  File "/home/airflow/.local/lib/python3.8/site-packages/pandas/core/generic.py", line 730, in _set_axis
    self._mgr.set_axis(axis, labels)
  File "/home/airflow/.local/lib/python3.8/site-packages/pandas/core/internals/managers.py", line 225, in set_axis
    self._validate_set_axis(axis, new_labels)
  File "/home/airflow/.local/lib/python3.8/site-packages/pandas/core/internals/base.py", line 70, in _validate_set_axis
    raise ValueError(
ValueError: Length mismatch: Expected axis has 0 elements, new values have 15 elements
[2024-07-16T17:10:15.180+0000] {taskinstance.py:1149} INFO - Marking task as FAILED. dag_id=staigingtodv, task_id=payment, execution_date=20240715T000000, start_date=20240716T171013, end_date=20240716T171015
[2024-07-16T17:10:15.212+0000] {standard_task_runner.py:107} ERROR - Failed to execute job 12 for task payment (Length mismatch: Expected axis has 0 elements, new values have 15 elements; 102)
[2024-07-16T17:10:15.268+0000] {local_task_job_runner.py:234} INFO - Task exited with return code 1
[2024-07-16T17:10:15.330+0000] {taskinstance.py:3312} INFO - 0 downstream tasks scheduled from follow-on schedule check
