[2024-07-22T18:39:30.224+0000] {taskinstance.py:1979} INFO - Dependencies all met for dep_context=non-requeueable deps ti=<TaskInstance: stagingtodv.staff scheduled__2024-07-21T00:00:00+00:00 [queued]>
[2024-07-22T18:39:30.233+0000] {taskinstance.py:1979} INFO - Dependencies all met for dep_context=requeueable deps ti=<TaskInstance: stagingtodv.staff scheduled__2024-07-21T00:00:00+00:00 [queued]>
[2024-07-22T18:39:30.234+0000] {taskinstance.py:2193} INFO - Starting attempt 1 of 1
[2024-07-22T18:39:30.243+0000] {taskinstance.py:2217} INFO - Executing <Task(PythonOperator): staff> on 2024-07-21 00:00:00+00:00
[2024-07-22T18:39:30.247+0000] {standard_task_runner.py:60} INFO - Started process 137 to run task
[2024-07-22T18:39:30.256+0000] {standard_task_runner.py:87} INFO - Running: ['***', 'tasks', 'run', 'stagingtodv', 'staff', 'scheduled__2024-07-21T00:00:00+00:00', '--job-id', '46', '--raw', '--subdir', 'DAGS_FOLDER/dag.py', '--cfg-path', '/tmp/tmpr92875l2']
[2024-07-22T18:39:30.259+0000] {standard_task_runner.py:88} INFO - Job 46: Subtask staff
[2024-07-22T18:39:30.301+0000] {task_command.py:423} INFO - Running <TaskInstance: stagingtodv.staff scheduled__2024-07-21T00:00:00+00:00 [running]> on host ef8b8dee6045
[2024-07-22T18:39:30.427+0000] {taskinstance.py:2513} INFO - Exporting env vars: AIRFLOW_CTX_DAG_OWNER='***' AIRFLOW_CTX_DAG_ID='stagingtodv' AIRFLOW_CTX_TASK_ID='staff' AIRFLOW_CTX_EXECUTION_DATE='2024-07-21T00:00:00+00:00' AIRFLOW_CTX_TRY_NUMBER='1' AIRFLOW_CTX_DAG_RUN_ID='scheduled__2024-07-21T00:00:00+00:00'
[2024-07-22T18:39:30.431+0000] {logging_mixin.py:188} INFO - -------------------------------------------- select *  from etlconf.Etl_Process_Mapping where SourceTableName = 'staff' and Stage = 'stagingtodv'
[2024-07-22T18:39:30.661+0000] {taskinstance.py:2731} ERROR - Task failed with exception
Traceback (most recent call last):
  File "/home/airflow/.local/lib/python3.8/site-packages/airflow/models/taskinstance.py", line 444, in _execute_task
    result = _execute_callable(context=context, **execute_callable_kwargs)
  File "/home/airflow/.local/lib/python3.8/site-packages/airflow/models/taskinstance.py", line 414, in _execute_callable
    return execute_callable(context=context, **execute_callable_kwargs)
  File "/home/airflow/.local/lib/python3.8/site-packages/airflow/operators/python.py", line 200, in execute
    return_value = self.execute_callable()
  File "/home/airflow/.local/lib/python3.8/site-packages/airflow/operators/python.py", line 217, in execute_callable
    return self.python_callable(*self.op_args, **self.op_kwargs)
  File "/opt/airflow/dags/dag.py", line 41, in process_table
    tabletype = get_data_from_conf_table(table,stage)['tabletype'].values[0]
  File "/opt/airflow/dags/dag.py", line 34, in get_data_from_conf_table
    df.columns = [desc[0] for desc in cur.description]
  File "/home/airflow/.local/lib/python3.8/site-packages/pandas/core/generic.py", line 6002, in __setattr__
    return object.__setattr__(self, name, value)
  File "pandas/_libs/properties.pyx", line 69, in pandas._libs.properties.AxisProperty.__set__
  File "/home/airflow/.local/lib/python3.8/site-packages/pandas/core/generic.py", line 730, in _set_axis
    self._mgr.set_axis(axis, labels)
  File "/home/airflow/.local/lib/python3.8/site-packages/pandas/core/internals/managers.py", line 225, in set_axis
    self._validate_set_axis(axis, new_labels)
  File "/home/airflow/.local/lib/python3.8/site-packages/pandas/core/internals/base.py", line 70, in _validate_set_axis
    raise ValueError(
ValueError: Length mismatch: Expected axis has 0 elements, new values have 15 elements
[2024-07-22T18:39:30.672+0000] {taskinstance.py:1149} INFO - Marking task as FAILED. dag_id=stagingtodv, task_id=staff, execution_date=20240721T000000, start_date=20240722T183930, end_date=20240722T183930
[2024-07-22T18:39:30.684+0000] {standard_task_runner.py:107} ERROR - Failed to execute job 46 for task staff (Length mismatch: Expected axis has 0 elements, new values have 15 elements; 137)
[2024-07-22T18:39:30.734+0000] {local_task_job_runner.py:234} INFO - Task exited with return code 1
[2024-07-22T18:39:30.759+0000] {taskinstance.py:3312} INFO - 0 downstream tasks scheduled from follow-on schedule check
[2024-07-22T19:05:06.687+0000] {taskinstance.py:1979} INFO - Dependencies all met for dep_context=non-requeueable deps ti=<TaskInstance: stagingtodv.staff scheduled__2024-07-21T00:00:00+00:00 [queued]>
[2024-07-22T19:05:06.709+0000] {taskinstance.py:1979} INFO - Dependencies all met for dep_context=requeueable deps ti=<TaskInstance: stagingtodv.staff scheduled__2024-07-21T00:00:00+00:00 [queued]>
[2024-07-22T19:05:06.720+0000] {taskinstance.py:2193} INFO - Starting attempt 1 of 1
[2024-07-22T19:05:06.760+0000] {taskinstance.py:2217} INFO - Executing <Task(PythonOperator): staff> on 2024-07-21 00:00:00+00:00
[2024-07-22T19:05:06.768+0000] {standard_task_runner.py:60} INFO - Started process 89 to run task
[2024-07-22T19:05:06.784+0000] {standard_task_runner.py:87} INFO - Running: ['***', 'tasks', 'run', 'stagingtodv', 'staff', 'scheduled__2024-07-21T00:00:00+00:00', '--job-id', '3', '--raw', '--subdir', 'DAGS_FOLDER/dag.py', '--cfg-path', '/tmp/tmpuxnuzm5j']
[2024-07-22T19:05:06.810+0000] {standard_task_runner.py:88} INFO - Job 3: Subtask staff
[2024-07-22T19:05:06.917+0000] {task_command.py:423} INFO - Running <TaskInstance: stagingtodv.staff scheduled__2024-07-21T00:00:00+00:00 [running]> on host d97758bf7368
[2024-07-22T19:05:08.343+0000] {taskinstance.py:2513} INFO - Exporting env vars: AIRFLOW_CTX_DAG_OWNER='***' AIRFLOW_CTX_DAG_ID='stagingtodv' AIRFLOW_CTX_TASK_ID='staff' AIRFLOW_CTX_EXECUTION_DATE='2024-07-21T00:00:00+00:00' AIRFLOW_CTX_TRY_NUMBER='1' AIRFLOW_CTX_DAG_RUN_ID='scheduled__2024-07-21T00:00:00+00:00'
[2024-07-22T19:05:08.347+0000] {logging_mixin.py:188} INFO - -------------------------------------------- select *  from etlconf.Etl_Process_Mapping where SourceTableName = 'staff' and Stage = 'stagingtodv'
[2024-07-22T19:05:08.501+0000] {taskinstance.py:2731} ERROR - Task failed with exception
Traceback (most recent call last):
  File "/home/airflow/.local/lib/python3.8/site-packages/airflow/models/taskinstance.py", line 444, in _execute_task
    result = _execute_callable(context=context, **execute_callable_kwargs)
  File "/home/airflow/.local/lib/python3.8/site-packages/airflow/models/taskinstance.py", line 414, in _execute_callable
    return execute_callable(context=context, **execute_callable_kwargs)
  File "/home/airflow/.local/lib/python3.8/site-packages/airflow/operators/python.py", line 200, in execute
    return_value = self.execute_callable()
  File "/home/airflow/.local/lib/python3.8/site-packages/airflow/operators/python.py", line 217, in execute_callable
    return self.python_callable(*self.op_args, **self.op_kwargs)
  File "/opt/airflow/dags/dag.py", line 41, in process_table
    tabletype = get_data_from_conf_table(table,stage)['tabletype'].values[0]
  File "/opt/airflow/dags/dag.py", line 34, in get_data_from_conf_table
    df.columns = [desc[0] for desc in cur.description]
  File "/home/airflow/.local/lib/python3.8/site-packages/pandas/core/generic.py", line 6002, in __setattr__
    return object.__setattr__(self, name, value)
  File "pandas/_libs/properties.pyx", line 69, in pandas._libs.properties.AxisProperty.__set__
  File "/home/airflow/.local/lib/python3.8/site-packages/pandas/core/generic.py", line 730, in _set_axis
    self._mgr.set_axis(axis, labels)
  File "/home/airflow/.local/lib/python3.8/site-packages/pandas/core/internals/managers.py", line 225, in set_axis
    self._validate_set_axis(axis, new_labels)
  File "/home/airflow/.local/lib/python3.8/site-packages/pandas/core/internals/base.py", line 70, in _validate_set_axis
    raise ValueError(
ValueError: Length mismatch: Expected axis has 0 elements, new values have 15 elements
[2024-07-22T19:05:08.553+0000] {taskinstance.py:1149} INFO - Marking task as FAILED. dag_id=stagingtodv, task_id=staff, execution_date=20240721T000000, start_date=20240722T190506, end_date=20240722T190508
[2024-07-22T19:05:08.577+0000] {standard_task_runner.py:107} ERROR - Failed to execute job 3 for task staff (Length mismatch: Expected axis has 0 elements, new values have 15 elements; 89)
[2024-07-22T19:05:08.628+0000] {local_task_job_runner.py:234} INFO - Task exited with return code 1
[2024-07-22T19:05:08.646+0000] {taskinstance.py:3312} INFO - 0 downstream tasks scheduled from follow-on schedule check
[2024-07-22T19:14:28.055+0000] {taskinstance.py:1979} INFO - Dependencies all met for dep_context=non-requeueable deps ti=<TaskInstance: stagingtodv.staff scheduled__2024-07-21T00:00:00+00:00 [queued]>
[2024-07-22T19:14:28.078+0000] {taskinstance.py:1979} INFO - Dependencies all met for dep_context=requeueable deps ti=<TaskInstance: stagingtodv.staff scheduled__2024-07-21T00:00:00+00:00 [queued]>
[2024-07-22T19:14:28.081+0000] {taskinstance.py:2193} INFO - Starting attempt 1 of 1
[2024-07-22T19:14:28.126+0000] {taskinstance.py:2217} INFO - Executing <Task(PythonOperator): staff> on 2024-07-21 00:00:00+00:00
[2024-07-22T19:14:28.140+0000] {standard_task_runner.py:60} INFO - Started process 91 to run task
[2024-07-22T19:14:28.159+0000] {standard_task_runner.py:87} INFO - Running: ['***', 'tasks', 'run', 'stagingtodv', 'staff', 'scheduled__2024-07-21T00:00:00+00:00', '--job-id', '10', '--raw', '--subdir', 'DAGS_FOLDER/dag.py', '--cfg-path', '/tmp/tmpz5fagfuz']
[2024-07-22T19:14:28.163+0000] {standard_task_runner.py:88} INFO - Job 10: Subtask staff
[2024-07-22T19:14:28.338+0000] {task_command.py:423} INFO - Running <TaskInstance: stagingtodv.staff scheduled__2024-07-21T00:00:00+00:00 [running]> on host 06b045a8c1a2
[2024-07-22T19:14:29.329+0000] {taskinstance.py:2513} INFO - Exporting env vars: AIRFLOW_CTX_DAG_OWNER='***' AIRFLOW_CTX_DAG_ID='stagingtodv' AIRFLOW_CTX_TASK_ID='staff' AIRFLOW_CTX_EXECUTION_DATE='2024-07-21T00:00:00+00:00' AIRFLOW_CTX_TRY_NUMBER='1' AIRFLOW_CTX_DAG_RUN_ID='scheduled__2024-07-21T00:00:00+00:00'
[2024-07-22T19:14:29.338+0000] {logging_mixin.py:188} INFO - -------------------------------------------- select *  from etlconf.Etl_Process_Mapping where SourceTableName = 'staff' and Stage = 'stagingtodv'
[2024-07-22T19:14:29.389+0000] {taskinstance.py:2731} ERROR - Task failed with exception
Traceback (most recent call last):
  File "/home/airflow/.local/lib/python3.8/site-packages/airflow/models/taskinstance.py", line 444, in _execute_task
    result = _execute_callable(context=context, **execute_callable_kwargs)
  File "/home/airflow/.local/lib/python3.8/site-packages/airflow/models/taskinstance.py", line 414, in _execute_callable
    return execute_callable(context=context, **execute_callable_kwargs)
  File "/home/airflow/.local/lib/python3.8/site-packages/airflow/operators/python.py", line 200, in execute
    return_value = self.execute_callable()
  File "/home/airflow/.local/lib/python3.8/site-packages/airflow/operators/python.py", line 217, in execute_callable
    return self.python_callable(*self.op_args, **self.op_kwargs)
  File "/opt/airflow/dags/dag.py", line 41, in process_table
    tabletype = get_data_from_conf_table(table,stage)['tabletype'].values[0]
  File "/opt/airflow/dags/dag.py", line 34, in get_data_from_conf_table
    df.columns = [desc[0] for desc in cur.description]
  File "/home/airflow/.local/lib/python3.8/site-packages/pandas/core/generic.py", line 6002, in __setattr__
    return object.__setattr__(self, name, value)
  File "pandas/_libs/properties.pyx", line 69, in pandas._libs.properties.AxisProperty.__set__
  File "/home/airflow/.local/lib/python3.8/site-packages/pandas/core/generic.py", line 730, in _set_axis
    self._mgr.set_axis(axis, labels)
  File "/home/airflow/.local/lib/python3.8/site-packages/pandas/core/internals/managers.py", line 225, in set_axis
    self._validate_set_axis(axis, new_labels)
  File "/home/airflow/.local/lib/python3.8/site-packages/pandas/core/internals/base.py", line 70, in _validate_set_axis
    raise ValueError(
ValueError: Length mismatch: Expected axis has 0 elements, new values have 15 elements
[2024-07-22T19:14:29.414+0000] {taskinstance.py:1149} INFO - Marking task as FAILED. dag_id=stagingtodv, task_id=staff, execution_date=20240721T000000, start_date=20240722T191428, end_date=20240722T191429
[2024-07-22T19:14:29.456+0000] {standard_task_runner.py:107} ERROR - Failed to execute job 10 for task staff (Length mismatch: Expected axis has 0 elements, new values have 15 elements; 91)
[2024-07-22T19:14:29.533+0000] {local_task_job_runner.py:234} INFO - Task exited with return code 1
[2024-07-22T19:14:29.620+0000] {taskinstance.py:3312} INFO - 0 downstream tasks scheduled from follow-on schedule check
[2024-07-22T19:18:50.064+0000] {taskinstance.py:1979} INFO - Dependencies all met for dep_context=non-requeueable deps ti=<TaskInstance: stagingtodv.staff scheduled__2024-07-21T00:00:00+00:00 [queued]>
[2024-07-22T19:18:50.097+0000] {taskinstance.py:1979} INFO - Dependencies all met for dep_context=requeueable deps ti=<TaskInstance: stagingtodv.staff scheduled__2024-07-21T00:00:00+00:00 [queued]>
[2024-07-22T19:18:50.104+0000] {taskinstance.py:2193} INFO - Starting attempt 1 of 1
[2024-07-22T19:18:50.196+0000] {taskinstance.py:2217} INFO - Executing <Task(PythonOperator): staff> on 2024-07-21 00:00:00+00:00
[2024-07-22T19:18:50.258+0000] {standard_task_runner.py:60} INFO - Started process 103 to run task
[2024-07-22T19:18:50.280+0000] {standard_task_runner.py:87} INFO - Running: ['***', 'tasks', 'run', 'stagingtodv', 'staff', 'scheduled__2024-07-21T00:00:00+00:00', '--job-id', '15', '--raw', '--subdir', 'DAGS_FOLDER/dag.py', '--cfg-path', '/tmp/tmp1bl1332h']
[2024-07-22T19:18:50.298+0000] {standard_task_runner.py:88} INFO - Job 15: Subtask staff
[2024-07-22T19:18:50.480+0000] {task_command.py:423} INFO - Running <TaskInstance: stagingtodv.staff scheduled__2024-07-21T00:00:00+00:00 [running]> on host 59af9ef614d6
[2024-07-22T19:18:51.509+0000] {taskinstance.py:2513} INFO - Exporting env vars: AIRFLOW_CTX_DAG_OWNER='***' AIRFLOW_CTX_DAG_ID='stagingtodv' AIRFLOW_CTX_TASK_ID='staff' AIRFLOW_CTX_EXECUTION_DATE='2024-07-21T00:00:00+00:00' AIRFLOW_CTX_TRY_NUMBER='1' AIRFLOW_CTX_DAG_RUN_ID='scheduled__2024-07-21T00:00:00+00:00'
[2024-07-22T19:18:51.519+0000] {logging_mixin.py:188} INFO - -------------------------------------------- select *  from etlconf.Etl_Process_Mapping where SourceTableName = 'staff' and Stage = 'stagingtodv'
[2024-07-22T19:18:51.571+0000] {taskinstance.py:2731} ERROR - Task failed with exception
Traceback (most recent call last):
  File "/home/airflow/.local/lib/python3.8/site-packages/airflow/models/taskinstance.py", line 444, in _execute_task
    result = _execute_callable(context=context, **execute_callable_kwargs)
  File "/home/airflow/.local/lib/python3.8/site-packages/airflow/models/taskinstance.py", line 414, in _execute_callable
    return execute_callable(context=context, **execute_callable_kwargs)
  File "/home/airflow/.local/lib/python3.8/site-packages/airflow/operators/python.py", line 200, in execute
    return_value = self.execute_callable()
  File "/home/airflow/.local/lib/python3.8/site-packages/airflow/operators/python.py", line 217, in execute_callable
    return self.python_callable(*self.op_args, **self.op_kwargs)
  File "/opt/airflow/dags/dag.py", line 41, in process_table
    tabletype = get_data_from_conf_table(table,stage)['tabletype'].values[0]
  File "/opt/airflow/dags/dag.py", line 34, in get_data_from_conf_table
    df.columns = [desc[0] for desc in cur.description]
  File "/home/airflow/.local/lib/python3.8/site-packages/pandas/core/generic.py", line 6002, in __setattr__
    return object.__setattr__(self, name, value)
  File "pandas/_libs/properties.pyx", line 69, in pandas._libs.properties.AxisProperty.__set__
  File "/home/airflow/.local/lib/python3.8/site-packages/pandas/core/generic.py", line 730, in _set_axis
    self._mgr.set_axis(axis, labels)
  File "/home/airflow/.local/lib/python3.8/site-packages/pandas/core/internals/managers.py", line 225, in set_axis
    self._validate_set_axis(axis, new_labels)
  File "/home/airflow/.local/lib/python3.8/site-packages/pandas/core/internals/base.py", line 70, in _validate_set_axis
    raise ValueError(
ValueError: Length mismatch: Expected axis has 0 elements, new values have 15 elements
[2024-07-22T19:18:51.590+0000] {taskinstance.py:1149} INFO - Marking task as FAILED. dag_id=stagingtodv, task_id=staff, execution_date=20240721T000000, start_date=20240722T191850, end_date=20240722T191851
[2024-07-22T19:18:51.600+0000] {standard_task_runner.py:107} ERROR - Failed to execute job 15 for task staff (Length mismatch: Expected axis has 0 elements, new values have 15 elements; 103)
[2024-07-22T19:18:51.633+0000] {local_task_job_runner.py:234} INFO - Task exited with return code 1
[2024-07-22T19:18:51.665+0000] {taskinstance.py:3312} INFO - 0 downstream tasks scheduled from follow-on schedule check
[2024-07-22T19:25:04.145+0000] {taskinstance.py:1979} INFO - Dependencies all met for dep_context=non-requeueable deps ti=<TaskInstance: stagingtodv.staff scheduled__2024-07-21T00:00:00+00:00 [queued]>
[2024-07-22T19:25:04.179+0000] {taskinstance.py:1979} INFO - Dependencies all met for dep_context=requeueable deps ti=<TaskInstance: stagingtodv.staff scheduled__2024-07-21T00:00:00+00:00 [queued]>
[2024-07-22T19:25:04.184+0000] {taskinstance.py:2193} INFO - Starting attempt 1 of 1
[2024-07-22T19:25:04.228+0000] {taskinstance.py:2217} INFO - Executing <Task(PythonOperator): staff> on 2024-07-21 00:00:00+00:00
[2024-07-22T19:25:04.239+0000] {standard_task_runner.py:60} INFO - Started process 95 to run task
[2024-07-22T19:25:04.251+0000] {standard_task_runner.py:87} INFO - Running: ['***', 'tasks', 'run', 'stagingtodv', 'staff', 'scheduled__2024-07-21T00:00:00+00:00', '--job-id', '9', '--raw', '--subdir', 'DAGS_FOLDER/dag.py', '--cfg-path', '/tmp/tmpiic35bfw']
[2024-07-22T19:25:04.263+0000] {standard_task_runner.py:88} INFO - Job 9: Subtask staff
[2024-07-22T19:25:04.427+0000] {task_command.py:423} INFO - Running <TaskInstance: stagingtodv.staff scheduled__2024-07-21T00:00:00+00:00 [running]> on host 54d412404717
[2024-07-22T19:25:05.651+0000] {taskinstance.py:2513} INFO - Exporting env vars: AIRFLOW_CTX_DAG_OWNER='***' AIRFLOW_CTX_DAG_ID='stagingtodv' AIRFLOW_CTX_TASK_ID='staff' AIRFLOW_CTX_EXECUTION_DATE='2024-07-21T00:00:00+00:00' AIRFLOW_CTX_TRY_NUMBER='1' AIRFLOW_CTX_DAG_RUN_ID='scheduled__2024-07-21T00:00:00+00:00'
[2024-07-22T19:25:05.658+0000] {logging_mixin.py:188} INFO - -------------------------------------------- select *  from etlconf.Etl_Process_Mapping where SourceTableName = 'staff' and Stage = 'stagingtodv'
[2024-07-22T19:25:05.764+0000] {taskinstance.py:2731} ERROR - Task failed with exception
Traceback (most recent call last):
  File "/home/airflow/.local/lib/python3.8/site-packages/airflow/models/taskinstance.py", line 444, in _execute_task
    result = _execute_callable(context=context, **execute_callable_kwargs)
  File "/home/airflow/.local/lib/python3.8/site-packages/airflow/models/taskinstance.py", line 414, in _execute_callable
    return execute_callable(context=context, **execute_callable_kwargs)
  File "/home/airflow/.local/lib/python3.8/site-packages/airflow/operators/python.py", line 200, in execute
    return_value = self.execute_callable()
  File "/home/airflow/.local/lib/python3.8/site-packages/airflow/operators/python.py", line 217, in execute_callable
    return self.python_callable(*self.op_args, **self.op_kwargs)
  File "/opt/airflow/dags/dag.py", line 41, in process_table
    tabletype = get_data_from_conf_table(table,stage)['tabletype'].values[0]
  File "/opt/airflow/dags/dag.py", line 34, in get_data_from_conf_table
    df.columns = [desc[0] for desc in cur.description]
  File "/home/airflow/.local/lib/python3.8/site-packages/pandas/core/generic.py", line 6002, in __setattr__
    return object.__setattr__(self, name, value)
  File "pandas/_libs/properties.pyx", line 69, in pandas._libs.properties.AxisProperty.__set__
  File "/home/airflow/.local/lib/python3.8/site-packages/pandas/core/generic.py", line 730, in _set_axis
    self._mgr.set_axis(axis, labels)
  File "/home/airflow/.local/lib/python3.8/site-packages/pandas/core/internals/managers.py", line 225, in set_axis
    self._validate_set_axis(axis, new_labels)
  File "/home/airflow/.local/lib/python3.8/site-packages/pandas/core/internals/base.py", line 70, in _validate_set_axis
    raise ValueError(
ValueError: Length mismatch: Expected axis has 0 elements, new values have 15 elements
[2024-07-22T19:25:05.788+0000] {taskinstance.py:1149} INFO - Marking task as FAILED. dag_id=stagingtodv, task_id=staff, execution_date=20240721T000000, start_date=20240722T192504, end_date=20240722T192505
[2024-07-22T19:25:05.806+0000] {standard_task_runner.py:107} ERROR - Failed to execute job 9 for task staff (Length mismatch: Expected axis has 0 elements, new values have 15 elements; 95)
[2024-07-22T19:25:05.871+0000] {local_task_job_runner.py:234} INFO - Task exited with return code 1
[2024-07-22T19:25:05.906+0000] {taskinstance.py:3312} INFO - 0 downstream tasks scheduled from follow-on schedule check
[2024-07-22T19:28:23.086+0000] {taskinstance.py:1979} INFO - Dependencies all met for dep_context=non-requeueable deps ti=<TaskInstance: stagingtodv.staff scheduled__2024-07-21T00:00:00+00:00 [queued]>
[2024-07-22T19:28:23.112+0000] {taskinstance.py:1979} INFO - Dependencies all met for dep_context=requeueable deps ti=<TaskInstance: stagingtodv.staff scheduled__2024-07-21T00:00:00+00:00 [queued]>
[2024-07-22T19:28:23.116+0000] {taskinstance.py:2193} INFO - Starting attempt 1 of 1
[2024-07-22T19:28:23.140+0000] {taskinstance.py:2217} INFO - Executing <Task(PythonOperator): staff> on 2024-07-21 00:00:00+00:00
[2024-07-22T19:28:23.153+0000] {standard_task_runner.py:60} INFO - Started process 97 to run task
[2024-07-22T19:28:23.167+0000] {standard_task_runner.py:87} INFO - Running: ['***', 'tasks', 'run', 'stagingtodv', 'staff', 'scheduled__2024-07-21T00:00:00+00:00', '--job-id', '9', '--raw', '--subdir', 'DAGS_FOLDER/dag.py', '--cfg-path', '/tmp/tmpbdl0izg6']
[2024-07-22T19:28:23.182+0000] {standard_task_runner.py:88} INFO - Job 9: Subtask staff
[2024-07-22T19:28:23.340+0000] {task_command.py:423} INFO - Running <TaskInstance: stagingtodv.staff scheduled__2024-07-21T00:00:00+00:00 [running]> on host e6f3df1cbf4c
[2024-07-22T19:28:24.676+0000] {taskinstance.py:2513} INFO - Exporting env vars: AIRFLOW_CTX_DAG_OWNER='***' AIRFLOW_CTX_DAG_ID='stagingtodv' AIRFLOW_CTX_TASK_ID='staff' AIRFLOW_CTX_EXECUTION_DATE='2024-07-21T00:00:00+00:00' AIRFLOW_CTX_TRY_NUMBER='1' AIRFLOW_CTX_DAG_RUN_ID='scheduled__2024-07-21T00:00:00+00:00'
[2024-07-22T19:28:24.685+0000] {logging_mixin.py:188} INFO - -------------------------------------------- select *  from etlconf.Etl_Process_Mapping where SourceTableName = 'staff' and Stage = 'stagingtodv'
[2024-07-22T19:28:24.725+0000] {taskinstance.py:2731} ERROR - Task failed with exception
Traceback (most recent call last):
  File "/home/airflow/.local/lib/python3.8/site-packages/airflow/models/taskinstance.py", line 444, in _execute_task
    result = _execute_callable(context=context, **execute_callable_kwargs)
  File "/home/airflow/.local/lib/python3.8/site-packages/airflow/models/taskinstance.py", line 414, in _execute_callable
    return execute_callable(context=context, **execute_callable_kwargs)
  File "/home/airflow/.local/lib/python3.8/site-packages/airflow/operators/python.py", line 200, in execute
    return_value = self.execute_callable()
  File "/home/airflow/.local/lib/python3.8/site-packages/airflow/operators/python.py", line 217, in execute_callable
    return self.python_callable(*self.op_args, **self.op_kwargs)
  File "/opt/airflow/dags/dag.py", line 41, in process_table
    tabletype = get_data_from_conf_table(table,stage)['tabletype'].values[0]
  File "/opt/airflow/dags/dag.py", line 34, in get_data_from_conf_table
    df.columns = [desc[0] for desc in cur.description]
  File "/home/airflow/.local/lib/python3.8/site-packages/pandas/core/generic.py", line 6002, in __setattr__
    return object.__setattr__(self, name, value)
  File "pandas/_libs/properties.pyx", line 69, in pandas._libs.properties.AxisProperty.__set__
  File "/home/airflow/.local/lib/python3.8/site-packages/pandas/core/generic.py", line 730, in _set_axis
    self._mgr.set_axis(axis, labels)
  File "/home/airflow/.local/lib/python3.8/site-packages/pandas/core/internals/managers.py", line 225, in set_axis
    self._validate_set_axis(axis, new_labels)
  File "/home/airflow/.local/lib/python3.8/site-packages/pandas/core/internals/base.py", line 70, in _validate_set_axis
    raise ValueError(
ValueError: Length mismatch: Expected axis has 0 elements, new values have 15 elements
[2024-07-22T19:28:24.757+0000] {taskinstance.py:1149} INFO - Marking task as FAILED. dag_id=stagingtodv, task_id=staff, execution_date=20240721T000000, start_date=20240722T192823, end_date=20240722T192824
[2024-07-22T19:28:24.790+0000] {standard_task_runner.py:107} ERROR - Failed to execute job 9 for task staff (Length mismatch: Expected axis has 0 elements, new values have 15 elements; 97)
[2024-07-22T19:28:24.827+0000] {local_task_job_runner.py:234} INFO - Task exited with return code 1
[2024-07-22T19:28:24.896+0000] {taskinstance.py:3312} INFO - 0 downstream tasks scheduled from follow-on schedule check
[2024-07-22T19:30:31.947+0000] {taskinstance.py:1979} INFO - Dependencies all met for dep_context=non-requeueable deps ti=<TaskInstance: stagingtodv.staff scheduled__2024-07-21T00:00:00+00:00 [queued]>
[2024-07-22T19:30:31.976+0000] {taskinstance.py:1979} INFO - Dependencies all met for dep_context=requeueable deps ti=<TaskInstance: stagingtodv.staff scheduled__2024-07-21T00:00:00+00:00 [queued]>
[2024-07-22T19:30:31.984+0000] {taskinstance.py:2193} INFO - Starting attempt 1 of 1
[2024-07-22T19:30:32.021+0000] {taskinstance.py:2217} INFO - Executing <Task(PythonOperator): staff> on 2024-07-21 00:00:00+00:00
[2024-07-22T19:30:32.029+0000] {standard_task_runner.py:60} INFO - Started process 93 to run task
[2024-07-22T19:30:32.035+0000] {standard_task_runner.py:87} INFO - Running: ['***', 'tasks', 'run', 'stagingtodv', 'staff', 'scheduled__2024-07-21T00:00:00+00:00', '--job-id', '6', '--raw', '--subdir', 'DAGS_FOLDER/dag.py', '--cfg-path', '/tmp/tmpnj6uskzk']
[2024-07-22T19:30:32.038+0000] {standard_task_runner.py:88} INFO - Job 6: Subtask staff
[2024-07-22T19:30:32.196+0000] {task_command.py:423} INFO - Running <TaskInstance: stagingtodv.staff scheduled__2024-07-21T00:00:00+00:00 [running]> on host 96cb61053a1d
[2024-07-22T19:30:33.686+0000] {taskinstance.py:2513} INFO - Exporting env vars: AIRFLOW_CTX_DAG_OWNER='***' AIRFLOW_CTX_DAG_ID='stagingtodv' AIRFLOW_CTX_TASK_ID='staff' AIRFLOW_CTX_EXECUTION_DATE='2024-07-21T00:00:00+00:00' AIRFLOW_CTX_TRY_NUMBER='1' AIRFLOW_CTX_DAG_RUN_ID='scheduled__2024-07-21T00:00:00+00:00'
[2024-07-22T19:30:33.693+0000] {logging_mixin.py:188} INFO - -------------------------------------------- select *  from etlconf.Etl_Process_Mapping where SourceTableName = 'staff' and Stage = 'stagingtodv'
[2024-07-22T19:30:33.761+0000] {taskinstance.py:2731} ERROR - Task failed with exception
Traceback (most recent call last):
  File "/home/airflow/.local/lib/python3.8/site-packages/airflow/models/taskinstance.py", line 444, in _execute_task
    result = _execute_callable(context=context, **execute_callable_kwargs)
  File "/home/airflow/.local/lib/python3.8/site-packages/airflow/models/taskinstance.py", line 414, in _execute_callable
    return execute_callable(context=context, **execute_callable_kwargs)
  File "/home/airflow/.local/lib/python3.8/site-packages/airflow/operators/python.py", line 200, in execute
    return_value = self.execute_callable()
  File "/home/airflow/.local/lib/python3.8/site-packages/airflow/operators/python.py", line 217, in execute_callable
    return self.python_callable(*self.op_args, **self.op_kwargs)
  File "/opt/airflow/dags/dag.py", line 41, in process_table
    tabletype = get_data_from_conf_table(table,stage)['tabletype'].values[0]
  File "/opt/airflow/dags/dag.py", line 34, in get_data_from_conf_table
    df.columns = [desc[0] for desc in cur.description]
  File "/home/airflow/.local/lib/python3.8/site-packages/pandas/core/generic.py", line 6002, in __setattr__
    return object.__setattr__(self, name, value)
  File "pandas/_libs/properties.pyx", line 69, in pandas._libs.properties.AxisProperty.__set__
  File "/home/airflow/.local/lib/python3.8/site-packages/pandas/core/generic.py", line 730, in _set_axis
    self._mgr.set_axis(axis, labels)
  File "/home/airflow/.local/lib/python3.8/site-packages/pandas/core/internals/managers.py", line 225, in set_axis
    self._validate_set_axis(axis, new_labels)
  File "/home/airflow/.local/lib/python3.8/site-packages/pandas/core/internals/base.py", line 70, in _validate_set_axis
    raise ValueError(
ValueError: Length mismatch: Expected axis has 0 elements, new values have 15 elements
[2024-07-22T19:30:33.775+0000] {taskinstance.py:1149} INFO - Marking task as FAILED. dag_id=stagingtodv, task_id=staff, execution_date=20240721T000000, start_date=20240722T193031, end_date=20240722T193033
[2024-07-22T19:30:33.792+0000] {standard_task_runner.py:107} ERROR - Failed to execute job 6 for task staff (Length mismatch: Expected axis has 0 elements, new values have 15 elements; 93)
[2024-07-22T19:30:33.829+0000] {local_task_job_runner.py:234} INFO - Task exited with return code 1
[2024-07-22T19:30:33.865+0000] {taskinstance.py:3312} INFO - 0 downstream tasks scheduled from follow-on schedule check
[2024-07-22T19:38:48.919+0000] {taskinstance.py:1979} INFO - Dependencies all met for dep_context=non-requeueable deps ti=<TaskInstance: stagingtodv.staff scheduled__2024-07-21T00:00:00+00:00 [queued]>
[2024-07-22T19:38:48.938+0000] {taskinstance.py:1979} INFO - Dependencies all met for dep_context=requeueable deps ti=<TaskInstance: stagingtodv.staff scheduled__2024-07-21T00:00:00+00:00 [queued]>
[2024-07-22T19:38:48.941+0000] {taskinstance.py:2193} INFO - Starting attempt 1 of 1
[2024-07-22T19:38:48.977+0000] {taskinstance.py:2217} INFO - Executing <Task(PythonOperator): staff> on 2024-07-21 00:00:00+00:00
[2024-07-22T19:38:48.997+0000] {standard_task_runner.py:60} INFO - Started process 127 to run task
[2024-07-22T19:38:49.022+0000] {standard_task_runner.py:87} INFO - Running: ['***', 'tasks', 'run', 'stagingtodv', 'staff', 'scheduled__2024-07-21T00:00:00+00:00', '--job-id', '10', '--raw', '--subdir', 'DAGS_FOLDER/dag.py', '--cfg-path', '/tmp/tmp98ddbfbn']
[2024-07-22T19:38:49.040+0000] {standard_task_runner.py:88} INFO - Job 10: Subtask staff
[2024-07-22T19:38:49.177+0000] {task_command.py:423} INFO - Running <TaskInstance: stagingtodv.staff scheduled__2024-07-21T00:00:00+00:00 [running]> on host f5ad498ee7ee
[2024-07-22T19:38:50.905+0000] {taskinstance.py:2513} INFO - Exporting env vars: AIRFLOW_CTX_DAG_OWNER='***' AIRFLOW_CTX_DAG_ID='stagingtodv' AIRFLOW_CTX_TASK_ID='staff' AIRFLOW_CTX_EXECUTION_DATE='2024-07-21T00:00:00+00:00' AIRFLOW_CTX_TRY_NUMBER='1' AIRFLOW_CTX_DAG_RUN_ID='scheduled__2024-07-21T00:00:00+00:00'
[2024-07-22T19:38:50.907+0000] {logging_mixin.py:188} INFO - -------------------------------------------- select *  from etlconf.Etl_Process_Mapping where SourceTableName = 'staff' and Stage = 'stagingtodv'
[2024-07-22T19:38:50.939+0000] {taskinstance.py:2731} ERROR - Task failed with exception
Traceback (most recent call last):
  File "/home/airflow/.local/lib/python3.8/site-packages/airflow/models/taskinstance.py", line 444, in _execute_task
    result = _execute_callable(context=context, **execute_callable_kwargs)
  File "/home/airflow/.local/lib/python3.8/site-packages/airflow/models/taskinstance.py", line 414, in _execute_callable
    return execute_callable(context=context, **execute_callable_kwargs)
  File "/home/airflow/.local/lib/python3.8/site-packages/airflow/operators/python.py", line 200, in execute
    return_value = self.execute_callable()
  File "/home/airflow/.local/lib/python3.8/site-packages/airflow/operators/python.py", line 217, in execute_callable
    return self.python_callable(*self.op_args, **self.op_kwargs)
  File "/opt/airflow/dags/dag.py", line 41, in process_table
    tabletype = get_data_from_conf_table(table,stage)['tabletype'].values[0]
  File "/opt/airflow/dags/dag.py", line 34, in get_data_from_conf_table
    df.columns = [desc[0] for desc in cur.description]
  File "/home/airflow/.local/lib/python3.8/site-packages/pandas/core/generic.py", line 6002, in __setattr__
    return object.__setattr__(self, name, value)
  File "pandas/_libs/properties.pyx", line 69, in pandas._libs.properties.AxisProperty.__set__
  File "/home/airflow/.local/lib/python3.8/site-packages/pandas/core/generic.py", line 730, in _set_axis
    self._mgr.set_axis(axis, labels)
  File "/home/airflow/.local/lib/python3.8/site-packages/pandas/core/internals/managers.py", line 225, in set_axis
    self._validate_set_axis(axis, new_labels)
  File "/home/airflow/.local/lib/python3.8/site-packages/pandas/core/internals/base.py", line 70, in _validate_set_axis
    raise ValueError(
ValueError: Length mismatch: Expected axis has 0 elements, new values have 15 elements
[2024-07-22T19:38:50.953+0000] {taskinstance.py:1149} INFO - Marking task as FAILED. dag_id=stagingtodv, task_id=staff, execution_date=20240721T000000, start_date=20240722T193848, end_date=20240722T193850
[2024-07-22T19:38:50.967+0000] {standard_task_runner.py:107} ERROR - Failed to execute job 10 for task staff (Length mismatch: Expected axis has 0 elements, new values have 15 elements; 127)
[2024-07-22T19:38:50.994+0000] {local_task_job_runner.py:234} INFO - Task exited with return code 1
[2024-07-22T19:38:51.014+0000] {taskinstance.py:3312} INFO - 0 downstream tasks scheduled from follow-on schedule check
[2024-07-22T19:43:44.539+0000] {taskinstance.py:1979} INFO - Dependencies all met for dep_context=non-requeueable deps ti=<TaskInstance: stagingtodv.staff scheduled__2024-07-21T00:00:00+00:00 [queued]>
[2024-07-22T19:43:44.549+0000] {taskinstance.py:1979} INFO - Dependencies all met for dep_context=requeueable deps ti=<TaskInstance: stagingtodv.staff scheduled__2024-07-21T00:00:00+00:00 [queued]>
[2024-07-22T19:43:44.550+0000] {taskinstance.py:2193} INFO - Starting attempt 1 of 1
[2024-07-22T19:43:44.574+0000] {taskinstance.py:2217} INFO - Executing <Task(PythonOperator): staff> on 2024-07-21 00:00:00+00:00
[2024-07-22T19:43:44.592+0000] {standard_task_runner.py:60} INFO - Started process 115 to run task
[2024-07-22T19:43:44.615+0000] {standard_task_runner.py:87} INFO - Running: ['***', 'tasks', 'run', 'stagingtodv', 'staff', 'scheduled__2024-07-21T00:00:00+00:00', '--job-id', '4', '--raw', '--subdir', 'DAGS_FOLDER/dag.py', '--cfg-path', '/tmp/tmp4p9mab01']
[2024-07-22T19:43:44.653+0000] {standard_task_runner.py:88} INFO - Job 4: Subtask staff
[2024-07-22T19:43:44.938+0000] {task_command.py:423} INFO - Running <TaskInstance: stagingtodv.staff scheduled__2024-07-21T00:00:00+00:00 [running]> on host 83712395e44a
[2024-07-22T19:43:46.358+0000] {taskinstance.py:2513} INFO - Exporting env vars: AIRFLOW_CTX_DAG_OWNER='***' AIRFLOW_CTX_DAG_ID='stagingtodv' AIRFLOW_CTX_TASK_ID='staff' AIRFLOW_CTX_EXECUTION_DATE='2024-07-21T00:00:00+00:00' AIRFLOW_CTX_TRY_NUMBER='1' AIRFLOW_CTX_DAG_RUN_ID='scheduled__2024-07-21T00:00:00+00:00'
[2024-07-22T19:43:46.359+0000] {logging_mixin.py:188} INFO - -------------------------------------------- select *  from etlconf.Etl_Process_Mapping where SourceTableName = 'staff' and Stage = 'stagingtodv'
[2024-07-22T19:43:46.400+0000] {taskinstance.py:2731} ERROR - Task failed with exception
Traceback (most recent call last):
  File "/home/airflow/.local/lib/python3.8/site-packages/airflow/models/taskinstance.py", line 444, in _execute_task
    result = _execute_callable(context=context, **execute_callable_kwargs)
  File "/home/airflow/.local/lib/python3.8/site-packages/airflow/models/taskinstance.py", line 414, in _execute_callable
    return execute_callable(context=context, **execute_callable_kwargs)
  File "/home/airflow/.local/lib/python3.8/site-packages/airflow/operators/python.py", line 200, in execute
    return_value = self.execute_callable()
  File "/home/airflow/.local/lib/python3.8/site-packages/airflow/operators/python.py", line 217, in execute_callable
    return self.python_callable(*self.op_args, **self.op_kwargs)
  File "/opt/airflow/dags/dag.py", line 41, in process_table
    tabletype = get_data_from_conf_table(table,stage)['tabletype'].values[0]
  File "/opt/airflow/dags/dag.py", line 34, in get_data_from_conf_table
    df.columns = [desc[0] for desc in cur.description]
  File "/home/airflow/.local/lib/python3.8/site-packages/pandas/core/generic.py", line 6002, in __setattr__
    return object.__setattr__(self, name, value)
  File "pandas/_libs/properties.pyx", line 69, in pandas._libs.properties.AxisProperty.__set__
  File "/home/airflow/.local/lib/python3.8/site-packages/pandas/core/generic.py", line 730, in _set_axis
    self._mgr.set_axis(axis, labels)
  File "/home/airflow/.local/lib/python3.8/site-packages/pandas/core/internals/managers.py", line 225, in set_axis
    self._validate_set_axis(axis, new_labels)
  File "/home/airflow/.local/lib/python3.8/site-packages/pandas/core/internals/base.py", line 70, in _validate_set_axis
    raise ValueError(
ValueError: Length mismatch: Expected axis has 0 elements, new values have 15 elements
[2024-07-22T19:43:46.418+0000] {taskinstance.py:1149} INFO - Marking task as FAILED. dag_id=stagingtodv, task_id=staff, execution_date=20240721T000000, start_date=20240722T194344, end_date=20240722T194346
[2024-07-22T19:43:46.431+0000] {standard_task_runner.py:107} ERROR - Failed to execute job 4 for task staff (Length mismatch: Expected axis has 0 elements, new values have 15 elements; 115)
[2024-07-22T19:43:46.478+0000] {local_task_job_runner.py:234} INFO - Task exited with return code 1
[2024-07-22T19:43:46.493+0000] {taskinstance.py:3312} INFO - 0 downstream tasks scheduled from follow-on schedule check
[2024-07-22T19:52:47.045+0000] {taskinstance.py:1979} INFO - Dependencies all met for dep_context=non-requeueable deps ti=<TaskInstance: stagingtodv.staff scheduled__2024-07-21T00:00:00+00:00 [queued]>
[2024-07-22T19:52:47.061+0000] {taskinstance.py:1979} INFO - Dependencies all met for dep_context=requeueable deps ti=<TaskInstance: stagingtodv.staff scheduled__2024-07-21T00:00:00+00:00 [queued]>
[2024-07-22T19:52:47.064+0000] {taskinstance.py:2193} INFO - Starting attempt 1 of 1
[2024-07-22T19:52:47.108+0000] {taskinstance.py:2217} INFO - Executing <Task(PythonOperator): staff> on 2024-07-21 00:00:00+00:00
[2024-07-22T19:52:47.162+0000] {standard_task_runner.py:60} INFO - Started process 101 to run task
[2024-07-22T19:52:47.174+0000] {standard_task_runner.py:87} INFO - Running: ['***', 'tasks', 'run', 'stagingtodv', 'staff', 'scheduled__2024-07-21T00:00:00+00:00', '--job-id', '14', '--raw', '--subdir', 'DAGS_FOLDER/dag.py', '--cfg-path', '/tmp/tmpv6c1q44j']
[2024-07-22T19:52:47.184+0000] {standard_task_runner.py:88} INFO - Job 14: Subtask staff
[2024-07-22T19:52:47.386+0000] {task_command.py:423} INFO - Running <TaskInstance: stagingtodv.staff scheduled__2024-07-21T00:00:00+00:00 [running]> on host 6e14590d795e
[2024-07-22T19:52:47.580+0000] {taskinstance.py:2513} INFO - Exporting env vars: AIRFLOW_CTX_DAG_OWNER='***' AIRFLOW_CTX_DAG_ID='stagingtodv' AIRFLOW_CTX_TASK_ID='staff' AIRFLOW_CTX_EXECUTION_DATE='2024-07-21T00:00:00+00:00' AIRFLOW_CTX_TRY_NUMBER='1' AIRFLOW_CTX_DAG_RUN_ID='scheduled__2024-07-21T00:00:00+00:00'
[2024-07-22T19:52:47.591+0000] {logging_mixin.py:188} INFO - -------------------------------------------- select *  from etlconf.Etl_Process_Mapping where SourceTableName = 'staff' and Stage = 'stagingtodv'
[2024-07-22T19:52:48.856+0000] {taskinstance.py:2731} ERROR - Task failed with exception
Traceback (most recent call last):
  File "/home/airflow/.local/lib/python3.8/site-packages/airflow/models/taskinstance.py", line 444, in _execute_task
    result = _execute_callable(context=context, **execute_callable_kwargs)
  File "/home/airflow/.local/lib/python3.8/site-packages/airflow/models/taskinstance.py", line 414, in _execute_callable
    return execute_callable(context=context, **execute_callable_kwargs)
  File "/home/airflow/.local/lib/python3.8/site-packages/airflow/operators/python.py", line 200, in execute
    return_value = self.execute_callable()
  File "/home/airflow/.local/lib/python3.8/site-packages/airflow/operators/python.py", line 217, in execute_callable
    return self.python_callable(*self.op_args, **self.op_kwargs)
  File "/opt/airflow/dags/dag.py", line 41, in process_table
    tabletype = get_data_from_conf_table(table,stage)['tabletype'].values[0]
  File "/opt/airflow/dags/dag.py", line 34, in get_data_from_conf_table
    df.columns = [desc[0] for desc in cur.description]
  File "/home/airflow/.local/lib/python3.8/site-packages/pandas/core/generic.py", line 6002, in __setattr__
    return object.__setattr__(self, name, value)
  File "pandas/_libs/properties.pyx", line 69, in pandas._libs.properties.AxisProperty.__set__
  File "/home/airflow/.local/lib/python3.8/site-packages/pandas/core/generic.py", line 730, in _set_axis
    self._mgr.set_axis(axis, labels)
  File "/home/airflow/.local/lib/python3.8/site-packages/pandas/core/internals/managers.py", line 225, in set_axis
    self._validate_set_axis(axis, new_labels)
  File "/home/airflow/.local/lib/python3.8/site-packages/pandas/core/internals/base.py", line 70, in _validate_set_axis
    raise ValueError(
ValueError: Length mismatch: Expected axis has 0 elements, new values have 15 elements
[2024-07-22T19:52:48.879+0000] {taskinstance.py:1149} INFO - Marking task as FAILED. dag_id=stagingtodv, task_id=staff, execution_date=20240721T000000, start_date=20240722T195247, end_date=20240722T195248
[2024-07-22T19:52:48.902+0000] {standard_task_runner.py:107} ERROR - Failed to execute job 14 for task staff (Length mismatch: Expected axis has 0 elements, new values have 15 elements; 101)
[2024-07-22T19:52:48.938+0000] {local_task_job_runner.py:234} INFO - Task exited with return code 1
[2024-07-22T19:52:48.966+0000] {taskinstance.py:3312} INFO - 0 downstream tasks scheduled from follow-on schedule check
[2024-07-22T19:57:18.831+0000] {taskinstance.py:1979} INFO - Dependencies all met for dep_context=non-requeueable deps ti=<TaskInstance: stagingtodv.staff scheduled__2024-07-21T00:00:00+00:00 [queued]>
[2024-07-22T19:57:18.858+0000] {taskinstance.py:1979} INFO - Dependencies all met for dep_context=requeueable deps ti=<TaskInstance: stagingtodv.staff scheduled__2024-07-21T00:00:00+00:00 [queued]>
[2024-07-22T19:57:18.860+0000] {taskinstance.py:2193} INFO - Starting attempt 1 of 1
[2024-07-22T19:57:18.909+0000] {taskinstance.py:2217} INFO - Executing <Task(PythonOperator): staff> on 2024-07-21 00:00:00+00:00
[2024-07-22T19:57:18.925+0000] {standard_task_runner.py:60} INFO - Started process 88 to run task
[2024-07-22T19:57:18.929+0000] {standard_task_runner.py:87} INFO - Running: ['***', 'tasks', 'run', 'stagingtodv', 'staff', 'scheduled__2024-07-21T00:00:00+00:00', '--job-id', '4', '--raw', '--subdir', 'DAGS_FOLDER/dag.py', '--cfg-path', '/tmp/tmpzrjq_h3f']
[2024-07-22T19:57:18.939+0000] {standard_task_runner.py:88} INFO - Job 4: Subtask staff
[2024-07-22T19:57:19.065+0000] {task_command.py:423} INFO - Running <TaskInstance: stagingtodv.staff scheduled__2024-07-21T00:00:00+00:00 [running]> on host 1ca6b70ca81e
[2024-07-22T19:57:20.086+0000] {taskinstance.py:2513} INFO - Exporting env vars: AIRFLOW_CTX_DAG_OWNER='***' AIRFLOW_CTX_DAG_ID='stagingtodv' AIRFLOW_CTX_TASK_ID='staff' AIRFLOW_CTX_EXECUTION_DATE='2024-07-21T00:00:00+00:00' AIRFLOW_CTX_TRY_NUMBER='1' AIRFLOW_CTX_DAG_RUN_ID='scheduled__2024-07-21T00:00:00+00:00'
[2024-07-22T19:57:20.088+0000] {logging_mixin.py:188} INFO - -------------------------------------------- select *  from etlconf.Etl_Process_Mapping where SourceTableName = 'staff' and Stage = 'stagingtodv'
[2024-07-22T19:57:20.503+0000] {taskinstance.py:2731} ERROR - Task failed with exception
Traceback (most recent call last):
  File "/home/airflow/.local/lib/python3.8/site-packages/airflow/models/taskinstance.py", line 444, in _execute_task
    result = _execute_callable(context=context, **execute_callable_kwargs)
  File "/home/airflow/.local/lib/python3.8/site-packages/airflow/models/taskinstance.py", line 414, in _execute_callable
    return execute_callable(context=context, **execute_callable_kwargs)
  File "/home/airflow/.local/lib/python3.8/site-packages/airflow/operators/python.py", line 200, in execute
    return_value = self.execute_callable()
  File "/home/airflow/.local/lib/python3.8/site-packages/airflow/operators/python.py", line 217, in execute_callable
    return self.python_callable(*self.op_args, **self.op_kwargs)
  File "/opt/airflow/dags/dag.py", line 41, in process_table
    tabletype = get_data_from_conf_table(table,stage)['tabletype'].values[0]
  File "/opt/airflow/dags/dag.py", line 34, in get_data_from_conf_table
    df.columns = [desc[0] for desc in cur.description]
  File "/home/airflow/.local/lib/python3.8/site-packages/pandas/core/generic.py", line 6002, in __setattr__
    return object.__setattr__(self, name, value)
  File "pandas/_libs/properties.pyx", line 69, in pandas._libs.properties.AxisProperty.__set__
  File "/home/airflow/.local/lib/python3.8/site-packages/pandas/core/generic.py", line 730, in _set_axis
    self._mgr.set_axis(axis, labels)
  File "/home/airflow/.local/lib/python3.8/site-packages/pandas/core/internals/managers.py", line 225, in set_axis
    self._validate_set_axis(axis, new_labels)
  File "/home/airflow/.local/lib/python3.8/site-packages/pandas/core/internals/base.py", line 70, in _validate_set_axis
    raise ValueError(
ValueError: Length mismatch: Expected axis has 0 elements, new values have 15 elements
[2024-07-22T19:57:20.588+0000] {taskinstance.py:1149} INFO - Marking task as FAILED. dag_id=stagingtodv, task_id=staff, execution_date=20240721T000000, start_date=20240722T195718, end_date=20240722T195720
[2024-07-22T19:57:20.635+0000] {standard_task_runner.py:107} ERROR - Failed to execute job 4 for task staff (Length mismatch: Expected axis has 0 elements, new values have 15 elements; 88)
[2024-07-22T19:57:20.711+0000] {local_task_job_runner.py:234} INFO - Task exited with return code 1
[2024-07-22T19:57:20.756+0000] {taskinstance.py:3312} INFO - 0 downstream tasks scheduled from follow-on schedule check
[2024-07-22T20:01:00.698+0000] {taskinstance.py:1979} INFO - Dependencies all met for dep_context=non-requeueable deps ti=<TaskInstance: stagingtodv.staff scheduled__2024-07-21T00:00:00+00:00 [queued]>
[2024-07-22T20:01:00.731+0000] {taskinstance.py:1979} INFO - Dependencies all met for dep_context=requeueable deps ti=<TaskInstance: stagingtodv.staff scheduled__2024-07-21T00:00:00+00:00 [queued]>
[2024-07-22T20:01:00.736+0000] {taskinstance.py:2193} INFO - Starting attempt 1 of 1
[2024-07-22T20:01:00.775+0000] {taskinstance.py:2217} INFO - Executing <Task(PythonOperator): staff> on 2024-07-21 00:00:00+00:00
[2024-07-22T20:01:00.797+0000] {standard_task_runner.py:60} INFO - Started process 119 to run task
[2024-07-22T20:01:00.818+0000] {standard_task_runner.py:87} INFO - Running: ['***', 'tasks', 'run', 'stagingtodv', 'staff', 'scheduled__2024-07-21T00:00:00+00:00', '--job-id', '3', '--raw', '--subdir', 'DAGS_FOLDER/dag.py', '--cfg-path', '/tmp/tmp6ttuybc2']
[2024-07-22T20:01:00.834+0000] {standard_task_runner.py:88} INFO - Job 3: Subtask staff
[2024-07-22T20:01:01.065+0000] {task_command.py:423} INFO - Running <TaskInstance: stagingtodv.staff scheduled__2024-07-21T00:00:00+00:00 [running]> on host 2aa012dff3cf
[2024-07-22T20:01:02.295+0000] {taskinstance.py:2513} INFO - Exporting env vars: AIRFLOW_CTX_DAG_OWNER='***' AIRFLOW_CTX_DAG_ID='stagingtodv' AIRFLOW_CTX_TASK_ID='staff' AIRFLOW_CTX_EXECUTION_DATE='2024-07-21T00:00:00+00:00' AIRFLOW_CTX_TRY_NUMBER='1' AIRFLOW_CTX_DAG_RUN_ID='scheduled__2024-07-21T00:00:00+00:00'
[2024-07-22T20:01:02.301+0000] {logging_mixin.py:188} INFO - -------------------------------------------- select *  from etlconf.Etl_Process_Mapping where SourceTableName = 'staff' and Stage = 'stagingtodv'
[2024-07-22T20:01:02.371+0000] {taskinstance.py:2731} ERROR - Task failed with exception
Traceback (most recent call last):
  File "/home/airflow/.local/lib/python3.8/site-packages/airflow/models/taskinstance.py", line 444, in _execute_task
    result = _execute_callable(context=context, **execute_callable_kwargs)
  File "/home/airflow/.local/lib/python3.8/site-packages/airflow/models/taskinstance.py", line 414, in _execute_callable
    return execute_callable(context=context, **execute_callable_kwargs)
  File "/home/airflow/.local/lib/python3.8/site-packages/airflow/operators/python.py", line 200, in execute
    return_value = self.execute_callable()
  File "/home/airflow/.local/lib/python3.8/site-packages/airflow/operators/python.py", line 217, in execute_callable
    return self.python_callable(*self.op_args, **self.op_kwargs)
  File "/opt/airflow/dags/dag.py", line 41, in process_table
    tabletype = get_data_from_conf_table(table,stage)['tabletype'].values[0]
  File "/opt/airflow/dags/dag.py", line 34, in get_data_from_conf_table
    df.columns = [desc[0] for desc in cur.description]
  File "/home/airflow/.local/lib/python3.8/site-packages/pandas/core/generic.py", line 6002, in __setattr__
    return object.__setattr__(self, name, value)
  File "pandas/_libs/properties.pyx", line 69, in pandas._libs.properties.AxisProperty.__set__
  File "/home/airflow/.local/lib/python3.8/site-packages/pandas/core/generic.py", line 730, in _set_axis
    self._mgr.set_axis(axis, labels)
  File "/home/airflow/.local/lib/python3.8/site-packages/pandas/core/internals/managers.py", line 225, in set_axis
    self._validate_set_axis(axis, new_labels)
  File "/home/airflow/.local/lib/python3.8/site-packages/pandas/core/internals/base.py", line 70, in _validate_set_axis
    raise ValueError(
ValueError: Length mismatch: Expected axis has 0 elements, new values have 15 elements
[2024-07-22T20:01:02.431+0000] {taskinstance.py:1149} INFO - Marking task as FAILED. dag_id=stagingtodv, task_id=staff, execution_date=20240721T000000, start_date=20240722T200100, end_date=20240722T200102
[2024-07-22T20:01:02.465+0000] {standard_task_runner.py:107} ERROR - Failed to execute job 3 for task staff (Length mismatch: Expected axis has 0 elements, new values have 15 elements; 119)
[2024-07-22T20:01:02.480+0000] {local_task_job_runner.py:234} INFO - Task exited with return code 1
[2024-07-22T20:01:02.513+0000] {taskinstance.py:3312} INFO - 0 downstream tasks scheduled from follow-on schedule check
[2024-07-22T20:07:53.184+0000] {taskinstance.py:1979} INFO - Dependencies all met for dep_context=non-requeueable deps ti=<TaskInstance: stagingtodv.staff scheduled__2024-07-21T00:00:00+00:00 [queued]>
[2024-07-22T20:07:53.217+0000] {taskinstance.py:1979} INFO - Dependencies all met for dep_context=requeueable deps ti=<TaskInstance: stagingtodv.staff scheduled__2024-07-21T00:00:00+00:00 [queued]>
[2024-07-22T20:07:53.221+0000] {taskinstance.py:2193} INFO - Starting attempt 1 of 1
[2024-07-22T20:07:53.252+0000] {taskinstance.py:2217} INFO - Executing <Task(PythonOperator): staff> on 2024-07-21 00:00:00+00:00
[2024-07-22T20:07:53.270+0000] {standard_task_runner.py:60} INFO - Started process 106 to run task
[2024-07-22T20:07:53.293+0000] {standard_task_runner.py:87} INFO - Running: ['***', 'tasks', 'run', 'stagingtodv', 'staff', 'scheduled__2024-07-21T00:00:00+00:00', '--job-id', '6', '--raw', '--subdir', 'DAGS_FOLDER/dag.py', '--cfg-path', '/tmp/tmpoc5ombhr']
[2024-07-22T20:07:53.305+0000] {standard_task_runner.py:88} INFO - Job 6: Subtask staff
[2024-07-22T20:07:53.510+0000] {task_command.py:423} INFO - Running <TaskInstance: stagingtodv.staff scheduled__2024-07-21T00:00:00+00:00 [running]> on host 05733b1af473
[2024-07-22T20:07:54.746+0000] {taskinstance.py:2513} INFO - Exporting env vars: AIRFLOW_CTX_DAG_OWNER='***' AIRFLOW_CTX_DAG_ID='stagingtodv' AIRFLOW_CTX_TASK_ID='staff' AIRFLOW_CTX_EXECUTION_DATE='2024-07-21T00:00:00+00:00' AIRFLOW_CTX_TRY_NUMBER='1' AIRFLOW_CTX_DAG_RUN_ID='scheduled__2024-07-21T00:00:00+00:00'
[2024-07-22T20:07:54.764+0000] {logging_mixin.py:188} INFO - -------------------------------------------- select *  from etlconf.Etl_Process_Mapping where SourceTableName = 'staff' and Stage = 'stagingtodv'
[2024-07-22T20:07:54.875+0000] {taskinstance.py:2731} ERROR - Task failed with exception
Traceback (most recent call last):
  File "/home/airflow/.local/lib/python3.8/site-packages/airflow/models/taskinstance.py", line 444, in _execute_task
    result = _execute_callable(context=context, **execute_callable_kwargs)
  File "/home/airflow/.local/lib/python3.8/site-packages/airflow/models/taskinstance.py", line 414, in _execute_callable
    return execute_callable(context=context, **execute_callable_kwargs)
  File "/home/airflow/.local/lib/python3.8/site-packages/airflow/operators/python.py", line 200, in execute
    return_value = self.execute_callable()
  File "/home/airflow/.local/lib/python3.8/site-packages/airflow/operators/python.py", line 217, in execute_callable
    return self.python_callable(*self.op_args, **self.op_kwargs)
  File "/opt/airflow/dags/dag.py", line 41, in process_table
    tabletype = get_data_from_conf_table(table,stage)['tabletype'].values[0]
  File "/opt/airflow/dags/dag.py", line 34, in get_data_from_conf_table
    df.columns = [desc[0] for desc in cur.description]
  File "/home/airflow/.local/lib/python3.8/site-packages/pandas/core/generic.py", line 6002, in __setattr__
    return object.__setattr__(self, name, value)
  File "pandas/_libs/properties.pyx", line 69, in pandas._libs.properties.AxisProperty.__set__
  File "/home/airflow/.local/lib/python3.8/site-packages/pandas/core/generic.py", line 730, in _set_axis
    self._mgr.set_axis(axis, labels)
  File "/home/airflow/.local/lib/python3.8/site-packages/pandas/core/internals/managers.py", line 225, in set_axis
    self._validate_set_axis(axis, new_labels)
  File "/home/airflow/.local/lib/python3.8/site-packages/pandas/core/internals/base.py", line 70, in _validate_set_axis
    raise ValueError(
ValueError: Length mismatch: Expected axis has 0 elements, new values have 15 elements
[2024-07-22T20:07:54.923+0000] {taskinstance.py:1149} INFO - Marking task as FAILED. dag_id=stagingtodv, task_id=staff, execution_date=20240721T000000, start_date=20240722T200753, end_date=20240722T200754
[2024-07-22T20:07:54.992+0000] {standard_task_runner.py:107} ERROR - Failed to execute job 6 for task staff (Length mismatch: Expected axis has 0 elements, new values have 15 elements; 106)
[2024-07-22T20:07:55.080+0000] {local_task_job_runner.py:234} INFO - Task exited with return code 1
[2024-07-22T20:07:55.149+0000] {taskinstance.py:3312} INFO - 0 downstream tasks scheduled from follow-on schedule check
[2024-07-22T20:12:24.402+0000] {taskinstance.py:1979} INFO - Dependencies all met for dep_context=non-requeueable deps ti=<TaskInstance: stagingtodv.staff scheduled__2024-07-21T00:00:00+00:00 [queued]>
[2024-07-22T20:12:24.449+0000] {taskinstance.py:1979} INFO - Dependencies all met for dep_context=requeueable deps ti=<TaskInstance: stagingtodv.staff scheduled__2024-07-21T00:00:00+00:00 [queued]>
[2024-07-22T20:12:24.453+0000] {taskinstance.py:2193} INFO - Starting attempt 1 of 1
[2024-07-22T20:12:24.492+0000] {taskinstance.py:2217} INFO - Executing <Task(PythonOperator): staff> on 2024-07-21 00:00:00+00:00
[2024-07-22T20:12:24.592+0000] {standard_task_runner.py:87} INFO - Running: ['***', 'tasks', 'run', 'stagingtodv', 'staff', 'scheduled__2024-07-21T00:00:00+00:00', '--job-id', '16', '--raw', '--subdir', 'DAGS_FOLDER/dag.py', '--cfg-path', '/tmp/tmpo5w8qza1']
[2024-07-22T20:12:24.606+0000] {standard_task_runner.py:88} INFO - Job 16: Subtask staff
[2024-07-22T20:12:24.559+0000] {standard_task_runner.py:60} INFO - Started process 109 to run task
[2024-07-22T20:12:24.774+0000] {task_command.py:423} INFO - Running <TaskInstance: stagingtodv.staff scheduled__2024-07-21T00:00:00+00:00 [running]> on host 0a26f4611472
[2024-07-22T20:12:26.067+0000] {taskinstance.py:2513} INFO - Exporting env vars: AIRFLOW_CTX_DAG_OWNER='***' AIRFLOW_CTX_DAG_ID='stagingtodv' AIRFLOW_CTX_TASK_ID='staff' AIRFLOW_CTX_EXECUTION_DATE='2024-07-21T00:00:00+00:00' AIRFLOW_CTX_TRY_NUMBER='1' AIRFLOW_CTX_DAG_RUN_ID='scheduled__2024-07-21T00:00:00+00:00'
[2024-07-22T20:12:26.074+0000] {logging_mixin.py:188} INFO - -------------------------------------------- select *  from etlconf.Etl_Process_Mapping where SourceTableName = 'staff' and Stage = 'stagingtodv'
[2024-07-22T20:12:26.098+0000] {taskinstance.py:2731} ERROR - Task failed with exception
Traceback (most recent call last):
  File "/home/airflow/.local/lib/python3.8/site-packages/airflow/models/taskinstance.py", line 444, in _execute_task
    result = _execute_callable(context=context, **execute_callable_kwargs)
  File "/home/airflow/.local/lib/python3.8/site-packages/airflow/models/taskinstance.py", line 414, in _execute_callable
    return execute_callable(context=context, **execute_callable_kwargs)
  File "/home/airflow/.local/lib/python3.8/site-packages/airflow/operators/python.py", line 200, in execute
    return_value = self.execute_callable()
  File "/home/airflow/.local/lib/python3.8/site-packages/airflow/operators/python.py", line 217, in execute_callable
    return self.python_callable(*self.op_args, **self.op_kwargs)
  File "/opt/airflow/dags/dag.py", line 41, in process_table
    tabletype = get_data_from_conf_table(table,stage)['tabletype'].values[0]
  File "/opt/airflow/dags/dag.py", line 34, in get_data_from_conf_table
    df.columns = [desc[0] for desc in cur.description]
  File "/home/airflow/.local/lib/python3.8/site-packages/pandas/core/generic.py", line 6002, in __setattr__
    return object.__setattr__(self, name, value)
  File "pandas/_libs/properties.pyx", line 69, in pandas._libs.properties.AxisProperty.__set__
  File "/home/airflow/.local/lib/python3.8/site-packages/pandas/core/generic.py", line 730, in _set_axis
    self._mgr.set_axis(axis, labels)
  File "/home/airflow/.local/lib/python3.8/site-packages/pandas/core/internals/managers.py", line 225, in set_axis
    self._validate_set_axis(axis, new_labels)
  File "/home/airflow/.local/lib/python3.8/site-packages/pandas/core/internals/base.py", line 70, in _validate_set_axis
    raise ValueError(
ValueError: Length mismatch: Expected axis has 0 elements, new values have 15 elements
[2024-07-22T20:12:26.129+0000] {taskinstance.py:1149} INFO - Marking task as FAILED. dag_id=stagingtodv, task_id=staff, execution_date=20240721T000000, start_date=20240722T201224, end_date=20240722T201226
[2024-07-22T20:12:26.160+0000] {standard_task_runner.py:107} ERROR - Failed to execute job 16 for task staff (Length mismatch: Expected axis has 0 elements, new values have 15 elements; 109)
[2024-07-22T20:12:26.200+0000] {local_task_job_runner.py:234} INFO - Task exited with return code 1
[2024-07-22T20:12:26.262+0000] {taskinstance.py:3312} INFO - 0 downstream tasks scheduled from follow-on schedule check
[2024-07-22T20:16:39.528+0000] {taskinstance.py:1979} INFO - Dependencies all met for dep_context=non-requeueable deps ti=<TaskInstance: stagingtodv.staff scheduled__2024-07-21T00:00:00+00:00 [queued]>
[2024-07-22T20:16:39.540+0000] {taskinstance.py:1979} INFO - Dependencies all met for dep_context=requeueable deps ti=<TaskInstance: stagingtodv.staff scheduled__2024-07-21T00:00:00+00:00 [queued]>
[2024-07-22T20:16:39.544+0000] {taskinstance.py:2193} INFO - Starting attempt 1 of 1
[2024-07-22T20:16:39.571+0000] {taskinstance.py:2217} INFO - Executing <Task(PythonOperator): staff> on 2024-07-21 00:00:00+00:00
[2024-07-22T20:16:39.579+0000] {standard_task_runner.py:60} INFO - Started process 93 to run task
[2024-07-22T20:16:39.594+0000] {standard_task_runner.py:87} INFO - Running: ['***', 'tasks', 'run', 'stagingtodv', 'staff', 'scheduled__2024-07-21T00:00:00+00:00', '--job-id', '6', '--raw', '--subdir', 'DAGS_FOLDER/dag.py', '--cfg-path', '/tmp/tmpmmt8k7e8']
[2024-07-22T20:16:39.605+0000] {standard_task_runner.py:88} INFO - Job 6: Subtask staff
[2024-07-22T20:16:39.773+0000] {task_command.py:423} INFO - Running <TaskInstance: stagingtodv.staff scheduled__2024-07-21T00:00:00+00:00 [running]> on host 78ac63ab6c84
[2024-07-22T20:16:40.820+0000] {taskinstance.py:2513} INFO - Exporting env vars: AIRFLOW_CTX_DAG_OWNER='***' AIRFLOW_CTX_DAG_ID='stagingtodv' AIRFLOW_CTX_TASK_ID='staff' AIRFLOW_CTX_EXECUTION_DATE='2024-07-21T00:00:00+00:00' AIRFLOW_CTX_TRY_NUMBER='1' AIRFLOW_CTX_DAG_RUN_ID='scheduled__2024-07-21T00:00:00+00:00'
[2024-07-22T20:16:40.832+0000] {logging_mixin.py:188} INFO - -------------------------------------------- select *  from etlconf.Etl_Process_Mapping where SourceTableName = 'staff' and Stage = 'stagingtodv'
[2024-07-22T20:16:40.900+0000] {taskinstance.py:2731} ERROR - Task failed with exception
Traceback (most recent call last):
  File "/home/airflow/.local/lib/python3.8/site-packages/airflow/models/taskinstance.py", line 444, in _execute_task
    result = _execute_callable(context=context, **execute_callable_kwargs)
  File "/home/airflow/.local/lib/python3.8/site-packages/airflow/models/taskinstance.py", line 414, in _execute_callable
    return execute_callable(context=context, **execute_callable_kwargs)
  File "/home/airflow/.local/lib/python3.8/site-packages/airflow/operators/python.py", line 200, in execute
    return_value = self.execute_callable()
  File "/home/airflow/.local/lib/python3.8/site-packages/airflow/operators/python.py", line 217, in execute_callable
    return self.python_callable(*self.op_args, **self.op_kwargs)
  File "/opt/airflow/dags/dag.py", line 41, in process_table
    tabletype = get_data_from_conf_table(table,stage)['tabletype'].values[0]
  File "/opt/airflow/dags/dag.py", line 34, in get_data_from_conf_table
    df.columns = [desc[0] for desc in cur.description]
  File "/home/airflow/.local/lib/python3.8/site-packages/pandas/core/generic.py", line 6002, in __setattr__
    return object.__setattr__(self, name, value)
  File "pandas/_libs/properties.pyx", line 69, in pandas._libs.properties.AxisProperty.__set__
  File "/home/airflow/.local/lib/python3.8/site-packages/pandas/core/generic.py", line 730, in _set_axis
    self._mgr.set_axis(axis, labels)
  File "/home/airflow/.local/lib/python3.8/site-packages/pandas/core/internals/managers.py", line 225, in set_axis
    self._validate_set_axis(axis, new_labels)
  File "/home/airflow/.local/lib/python3.8/site-packages/pandas/core/internals/base.py", line 70, in _validate_set_axis
    raise ValueError(
ValueError: Length mismatch: Expected axis has 0 elements, new values have 15 elements
[2024-07-22T20:16:40.960+0000] {taskinstance.py:1149} INFO - Marking task as FAILED. dag_id=stagingtodv, task_id=staff, execution_date=20240721T000000, start_date=20240722T201639, end_date=20240722T201640
[2024-07-22T20:16:41.035+0000] {standard_task_runner.py:107} ERROR - Failed to execute job 6 for task staff (Length mismatch: Expected axis has 0 elements, new values have 15 elements; 93)
[2024-07-22T20:16:41.085+0000] {local_task_job_runner.py:234} INFO - Task exited with return code 1
[2024-07-22T20:16:41.120+0000] {taskinstance.py:3312} INFO - 0 downstream tasks scheduled from follow-on schedule check
[2024-07-22T20:31:14.224+0000] {taskinstance.py:1979} INFO - Dependencies all met for dep_context=non-requeueable deps ti=<TaskInstance: stagingtodv.staff scheduled__2024-07-21T00:00:00+00:00 [queued]>
[2024-07-22T20:31:14.238+0000] {taskinstance.py:1979} INFO - Dependencies all met for dep_context=requeueable deps ti=<TaskInstance: stagingtodv.staff scheduled__2024-07-21T00:00:00+00:00 [queued]>
[2024-07-22T20:31:14.243+0000] {taskinstance.py:2193} INFO - Starting attempt 1 of 1
[2024-07-22T20:31:14.289+0000] {taskinstance.py:2217} INFO - Executing <Task(PythonOperator): staff> on 2024-07-21 00:00:00+00:00
[2024-07-22T20:31:14.306+0000] {standard_task_runner.py:60} INFO - Started process 93 to run task
[2024-07-22T20:31:14.317+0000] {standard_task_runner.py:87} INFO - Running: ['***', 'tasks', 'run', 'stagingtodv', 'staff', 'scheduled__2024-07-21T00:00:00+00:00', '--job-id', '13', '--raw', '--subdir', 'DAGS_FOLDER/dag.py', '--cfg-path', '/tmp/tmpkqskgv_r']
[2024-07-22T20:31:14.331+0000] {standard_task_runner.py:88} INFO - Job 13: Subtask staff
[2024-07-22T20:31:14.477+0000] {task_command.py:423} INFO - Running <TaskInstance: stagingtodv.staff scheduled__2024-07-21T00:00:00+00:00 [running]> on host 9126008e9d77
[2024-07-22T20:31:15.225+0000] {taskinstance.py:2513} INFO - Exporting env vars: AIRFLOW_CTX_DAG_OWNER='***' AIRFLOW_CTX_DAG_ID='stagingtodv' AIRFLOW_CTX_TASK_ID='staff' AIRFLOW_CTX_EXECUTION_DATE='2024-07-21T00:00:00+00:00' AIRFLOW_CTX_TRY_NUMBER='1' AIRFLOW_CTX_DAG_RUN_ID='scheduled__2024-07-21T00:00:00+00:00'
[2024-07-22T20:31:15.235+0000] {logging_mixin.py:188} INFO - -------------------------------------------- select *  from etlconf.Etl_Process_Mapping where SourceTableName = 'staff' and Stage = 'stagingtodv'
[2024-07-22T20:31:15.672+0000] {taskinstance.py:2731} ERROR - Task failed with exception
Traceback (most recent call last):
  File "/home/airflow/.local/lib/python3.8/site-packages/airflow/models/taskinstance.py", line 444, in _execute_task
    result = _execute_callable(context=context, **execute_callable_kwargs)
  File "/home/airflow/.local/lib/python3.8/site-packages/airflow/models/taskinstance.py", line 414, in _execute_callable
    return execute_callable(context=context, **execute_callable_kwargs)
  File "/home/airflow/.local/lib/python3.8/site-packages/airflow/operators/python.py", line 200, in execute
    return_value = self.execute_callable()
  File "/home/airflow/.local/lib/python3.8/site-packages/airflow/operators/python.py", line 217, in execute_callable
    return self.python_callable(*self.op_args, **self.op_kwargs)
  File "/opt/airflow/dags/dag.py", line 41, in process_table
    tabletype = get_data_from_conf_table(table,stage)['tabletype'].values[0]
  File "/opt/airflow/dags/dag.py", line 34, in get_data_from_conf_table
    df.columns = [desc[0] for desc in cur.description]
  File "/home/airflow/.local/lib/python3.8/site-packages/pandas/core/generic.py", line 6002, in __setattr__
    return object.__setattr__(self, name, value)
  File "pandas/_libs/properties.pyx", line 69, in pandas._libs.properties.AxisProperty.__set__
  File "/home/airflow/.local/lib/python3.8/site-packages/pandas/core/generic.py", line 730, in _set_axis
    self._mgr.set_axis(axis, labels)
  File "/home/airflow/.local/lib/python3.8/site-packages/pandas/core/internals/managers.py", line 225, in set_axis
    self._validate_set_axis(axis, new_labels)
  File "/home/airflow/.local/lib/python3.8/site-packages/pandas/core/internals/base.py", line 70, in _validate_set_axis
    raise ValueError(
ValueError: Length mismatch: Expected axis has 0 elements, new values have 15 elements
[2024-07-22T20:31:15.706+0000] {taskinstance.py:1149} INFO - Marking task as FAILED. dag_id=stagingtodv, task_id=staff, execution_date=20240721T000000, start_date=20240722T203114, end_date=20240722T203115
[2024-07-22T20:31:15.734+0000] {standard_task_runner.py:107} ERROR - Failed to execute job 13 for task staff (Length mismatch: Expected axis has 0 elements, new values have 15 elements; 93)
[2024-07-22T20:31:15.770+0000] {local_task_job_runner.py:234} INFO - Task exited with return code 1
[2024-07-22T20:31:15.817+0000] {taskinstance.py:3312} INFO - 0 downstream tasks scheduled from follow-on schedule check
[2024-07-22T20:33:01.044+0000] {taskinstance.py:1979} INFO - Dependencies all met for dep_context=non-requeueable deps ti=<TaskInstance: stagingtodv.staff scheduled__2024-07-21T00:00:00+00:00 [queued]>
[2024-07-22T20:33:01.056+0000] {taskinstance.py:1979} INFO - Dependencies all met for dep_context=requeueable deps ti=<TaskInstance: stagingtodv.staff scheduled__2024-07-21T00:00:00+00:00 [queued]>
[2024-07-22T20:33:01.067+0000] {taskinstance.py:2193} INFO - Starting attempt 1 of 1
[2024-07-22T20:33:01.086+0000] {taskinstance.py:2217} INFO - Executing <Task(PythonOperator): staff> on 2024-07-21 00:00:00+00:00
[2024-07-22T20:33:01.097+0000] {standard_task_runner.py:60} INFO - Started process 83 to run task
[2024-07-22T20:33:01.108+0000] {standard_task_runner.py:87} INFO - Running: ['***', 'tasks', 'run', 'stagingtodv', 'staff', 'scheduled__2024-07-21T00:00:00+00:00', '--job-id', '8', '--raw', '--subdir', 'DAGS_FOLDER/dag.py', '--cfg-path', '/tmp/tmpabk1jvcy']
[2024-07-22T20:33:01.119+0000] {standard_task_runner.py:88} INFO - Job 8: Subtask staff
[2024-07-22T20:33:01.291+0000] {task_command.py:423} INFO - Running <TaskInstance: stagingtodv.staff scheduled__2024-07-21T00:00:00+00:00 [running]> on host 79b906a44679
[2024-07-22T20:33:02.807+0000] {taskinstance.py:2513} INFO - Exporting env vars: AIRFLOW_CTX_DAG_OWNER='***' AIRFLOW_CTX_DAG_ID='stagingtodv' AIRFLOW_CTX_TASK_ID='staff' AIRFLOW_CTX_EXECUTION_DATE='2024-07-21T00:00:00+00:00' AIRFLOW_CTX_TRY_NUMBER='1' AIRFLOW_CTX_DAG_RUN_ID='scheduled__2024-07-21T00:00:00+00:00'
[2024-07-22T20:33:02.819+0000] {logging_mixin.py:188} INFO - -------------------------------------------- select *  from etlconf.Etl_Process_Mapping where SourceTableName = 'staff' and Stage = 'stagingtodv'
[2024-07-22T20:33:02.869+0000] {taskinstance.py:2731} ERROR - Task failed with exception
Traceback (most recent call last):
  File "/home/airflow/.local/lib/python3.8/site-packages/airflow/models/taskinstance.py", line 444, in _execute_task
    result = _execute_callable(context=context, **execute_callable_kwargs)
  File "/home/airflow/.local/lib/python3.8/site-packages/airflow/models/taskinstance.py", line 414, in _execute_callable
    return execute_callable(context=context, **execute_callable_kwargs)
  File "/home/airflow/.local/lib/python3.8/site-packages/airflow/operators/python.py", line 200, in execute
    return_value = self.execute_callable()
  File "/home/airflow/.local/lib/python3.8/site-packages/airflow/operators/python.py", line 217, in execute_callable
    return self.python_callable(*self.op_args, **self.op_kwargs)
  File "/opt/airflow/dags/dag.py", line 41, in process_table
    tabletype = get_data_from_conf_table(table,stage)['tabletype'].values[0]
  File "/opt/airflow/dags/dag.py", line 34, in get_data_from_conf_table
    df.columns = [desc[0] for desc in cur.description]
  File "/home/airflow/.local/lib/python3.8/site-packages/pandas/core/generic.py", line 6002, in __setattr__
    return object.__setattr__(self, name, value)
  File "pandas/_libs/properties.pyx", line 69, in pandas._libs.properties.AxisProperty.__set__
  File "/home/airflow/.local/lib/python3.8/site-packages/pandas/core/generic.py", line 730, in _set_axis
    self._mgr.set_axis(axis, labels)
  File "/home/airflow/.local/lib/python3.8/site-packages/pandas/core/internals/managers.py", line 225, in set_axis
    self._validate_set_axis(axis, new_labels)
  File "/home/airflow/.local/lib/python3.8/site-packages/pandas/core/internals/base.py", line 70, in _validate_set_axis
    raise ValueError(
ValueError: Length mismatch: Expected axis has 0 elements, new values have 15 elements
[2024-07-22T20:33:02.921+0000] {taskinstance.py:1149} INFO - Marking task as FAILED. dag_id=stagingtodv, task_id=staff, execution_date=20240721T000000, start_date=20240722T203301, end_date=20240722T203302
[2024-07-22T20:33:02.950+0000] {standard_task_runner.py:107} ERROR - Failed to execute job 8 for task staff (Length mismatch: Expected axis has 0 elements, new values have 15 elements; 83)
[2024-07-22T20:33:03.028+0000] {local_task_job_runner.py:234} INFO - Task exited with return code 1
[2024-07-22T20:33:03.083+0000] {taskinstance.py:3312} INFO - 0 downstream tasks scheduled from follow-on schedule check
[2024-07-22T20:35:55.018+0000] {taskinstance.py:1979} INFO - Dependencies all met for dep_context=non-requeueable deps ti=<TaskInstance: stagingtodv.staff scheduled__2024-07-21T00:00:00+00:00 [queued]>
[2024-07-22T20:35:55.042+0000] {taskinstance.py:1979} INFO - Dependencies all met for dep_context=requeueable deps ti=<TaskInstance: stagingtodv.staff scheduled__2024-07-21T00:00:00+00:00 [queued]>
[2024-07-22T20:35:55.050+0000] {taskinstance.py:2193} INFO - Starting attempt 1 of 1
[2024-07-22T20:35:55.100+0000] {taskinstance.py:2217} INFO - Executing <Task(PythonOperator): staff> on 2024-07-21 00:00:00+00:00
[2024-07-22T20:35:55.126+0000] {standard_task_runner.py:60} INFO - Started process 99 to run task
[2024-07-22T20:35:55.129+0000] {standard_task_runner.py:87} INFO - Running: ['***', 'tasks', 'run', 'stagingtodv', 'staff', 'scheduled__2024-07-21T00:00:00+00:00', '--job-id', '15', '--raw', '--subdir', 'DAGS_FOLDER/dag.py', '--cfg-path', '/tmp/tmpsd6slwyh']
[2024-07-22T20:35:55.157+0000] {standard_task_runner.py:88} INFO - Job 15: Subtask staff
[2024-07-22T20:35:55.544+0000] {task_command.py:423} INFO - Running <TaskInstance: stagingtodv.staff scheduled__2024-07-21T00:00:00+00:00 [running]> on host eba0c7ca727b
[2024-07-22T20:35:55.911+0000] {taskinstance.py:2513} INFO - Exporting env vars: AIRFLOW_CTX_DAG_OWNER='***' AIRFLOW_CTX_DAG_ID='stagingtodv' AIRFLOW_CTX_TASK_ID='staff' AIRFLOW_CTX_EXECUTION_DATE='2024-07-21T00:00:00+00:00' AIRFLOW_CTX_TRY_NUMBER='1' AIRFLOW_CTX_DAG_RUN_ID='scheduled__2024-07-21T00:00:00+00:00'
[2024-07-22T20:35:55.931+0000] {logging_mixin.py:188} INFO - -------------------------------------------- select *  from etlconf.Etl_Process_Mapping where SourceTableName = 'staff' and Stage = 'stagingtodv'
[2024-07-22T20:35:56.408+0000] {taskinstance.py:2731} ERROR - Task failed with exception
Traceback (most recent call last):
  File "/home/airflow/.local/lib/python3.8/site-packages/airflow/models/taskinstance.py", line 444, in _execute_task
    result = _execute_callable(context=context, **execute_callable_kwargs)
  File "/home/airflow/.local/lib/python3.8/site-packages/airflow/models/taskinstance.py", line 414, in _execute_callable
    return execute_callable(context=context, **execute_callable_kwargs)
  File "/home/airflow/.local/lib/python3.8/site-packages/airflow/operators/python.py", line 200, in execute
    return_value = self.execute_callable()
  File "/home/airflow/.local/lib/python3.8/site-packages/airflow/operators/python.py", line 217, in execute_callable
    return self.python_callable(*self.op_args, **self.op_kwargs)
  File "/opt/airflow/dags/dag.py", line 41, in process_table
    tabletype = get_data_from_conf_table(table,stage)['tabletype'].values[0]
  File "/opt/airflow/dags/dag.py", line 34, in get_data_from_conf_table
    df.columns = [desc[0] for desc in cur.description]
  File "/home/airflow/.local/lib/python3.8/site-packages/pandas/core/generic.py", line 6002, in __setattr__
    return object.__setattr__(self, name, value)
  File "pandas/_libs/properties.pyx", line 69, in pandas._libs.properties.AxisProperty.__set__
  File "/home/airflow/.local/lib/python3.8/site-packages/pandas/core/generic.py", line 730, in _set_axis
    self._mgr.set_axis(axis, labels)
  File "/home/airflow/.local/lib/python3.8/site-packages/pandas/core/internals/managers.py", line 225, in set_axis
    self._validate_set_axis(axis, new_labels)
  File "/home/airflow/.local/lib/python3.8/site-packages/pandas/core/internals/base.py", line 70, in _validate_set_axis
    raise ValueError(
ValueError: Length mismatch: Expected axis has 0 elements, new values have 15 elements
[2024-07-22T20:35:56.833+0000] {taskinstance.py:1149} INFO - Marking task as FAILED. dag_id=stagingtodv, task_id=staff, execution_date=20240721T000000, start_date=20240722T203555, end_date=20240722T203556
[2024-07-22T20:35:56.855+0000] {standard_task_runner.py:107} ERROR - Failed to execute job 15 for task staff (Length mismatch: Expected axis has 0 elements, new values have 15 elements; 99)
[2024-07-22T20:35:56.878+0000] {local_task_job_runner.py:234} INFO - Task exited with return code 1
[2024-07-22T20:35:56.931+0000] {taskinstance.py:3312} INFO - 0 downstream tasks scheduled from follow-on schedule check
[2024-07-22T20:37:38.516+0000] {taskinstance.py:1979} INFO - Dependencies all met for dep_context=non-requeueable deps ti=<TaskInstance: stagingtodv.staff scheduled__2024-07-21T00:00:00+00:00 [queued]>
[2024-07-22T20:37:38.563+0000] {taskinstance.py:1979} INFO - Dependencies all met for dep_context=requeueable deps ti=<TaskInstance: stagingtodv.staff scheduled__2024-07-21T00:00:00+00:00 [queued]>
[2024-07-22T20:37:38.568+0000] {taskinstance.py:2193} INFO - Starting attempt 1 of 1
[2024-07-22T20:37:38.618+0000] {taskinstance.py:2217} INFO - Executing <Task(PythonOperator): staff> on 2024-07-21 00:00:00+00:00
[2024-07-22T20:37:38.627+0000] {standard_task_runner.py:60} INFO - Started process 97 to run task
[2024-07-22T20:37:38.657+0000] {standard_task_runner.py:87} INFO - Running: ['***', 'tasks', 'run', 'stagingtodv', 'staff', 'scheduled__2024-07-21T00:00:00+00:00', '--job-id', '11', '--raw', '--subdir', 'DAGS_FOLDER/dag.py', '--cfg-path', '/tmp/tmp0ebd0nl1']
[2024-07-22T20:37:38.681+0000] {standard_task_runner.py:88} INFO - Job 11: Subtask staff
[2024-07-22T20:37:38.867+0000] {task_command.py:423} INFO - Running <TaskInstance: stagingtodv.staff scheduled__2024-07-21T00:00:00+00:00 [running]> on host ca612ea69d67
[2024-07-22T20:37:39.912+0000] {taskinstance.py:2513} INFO - Exporting env vars: AIRFLOW_CTX_DAG_OWNER='***' AIRFLOW_CTX_DAG_ID='stagingtodv' AIRFLOW_CTX_TASK_ID='staff' AIRFLOW_CTX_EXECUTION_DATE='2024-07-21T00:00:00+00:00' AIRFLOW_CTX_TRY_NUMBER='1' AIRFLOW_CTX_DAG_RUN_ID='scheduled__2024-07-21T00:00:00+00:00'
[2024-07-22T20:37:39.917+0000] {logging_mixin.py:188} INFO - -------------------------------------------- select *  from etlconf.Etl_Process_Mapping where SourceTableName = 'staff' and Stage = 'stagingtodv'
[2024-07-22T20:37:40.012+0000] {taskinstance.py:2731} ERROR - Task failed with exception
Traceback (most recent call last):
  File "/home/airflow/.local/lib/python3.8/site-packages/airflow/models/taskinstance.py", line 444, in _execute_task
    result = _execute_callable(context=context, **execute_callable_kwargs)
  File "/home/airflow/.local/lib/python3.8/site-packages/airflow/models/taskinstance.py", line 414, in _execute_callable
    return execute_callable(context=context, **execute_callable_kwargs)
  File "/home/airflow/.local/lib/python3.8/site-packages/airflow/operators/python.py", line 200, in execute
    return_value = self.execute_callable()
  File "/home/airflow/.local/lib/python3.8/site-packages/airflow/operators/python.py", line 217, in execute_callable
    return self.python_callable(*self.op_args, **self.op_kwargs)
  File "/opt/airflow/dags/dag.py", line 41, in process_table
    tabletype = get_data_from_conf_table(table,stage)['tabletype'].values[0]
  File "/opt/airflow/dags/dag.py", line 34, in get_data_from_conf_table
    df.columns = [desc[0] for desc in cur.description]
  File "/home/airflow/.local/lib/python3.8/site-packages/pandas/core/generic.py", line 6002, in __setattr__
    return object.__setattr__(self, name, value)
  File "pandas/_libs/properties.pyx", line 69, in pandas._libs.properties.AxisProperty.__set__
  File "/home/airflow/.local/lib/python3.8/site-packages/pandas/core/generic.py", line 730, in _set_axis
    self._mgr.set_axis(axis, labels)
  File "/home/airflow/.local/lib/python3.8/site-packages/pandas/core/internals/managers.py", line 225, in set_axis
    self._validate_set_axis(axis, new_labels)
  File "/home/airflow/.local/lib/python3.8/site-packages/pandas/core/internals/base.py", line 70, in _validate_set_axis
    raise ValueError(
ValueError: Length mismatch: Expected axis has 0 elements, new values have 15 elements
[2024-07-22T20:37:40.047+0000] {taskinstance.py:1149} INFO - Marking task as FAILED. dag_id=stagingtodv, task_id=staff, execution_date=20240721T000000, start_date=20240722T203738, end_date=20240722T203740
[2024-07-22T20:37:40.111+0000] {standard_task_runner.py:107} ERROR - Failed to execute job 11 for task staff (Length mismatch: Expected axis has 0 elements, new values have 15 elements; 97)
[2024-07-22T20:37:40.163+0000] {local_task_job_runner.py:234} INFO - Task exited with return code 1
[2024-07-22T20:37:40.304+0000] {taskinstance.py:3312} INFO - 0 downstream tasks scheduled from follow-on schedule check
[2024-07-22T20:48:35.641+0000] {taskinstance.py:1979} INFO - Dependencies all met for dep_context=non-requeueable deps ti=<TaskInstance: stagingtodv.staff scheduled__2024-07-21T00:00:00+00:00 [queued]>
[2024-07-22T20:48:35.672+0000] {taskinstance.py:1979} INFO - Dependencies all met for dep_context=requeueable deps ti=<TaskInstance: stagingtodv.staff scheduled__2024-07-21T00:00:00+00:00 [queued]>
[2024-07-22T20:48:35.679+0000] {taskinstance.py:2193} INFO - Starting attempt 1 of 1
[2024-07-22T20:48:35.734+0000] {taskinstance.py:2217} INFO - Executing <Task(PythonOperator): staff> on 2024-07-21 00:00:00+00:00
[2024-07-22T20:48:35.747+0000] {standard_task_runner.py:60} INFO - Started process 105 to run task
[2024-07-22T20:48:35.760+0000] {standard_task_runner.py:87} INFO - Running: ['***', 'tasks', 'run', 'stagingtodv', 'staff', 'scheduled__2024-07-21T00:00:00+00:00', '--job-id', '13', '--raw', '--subdir', 'DAGS_FOLDER/dag.py', '--cfg-path', '/tmp/tmp49hgljhr']
[2024-07-22T20:48:35.772+0000] {standard_task_runner.py:88} INFO - Job 13: Subtask staff
[2024-07-22T20:48:35.954+0000] {task_command.py:423} INFO - Running <TaskInstance: stagingtodv.staff scheduled__2024-07-21T00:00:00+00:00 [running]> on host d9bd7bcefcfd
[2024-07-22T20:48:37.335+0000] {taskinstance.py:2513} INFO - Exporting env vars: AIRFLOW_CTX_DAG_OWNER='***' AIRFLOW_CTX_DAG_ID='stagingtodv' AIRFLOW_CTX_TASK_ID='staff' AIRFLOW_CTX_EXECUTION_DATE='2024-07-21T00:00:00+00:00' AIRFLOW_CTX_TRY_NUMBER='1' AIRFLOW_CTX_DAG_RUN_ID='scheduled__2024-07-21T00:00:00+00:00'
[2024-07-22T20:48:37.353+0000] {logging_mixin.py:188} INFO - -------------------------------------------- select *  from etlconf.Etl_Process_Mapping where SourceTableName = 'staff' and Stage = 'stagingtodv'
[2024-07-22T20:48:37.424+0000] {taskinstance.py:2731} ERROR - Task failed with exception
Traceback (most recent call last):
  File "/home/airflow/.local/lib/python3.8/site-packages/airflow/models/taskinstance.py", line 444, in _execute_task
    result = _execute_callable(context=context, **execute_callable_kwargs)
  File "/home/airflow/.local/lib/python3.8/site-packages/airflow/models/taskinstance.py", line 414, in _execute_callable
    return execute_callable(context=context, **execute_callable_kwargs)
  File "/home/airflow/.local/lib/python3.8/site-packages/airflow/operators/python.py", line 200, in execute
    return_value = self.execute_callable()
  File "/home/airflow/.local/lib/python3.8/site-packages/airflow/operators/python.py", line 217, in execute_callable
    return self.python_callable(*self.op_args, **self.op_kwargs)
  File "/opt/airflow/dags/dag.py", line 41, in process_table
    tabletype = get_data_from_conf_table(table,stage)['tabletype'].values[0]
  File "/opt/airflow/dags/dag.py", line 34, in get_data_from_conf_table
    df.columns = [desc[0] for desc in cur.description]
  File "/home/airflow/.local/lib/python3.8/site-packages/pandas/core/generic.py", line 6002, in __setattr__
    return object.__setattr__(self, name, value)
  File "pandas/_libs/properties.pyx", line 69, in pandas._libs.properties.AxisProperty.__set__
  File "/home/airflow/.local/lib/python3.8/site-packages/pandas/core/generic.py", line 730, in _set_axis
    self._mgr.set_axis(axis, labels)
  File "/home/airflow/.local/lib/python3.8/site-packages/pandas/core/internals/managers.py", line 225, in set_axis
    self._validate_set_axis(axis, new_labels)
  File "/home/airflow/.local/lib/python3.8/site-packages/pandas/core/internals/base.py", line 70, in _validate_set_axis
    raise ValueError(
ValueError: Length mismatch: Expected axis has 0 elements, new values have 15 elements
[2024-07-22T20:48:37.484+0000] {taskinstance.py:1149} INFO - Marking task as FAILED. dag_id=stagingtodv, task_id=staff, execution_date=20240721T000000, start_date=20240722T204835, end_date=20240722T204837
[2024-07-22T20:48:37.502+0000] {standard_task_runner.py:107} ERROR - Failed to execute job 13 for task staff (Length mismatch: Expected axis has 0 elements, new values have 15 elements; 105)
[2024-07-22T20:48:37.540+0000] {local_task_job_runner.py:234} INFO - Task exited with return code 1
[2024-07-22T20:48:37.613+0000] {taskinstance.py:3312} INFO - 0 downstream tasks scheduled from follow-on schedule check
[2024-07-22T20:50:36.755+0000] {taskinstance.py:1979} INFO - Dependencies all met for dep_context=non-requeueable deps ti=<TaskInstance: stagingtodv.staff scheduled__2024-07-21T00:00:00+00:00 [queued]>
[2024-07-22T20:50:36.781+0000] {taskinstance.py:1979} INFO - Dependencies all met for dep_context=requeueable deps ti=<TaskInstance: stagingtodv.staff scheduled__2024-07-21T00:00:00+00:00 [queued]>
[2024-07-22T20:50:36.785+0000] {taskinstance.py:2193} INFO - Starting attempt 1 of 1
[2024-07-22T20:50:36.824+0000] {taskinstance.py:2217} INFO - Executing <Task(PythonOperator): staff> on 2024-07-21 00:00:00+00:00
[2024-07-22T20:50:36.832+0000] {standard_task_runner.py:60} INFO - Started process 95 to run task
[2024-07-22T20:50:36.881+0000] {standard_task_runner.py:87} INFO - Running: ['***', 'tasks', 'run', 'stagingtodv', 'staff', 'scheduled__2024-07-21T00:00:00+00:00', '--job-id', '12', '--raw', '--subdir', 'DAGS_FOLDER/dag.py', '--cfg-path', '/tmp/tmpvfzanm65']
[2024-07-22T20:50:36.901+0000] {standard_task_runner.py:88} INFO - Job 12: Subtask staff
[2024-07-22T20:50:37.072+0000] {task_command.py:423} INFO - Running <TaskInstance: stagingtodv.staff scheduled__2024-07-21T00:00:00+00:00 [running]> on host c43d948598a9
[2024-07-22T20:50:38.126+0000] {taskinstance.py:2513} INFO - Exporting env vars: AIRFLOW_CTX_DAG_OWNER='***' AIRFLOW_CTX_DAG_ID='stagingtodv' AIRFLOW_CTX_TASK_ID='staff' AIRFLOW_CTX_EXECUTION_DATE='2024-07-21T00:00:00+00:00' AIRFLOW_CTX_TRY_NUMBER='1' AIRFLOW_CTX_DAG_RUN_ID='scheduled__2024-07-21T00:00:00+00:00'
[2024-07-22T20:50:38.135+0000] {logging_mixin.py:188} INFO - -------------------------------------------- select *  from etlconf.Etl_Process_Mapping where SourceTableName = 'staff' and Stage = 'stagingtodv'
[2024-07-22T20:50:38.340+0000] {taskinstance.py:2731} ERROR - Task failed with exception
Traceback (most recent call last):
  File "/home/airflow/.local/lib/python3.8/site-packages/airflow/models/taskinstance.py", line 444, in _execute_task
    result = _execute_callable(context=context, **execute_callable_kwargs)
  File "/home/airflow/.local/lib/python3.8/site-packages/airflow/models/taskinstance.py", line 414, in _execute_callable
    return execute_callable(context=context, **execute_callable_kwargs)
  File "/home/airflow/.local/lib/python3.8/site-packages/airflow/operators/python.py", line 200, in execute
    return_value = self.execute_callable()
  File "/home/airflow/.local/lib/python3.8/site-packages/airflow/operators/python.py", line 217, in execute_callable
    return self.python_callable(*self.op_args, **self.op_kwargs)
  File "/opt/airflow/dags/dag.py", line 41, in process_table
    tabletype = get_data_from_conf_table(table,stage)['tabletype'].values[0]
  File "/opt/airflow/dags/dag.py", line 34, in get_data_from_conf_table
    df.columns = [desc[0] for desc in cur.description]
  File "/home/airflow/.local/lib/python3.8/site-packages/pandas/core/generic.py", line 6002, in __setattr__
    return object.__setattr__(self, name, value)
  File "pandas/_libs/properties.pyx", line 69, in pandas._libs.properties.AxisProperty.__set__
  File "/home/airflow/.local/lib/python3.8/site-packages/pandas/core/generic.py", line 730, in _set_axis
    self._mgr.set_axis(axis, labels)
  File "/home/airflow/.local/lib/python3.8/site-packages/pandas/core/internals/managers.py", line 225, in set_axis
    self._validate_set_axis(axis, new_labels)
  File "/home/airflow/.local/lib/python3.8/site-packages/pandas/core/internals/base.py", line 70, in _validate_set_axis
    raise ValueError(
ValueError: Length mismatch: Expected axis has 0 elements, new values have 15 elements
[2024-07-22T20:50:38.370+0000] {taskinstance.py:1149} INFO - Marking task as FAILED. dag_id=stagingtodv, task_id=staff, execution_date=20240721T000000, start_date=20240722T205036, end_date=20240722T205038
[2024-07-22T20:50:38.472+0000] {standard_task_runner.py:107} ERROR - Failed to execute job 12 for task staff (Length mismatch: Expected axis has 0 elements, new values have 15 elements; 95)
[2024-07-22T20:50:38.529+0000] {local_task_job_runner.py:234} INFO - Task exited with return code 1
[2024-07-22T20:50:38.613+0000] {taskinstance.py:3312} INFO - 0 downstream tasks scheduled from follow-on schedule check
[2024-07-22T20:56:52.739+0000] {taskinstance.py:1979} INFO - Dependencies all met for dep_context=non-requeueable deps ti=<TaskInstance: stagingtodv.staff scheduled__2024-07-21T00:00:00+00:00 [queued]>
[2024-07-22T20:56:52.828+0000] {taskinstance.py:1979} INFO - Dependencies all met for dep_context=requeueable deps ti=<TaskInstance: stagingtodv.staff scheduled__2024-07-21T00:00:00+00:00 [queued]>
[2024-07-22T20:56:52.843+0000] {taskinstance.py:2193} INFO - Starting attempt 1 of 1
[2024-07-22T20:56:52.930+0000] {taskinstance.py:2217} INFO - Executing <Task(PythonOperator): staff> on 2024-07-21 00:00:00+00:00
[2024-07-22T20:56:52.954+0000] {standard_task_runner.py:60} INFO - Started process 119 to run task
[2024-07-22T20:56:52.961+0000] {standard_task_runner.py:87} INFO - Running: ['***', 'tasks', 'run', 'stagingtodv', 'staff', 'scheduled__2024-07-21T00:00:00+00:00', '--job-id', '15', '--raw', '--subdir', 'DAGS_FOLDER/dag.py', '--cfg-path', '/tmp/tmpujuqn9s2']
[2024-07-22T20:56:53.032+0000] {standard_task_runner.py:88} INFO - Job 15: Subtask staff
[2024-07-22T20:56:53.236+0000] {task_command.py:423} INFO - Running <TaskInstance: stagingtodv.staff scheduled__2024-07-21T00:00:00+00:00 [running]> on host b40f86dea2d7
[2024-07-22T20:56:54.387+0000] {taskinstance.py:2513} INFO - Exporting env vars: AIRFLOW_CTX_DAG_OWNER='***' AIRFLOW_CTX_DAG_ID='stagingtodv' AIRFLOW_CTX_TASK_ID='staff' AIRFLOW_CTX_EXECUTION_DATE='2024-07-21T00:00:00+00:00' AIRFLOW_CTX_TRY_NUMBER='1' AIRFLOW_CTX_DAG_RUN_ID='scheduled__2024-07-21T00:00:00+00:00'
[2024-07-22T20:56:54.390+0000] {logging_mixin.py:188} INFO - -------------------------------------------- select *  from etlconf.Etl_Process_Mapping where SourceTableName = 'staff' and Stage = 'stagingtodv'
[2024-07-22T20:56:54.448+0000] {taskinstance.py:2731} ERROR - Task failed with exception
Traceback (most recent call last):
  File "/home/airflow/.local/lib/python3.8/site-packages/airflow/models/taskinstance.py", line 444, in _execute_task
    result = _execute_callable(context=context, **execute_callable_kwargs)
  File "/home/airflow/.local/lib/python3.8/site-packages/airflow/models/taskinstance.py", line 414, in _execute_callable
    return execute_callable(context=context, **execute_callable_kwargs)
  File "/home/airflow/.local/lib/python3.8/site-packages/airflow/operators/python.py", line 200, in execute
    return_value = self.execute_callable()
  File "/home/airflow/.local/lib/python3.8/site-packages/airflow/operators/python.py", line 217, in execute_callable
    return self.python_callable(*self.op_args, **self.op_kwargs)
  File "/opt/airflow/dags/dag.py", line 41, in process_table
    tabletype = get_data_from_conf_table(table,stage)['tabletype'].values[0]
  File "/opt/airflow/dags/dag.py", line 34, in get_data_from_conf_table
    df.columns = [desc[0] for desc in cur.description]
  File "/home/airflow/.local/lib/python3.8/site-packages/pandas/core/generic.py", line 6002, in __setattr__
    return object.__setattr__(self, name, value)
  File "pandas/_libs/properties.pyx", line 69, in pandas._libs.properties.AxisProperty.__set__
  File "/home/airflow/.local/lib/python3.8/site-packages/pandas/core/generic.py", line 730, in _set_axis
    self._mgr.set_axis(axis, labels)
  File "/home/airflow/.local/lib/python3.8/site-packages/pandas/core/internals/managers.py", line 225, in set_axis
    self._validate_set_axis(axis, new_labels)
  File "/home/airflow/.local/lib/python3.8/site-packages/pandas/core/internals/base.py", line 70, in _validate_set_axis
    raise ValueError(
ValueError: Length mismatch: Expected axis has 0 elements, new values have 15 elements
[2024-07-22T20:56:54.496+0000] {taskinstance.py:1149} INFO - Marking task as FAILED. dag_id=stagingtodv, task_id=staff, execution_date=20240721T000000, start_date=20240722T205652, end_date=20240722T205654
[2024-07-22T20:56:54.537+0000] {standard_task_runner.py:107} ERROR - Failed to execute job 15 for task staff (Length mismatch: Expected axis has 0 elements, new values have 15 elements; 119)
[2024-07-22T20:56:54.589+0000] {local_task_job_runner.py:234} INFO - Task exited with return code 1
[2024-07-22T20:56:54.645+0000] {taskinstance.py:3312} INFO - 0 downstream tasks scheduled from follow-on schedule check
[2024-07-22T21:02:40.245+0000] {taskinstance.py:1979} INFO - Dependencies all met for dep_context=non-requeueable deps ti=<TaskInstance: stagingtodv.staff scheduled__2024-07-21T00:00:00+00:00 [queued]>
[2024-07-22T21:02:40.264+0000] {taskinstance.py:1979} INFO - Dependencies all met for dep_context=requeueable deps ti=<TaskInstance: stagingtodv.staff scheduled__2024-07-21T00:00:00+00:00 [queued]>
[2024-07-22T21:02:40.272+0000] {taskinstance.py:2193} INFO - Starting attempt 1 of 1
[2024-07-22T21:02:40.311+0000] {taskinstance.py:2217} INFO - Executing <Task(PythonOperator): staff> on 2024-07-21 00:00:00+00:00
[2024-07-22T21:02:40.328+0000] {standard_task_runner.py:60} INFO - Started process 120 to run task
[2024-07-22T21:02:40.339+0000] {standard_task_runner.py:87} INFO - Running: ['***', 'tasks', 'run', 'stagingtodv', 'staff', 'scheduled__2024-07-21T00:00:00+00:00', '--job-id', '10', '--raw', '--subdir', 'DAGS_FOLDER/dag.py', '--cfg-path', '/tmp/tmpwy5y7wiy']
[2024-07-22T21:02:40.353+0000] {standard_task_runner.py:88} INFO - Job 10: Subtask staff
[2024-07-22T21:02:40.544+0000] {task_command.py:423} INFO - Running <TaskInstance: stagingtodv.staff scheduled__2024-07-21T00:00:00+00:00 [running]> on host fd3c041fbc80
[2024-07-22T21:02:42.038+0000] {taskinstance.py:2513} INFO - Exporting env vars: AIRFLOW_CTX_DAG_OWNER='***' AIRFLOW_CTX_DAG_ID='stagingtodv' AIRFLOW_CTX_TASK_ID='staff' AIRFLOW_CTX_EXECUTION_DATE='2024-07-21T00:00:00+00:00' AIRFLOW_CTX_TRY_NUMBER='1' AIRFLOW_CTX_DAG_RUN_ID='scheduled__2024-07-21T00:00:00+00:00'
[2024-07-22T21:02:42.041+0000] {logging_mixin.py:188} INFO - -------------------------------------------- select *  from etlconf.Etl_Process_Mapping where SourceTableName = 'staff' and Stage = 'stagingtodv'
[2024-07-22T21:02:42.064+0000] {taskinstance.py:2731} ERROR - Task failed with exception
Traceback (most recent call last):
  File "/home/airflow/.local/lib/python3.8/site-packages/airflow/models/taskinstance.py", line 444, in _execute_task
    result = _execute_callable(context=context, **execute_callable_kwargs)
  File "/home/airflow/.local/lib/python3.8/site-packages/airflow/models/taskinstance.py", line 414, in _execute_callable
    return execute_callable(context=context, **execute_callable_kwargs)
  File "/home/airflow/.local/lib/python3.8/site-packages/airflow/operators/python.py", line 200, in execute
    return_value = self.execute_callable()
  File "/home/airflow/.local/lib/python3.8/site-packages/airflow/operators/python.py", line 217, in execute_callable
    return self.python_callable(*self.op_args, **self.op_kwargs)
  File "/opt/airflow/dags/dag.py", line 41, in process_table
    tabletype = get_data_from_conf_table(table,stage)['tabletype'].values[0]
  File "/opt/airflow/dags/dag.py", line 34, in get_data_from_conf_table
    df.columns = [desc[0] for desc in cur.description]
  File "/home/airflow/.local/lib/python3.8/site-packages/pandas/core/generic.py", line 6002, in __setattr__
    return object.__setattr__(self, name, value)
  File "pandas/_libs/properties.pyx", line 69, in pandas._libs.properties.AxisProperty.__set__
  File "/home/airflow/.local/lib/python3.8/site-packages/pandas/core/generic.py", line 730, in _set_axis
    self._mgr.set_axis(axis, labels)
  File "/home/airflow/.local/lib/python3.8/site-packages/pandas/core/internals/managers.py", line 225, in set_axis
    self._validate_set_axis(axis, new_labels)
  File "/home/airflow/.local/lib/python3.8/site-packages/pandas/core/internals/base.py", line 70, in _validate_set_axis
    raise ValueError(
ValueError: Length mismatch: Expected axis has 0 elements, new values have 15 elements
[2024-07-22T21:02:42.080+0000] {taskinstance.py:1149} INFO - Marking task as FAILED. dag_id=stagingtodv, task_id=staff, execution_date=20240721T000000, start_date=20240722T210240, end_date=20240722T210242
[2024-07-22T21:02:42.092+0000] {standard_task_runner.py:107} ERROR - Failed to execute job 10 for task staff (Length mismatch: Expected axis has 0 elements, new values have 15 elements; 120)
[2024-07-22T21:02:42.132+0000] {local_task_job_runner.py:234} INFO - Task exited with return code 1
[2024-07-22T21:02:42.150+0000] {taskinstance.py:3312} INFO - 0 downstream tasks scheduled from follow-on schedule check
[2024-07-22T21:05:27.947+0000] {taskinstance.py:1979} INFO - Dependencies all met for dep_context=non-requeueable deps ti=<TaskInstance: stagingtodv.staff scheduled__2024-07-21T00:00:00+00:00 [queued]>
[2024-07-22T21:05:27.967+0000] {taskinstance.py:1979} INFO - Dependencies all met for dep_context=requeueable deps ti=<TaskInstance: stagingtodv.staff scheduled__2024-07-21T00:00:00+00:00 [queued]>
[2024-07-22T21:05:27.970+0000] {taskinstance.py:2193} INFO - Starting attempt 1 of 1
[2024-07-22T21:05:28.001+0000] {taskinstance.py:2217} INFO - Executing <Task(PythonOperator): staff> on 2024-07-21 00:00:00+00:00
[2024-07-22T21:05:28.024+0000] {standard_task_runner.py:60} INFO - Started process 94 to run task
[2024-07-22T21:05:28.051+0000] {standard_task_runner.py:87} INFO - Running: ['***', 'tasks', 'run', 'stagingtodv', 'staff', 'scheduled__2024-07-21T00:00:00+00:00', '--job-id', '12', '--raw', '--subdir', 'DAGS_FOLDER/dag.py', '--cfg-path', '/tmp/tmpfk6hq0qq']
[2024-07-22T21:05:28.074+0000] {standard_task_runner.py:88} INFO - Job 12: Subtask staff
[2024-07-22T21:05:28.251+0000] {task_command.py:423} INFO - Running <TaskInstance: stagingtodv.staff scheduled__2024-07-21T00:00:00+00:00 [running]> on host f59a56d3cdcb
[2024-07-22T21:05:29.309+0000] {taskinstance.py:2513} INFO - Exporting env vars: AIRFLOW_CTX_DAG_OWNER='***' AIRFLOW_CTX_DAG_ID='stagingtodv' AIRFLOW_CTX_TASK_ID='staff' AIRFLOW_CTX_EXECUTION_DATE='2024-07-21T00:00:00+00:00' AIRFLOW_CTX_TRY_NUMBER='1' AIRFLOW_CTX_DAG_RUN_ID='scheduled__2024-07-21T00:00:00+00:00'
[2024-07-22T21:05:29.311+0000] {logging_mixin.py:188} INFO - -------------------------------------------- select *  from etlconf.Etl_Process_Mapping where SourceTableName = 'staff' and Stage = 'stagingtodv'
[2024-07-22T21:05:29.410+0000] {taskinstance.py:2731} ERROR - Task failed with exception
Traceback (most recent call last):
  File "/home/airflow/.local/lib/python3.8/site-packages/airflow/models/taskinstance.py", line 444, in _execute_task
    result = _execute_callable(context=context, **execute_callable_kwargs)
  File "/home/airflow/.local/lib/python3.8/site-packages/airflow/models/taskinstance.py", line 414, in _execute_callable
    return execute_callable(context=context, **execute_callable_kwargs)
  File "/home/airflow/.local/lib/python3.8/site-packages/airflow/operators/python.py", line 200, in execute
    return_value = self.execute_callable()
  File "/home/airflow/.local/lib/python3.8/site-packages/airflow/operators/python.py", line 217, in execute_callable
    return self.python_callable(*self.op_args, **self.op_kwargs)
  File "/opt/airflow/dags/dag.py", line 41, in process_table
    tabletype = get_data_from_conf_table(table,stage)['tabletype'].values[0]
  File "/opt/airflow/dags/dag.py", line 34, in get_data_from_conf_table
    df.columns = [desc[0] for desc in cur.description]
  File "/home/airflow/.local/lib/python3.8/site-packages/pandas/core/generic.py", line 6002, in __setattr__
    return object.__setattr__(self, name, value)
  File "pandas/_libs/properties.pyx", line 69, in pandas._libs.properties.AxisProperty.__set__
  File "/home/airflow/.local/lib/python3.8/site-packages/pandas/core/generic.py", line 730, in _set_axis
    self._mgr.set_axis(axis, labels)
  File "/home/airflow/.local/lib/python3.8/site-packages/pandas/core/internals/managers.py", line 225, in set_axis
    self._validate_set_axis(axis, new_labels)
  File "/home/airflow/.local/lib/python3.8/site-packages/pandas/core/internals/base.py", line 70, in _validate_set_axis
    raise ValueError(
ValueError: Length mismatch: Expected axis has 0 elements, new values have 15 elements
[2024-07-22T21:05:29.438+0000] {taskinstance.py:1149} INFO - Marking task as FAILED. dag_id=stagingtodv, task_id=staff, execution_date=20240721T000000, start_date=20240722T210527, end_date=20240722T210529
[2024-07-22T21:05:29.458+0000] {standard_task_runner.py:107} ERROR - Failed to execute job 12 for task staff (Length mismatch: Expected axis has 0 elements, new values have 15 elements; 94)
[2024-07-22T21:05:29.509+0000] {local_task_job_runner.py:234} INFO - Task exited with return code 1
[2024-07-22T21:05:29.528+0000] {taskinstance.py:3312} INFO - 0 downstream tasks scheduled from follow-on schedule check
