[2024-07-22T20:19:38.413+0000] {taskinstance.py:1979} INFO - Dependencies all met for dep_context=non-requeueable deps ti=<TaskInstance: stagingtodv.store manual__2024-07-22T20:19:35.757016+00:00 [queued]>
[2024-07-22T20:19:38.431+0000] {taskinstance.py:1979} INFO - Dependencies all met for dep_context=requeueable deps ti=<TaskInstance: stagingtodv.store manual__2024-07-22T20:19:35.757016+00:00 [queued]>
[2024-07-22T20:19:38.433+0000] {taskinstance.py:2193} INFO - Starting attempt 1 of 1
[2024-07-22T20:19:38.470+0000] {taskinstance.py:2217} INFO - Executing <Task(PythonOperator): store> on 2024-07-22 20:19:35.757016+00:00
[2024-07-22T20:19:38.481+0000] {standard_task_runner.py:60} INFO - Started process 177 to run task
[2024-07-22T20:19:38.491+0000] {standard_task_runner.py:87} INFO - Running: ['***', 'tasks', 'run', 'stagingtodv', 'store', 'manual__2024-07-22T20:19:35.757016+00:00', '--job-id', '19', '--raw', '--subdir', 'DAGS_FOLDER/dag.py', '--cfg-path', '/tmp/tmpbfkliazh']
[2024-07-22T20:19:38.498+0000] {standard_task_runner.py:88} INFO - Job 19: Subtask store
[2024-07-22T20:19:38.722+0000] {task_command.py:423} INFO - Running <TaskInstance: stagingtodv.store manual__2024-07-22T20:19:35.757016+00:00 [running]> on host 78ac63ab6c84
[2024-07-22T20:19:38.941+0000] {taskinstance.py:2513} INFO - Exporting env vars: AIRFLOW_CTX_DAG_OWNER='***' AIRFLOW_CTX_DAG_ID='stagingtodv' AIRFLOW_CTX_TASK_ID='store' AIRFLOW_CTX_EXECUTION_DATE='2024-07-22T20:19:35.757016+00:00' AIRFLOW_CTX_TRY_NUMBER='1' AIRFLOW_CTX_DAG_RUN_ID='manual__2024-07-22T20:19:35.757016+00:00'
[2024-07-22T20:19:38.945+0000] {logging_mixin.py:188} INFO - -------------------------------------------- select *  from etlconf.Etl_Process_Mapping where SourceTableName = 'store' and Stage = 'stagingtodv'
[2024-07-22T20:19:39.939+0000] {taskinstance.py:2731} ERROR - Task failed with exception
Traceback (most recent call last):
  File "/home/airflow/.local/lib/python3.8/site-packages/airflow/models/taskinstance.py", line 444, in _execute_task
    result = _execute_callable(context=context, **execute_callable_kwargs)
  File "/home/airflow/.local/lib/python3.8/site-packages/airflow/models/taskinstance.py", line 414, in _execute_callable
    return execute_callable(context=context, **execute_callable_kwargs)
  File "/home/airflow/.local/lib/python3.8/site-packages/airflow/operators/python.py", line 200, in execute
    return_value = self.execute_callable()
  File "/home/airflow/.local/lib/python3.8/site-packages/airflow/operators/python.py", line 217, in execute_callable
    return self.python_callable(*self.op_args, **self.op_kwargs)
  File "/opt/airflow/dags/dag.py", line 41, in process_table
    tabletype = get_data_from_conf_table(table,stage)['tabletype'].values[0]
  File "/opt/airflow/dags/dag.py", line 34, in get_data_from_conf_table
    df.columns = [desc[0] for desc in cur.description]
  File "/home/airflow/.local/lib/python3.8/site-packages/pandas/core/generic.py", line 6002, in __setattr__
    return object.__setattr__(self, name, value)
  File "pandas/_libs/properties.pyx", line 69, in pandas._libs.properties.AxisProperty.__set__
  File "/home/airflow/.local/lib/python3.8/site-packages/pandas/core/generic.py", line 730, in _set_axis
    self._mgr.set_axis(axis, labels)
  File "/home/airflow/.local/lib/python3.8/site-packages/pandas/core/internals/managers.py", line 225, in set_axis
    self._validate_set_axis(axis, new_labels)
  File "/home/airflow/.local/lib/python3.8/site-packages/pandas/core/internals/base.py", line 70, in _validate_set_axis
    raise ValueError(
ValueError: Length mismatch: Expected axis has 0 elements, new values have 15 elements
[2024-07-22T20:19:39.966+0000] {taskinstance.py:1149} INFO - Marking task as FAILED. dag_id=stagingtodv, task_id=store, execution_date=20240722T201935, start_date=20240722T201938, end_date=20240722T201939
[2024-07-22T20:19:39.999+0000] {standard_task_runner.py:107} ERROR - Failed to execute job 19 for task store (Length mismatch: Expected axis has 0 elements, new values have 15 elements; 177)
[2024-07-22T20:19:40.055+0000] {local_task_job_runner.py:234} INFO - Task exited with return code 1
[2024-07-22T20:19:40.097+0000] {taskinstance.py:3312} INFO - 0 downstream tasks scheduled from follow-on schedule check
