[2024-07-16T16:54:49.067+0000] {taskinstance.py:1979} INFO - Dependencies all met for dep_context=non-requeueable deps ti=<TaskInstance: staigingtodv.country scheduled__2024-07-15T00:00:00+00:00 [queued]>
[2024-07-16T16:54:49.085+0000] {taskinstance.py:1979} INFO - Dependencies all met for dep_context=requeueable deps ti=<TaskInstance: staigingtodv.country scheduled__2024-07-15T00:00:00+00:00 [queued]>
[2024-07-16T16:54:49.088+0000] {taskinstance.py:2193} INFO - Starting attempt 1 of 1
[2024-07-16T16:54:49.116+0000] {taskinstance.py:2217} INFO - Executing <Task(PythonOperator): country> on 2024-07-15 00:00:00+00:00
[2024-07-16T16:54:49.138+0000] {standard_task_runner.py:60} INFO - Started process 101 to run task
[2024-07-16T16:54:49.158+0000] {standard_task_runner.py:87} INFO - Running: ['***', 'tasks', 'run', 'staigingtodv', 'country', 'scheduled__2024-07-15T00:00:00+00:00', '--job-id', '17', '--raw', '--subdir', 'DAGS_FOLDER/dag.py', '--cfg-path', '/tmp/tmpui83mgz1']
[2024-07-16T16:54:49.164+0000] {standard_task_runner.py:88} INFO - Job 17: Subtask country
[2024-07-16T16:54:49.288+0000] {task_command.py:423} INFO - Running <TaskInstance: staigingtodv.country scheduled__2024-07-15T00:00:00+00:00 [running]> on host d9cb41fade7e
[2024-07-16T16:54:50.263+0000] {taskinstance.py:2513} INFO - Exporting env vars: AIRFLOW_CTX_DAG_OWNER='***' AIRFLOW_CTX_DAG_ID='staigingtodv' AIRFLOW_CTX_TASK_ID='country' AIRFLOW_CTX_EXECUTION_DATE='2024-07-15T00:00:00+00:00' AIRFLOW_CTX_TRY_NUMBER='1' AIRFLOW_CTX_DAG_RUN_ID='scheduled__2024-07-15T00:00:00+00:00'
[2024-07-16T16:54:50.337+0000] {taskinstance.py:2731} ERROR - Task failed with exception
Traceback (most recent call last):
  File "/home/airflow/.local/lib/python3.8/site-packages/airflow/models/taskinstance.py", line 444, in _execute_task
    result = _execute_callable(context=context, **execute_callable_kwargs)
  File "/home/airflow/.local/lib/python3.8/site-packages/airflow/models/taskinstance.py", line 414, in _execute_callable
    return execute_callable(context=context, **execute_callable_kwargs)
  File "/home/airflow/.local/lib/python3.8/site-packages/airflow/operators/python.py", line 200, in execute
    return_value = self.execute_callable()
  File "/home/airflow/.local/lib/python3.8/site-packages/airflow/operators/python.py", line 217, in execute_callable
    return self.python_callable(*self.op_args, **self.op_kwargs)
  File "/opt/airflow/dags/dag.py", line 40, in process_table
    tabletype = get_data_from_conf_table(table,stage)['tabletype'].values[0]
  File "/opt/airflow/dags/dag.py", line 33, in get_data_from_conf_table
    df.columns = [desc[0] for desc in cur.description]
  File "/home/airflow/.local/lib/python3.8/site-packages/pandas/core/generic.py", line 6002, in __setattr__
    return object.__setattr__(self, name, value)
  File "pandas/_libs/properties.pyx", line 69, in pandas._libs.properties.AxisProperty.__set__
  File "/home/airflow/.local/lib/python3.8/site-packages/pandas/core/generic.py", line 730, in _set_axis
    self._mgr.set_axis(axis, labels)
  File "/home/airflow/.local/lib/python3.8/site-packages/pandas/core/internals/managers.py", line 225, in set_axis
    self._validate_set_axis(axis, new_labels)
  File "/home/airflow/.local/lib/python3.8/site-packages/pandas/core/internals/base.py", line 70, in _validate_set_axis
    raise ValueError(
ValueError: Length mismatch: Expected axis has 0 elements, new values have 15 elements
[2024-07-16T16:54:50.381+0000] {taskinstance.py:1149} INFO - Marking task as FAILED. dag_id=staigingtodv, task_id=country, execution_date=20240715T000000, start_date=20240716T165449, end_date=20240716T165450
[2024-07-16T16:54:50.438+0000] {standard_task_runner.py:107} ERROR - Failed to execute job 17 for task country (Length mismatch: Expected axis has 0 elements, new values have 15 elements; 101)
[2024-07-16T16:54:50.494+0000] {local_task_job_runner.py:234} INFO - Task exited with return code 1
[2024-07-16T16:54:50.526+0000] {taskinstance.py:3312} INFO - 0 downstream tasks scheduled from follow-on schedule check
[2024-07-16T16:58:22.088+0000] {taskinstance.py:1979} INFO - Dependencies all met for dep_context=non-requeueable deps ti=<TaskInstance: staigingtodv.country scheduled__2024-07-15T00:00:00+00:00 [queued]>
[2024-07-16T16:58:22.127+0000] {taskinstance.py:1979} INFO - Dependencies all met for dep_context=requeueable deps ti=<TaskInstance: staigingtodv.country scheduled__2024-07-15T00:00:00+00:00 [queued]>
[2024-07-16T16:58:22.128+0000] {taskinstance.py:2193} INFO - Starting attempt 1 of 1
[2024-07-16T16:58:22.165+0000] {taskinstance.py:2217} INFO - Executing <Task(PythonOperator): country> on 2024-07-15 00:00:00+00:00
[2024-07-16T16:58:22.191+0000] {standard_task_runner.py:60} INFO - Started process 103 to run task
[2024-07-16T16:58:22.223+0000] {standard_task_runner.py:87} INFO - Running: ['***', 'tasks', 'run', 'staigingtodv', 'country', 'scheduled__2024-07-15T00:00:00+00:00', '--job-id', '11', '--raw', '--subdir', 'DAGS_FOLDER/dag.py', '--cfg-path', '/tmp/tmpixolv0mg']
[2024-07-16T16:58:22.261+0000] {standard_task_runner.py:88} INFO - Job 11: Subtask country
[2024-07-16T16:58:22.460+0000] {task_command.py:423} INFO - Running <TaskInstance: staigingtodv.country scheduled__2024-07-15T00:00:00+00:00 [running]> on host bd70e8223b94
[2024-07-16T16:58:24.132+0000] {taskinstance.py:2513} INFO - Exporting env vars: AIRFLOW_CTX_DAG_OWNER='***' AIRFLOW_CTX_DAG_ID='staigingtodv' AIRFLOW_CTX_TASK_ID='country' AIRFLOW_CTX_EXECUTION_DATE='2024-07-15T00:00:00+00:00' AIRFLOW_CTX_TRY_NUMBER='1' AIRFLOW_CTX_DAG_RUN_ID='scheduled__2024-07-15T00:00:00+00:00'
[2024-07-16T16:58:24.151+0000] {taskinstance.py:2731} ERROR - Task failed with exception
Traceback (most recent call last):
  File "/home/airflow/.local/lib/python3.8/site-packages/airflow/models/taskinstance.py", line 444, in _execute_task
    result = _execute_callable(context=context, **execute_callable_kwargs)
  File "/home/airflow/.local/lib/python3.8/site-packages/airflow/models/taskinstance.py", line 414, in _execute_callable
    return execute_callable(context=context, **execute_callable_kwargs)
  File "/home/airflow/.local/lib/python3.8/site-packages/airflow/operators/python.py", line 200, in execute
    return_value = self.execute_callable()
  File "/home/airflow/.local/lib/python3.8/site-packages/airflow/operators/python.py", line 217, in execute_callable
    return self.python_callable(*self.op_args, **self.op_kwargs)
  File "/opt/airflow/dags/dag.py", line 40, in process_table
    tabletype = get_data_from_conf_table(table,stage)['tabletype'].values[0]
  File "/opt/airflow/dags/dag.py", line 33, in get_data_from_conf_table
    df.columns = [desc[0] for desc in cur.description]
  File "/home/airflow/.local/lib/python3.8/site-packages/pandas/core/generic.py", line 6002, in __setattr__
    return object.__setattr__(self, name, value)
  File "pandas/_libs/properties.pyx", line 69, in pandas._libs.properties.AxisProperty.__set__
  File "/home/airflow/.local/lib/python3.8/site-packages/pandas/core/generic.py", line 730, in _set_axis
    self._mgr.set_axis(axis, labels)
  File "/home/airflow/.local/lib/python3.8/site-packages/pandas/core/internals/managers.py", line 225, in set_axis
    self._validate_set_axis(axis, new_labels)
  File "/home/airflow/.local/lib/python3.8/site-packages/pandas/core/internals/base.py", line 70, in _validate_set_axis
    raise ValueError(
ValueError: Length mismatch: Expected axis has 0 elements, new values have 15 elements
[2024-07-16T16:58:24.165+0000] {taskinstance.py:1149} INFO - Marking task as FAILED. dag_id=staigingtodv, task_id=country, execution_date=20240715T000000, start_date=20240716T165822, end_date=20240716T165824
[2024-07-16T16:58:24.180+0000] {standard_task_runner.py:107} ERROR - Failed to execute job 11 for task country (Length mismatch: Expected axis has 0 elements, new values have 15 elements; 103)
[2024-07-16T16:58:24.217+0000] {local_task_job_runner.py:234} INFO - Task exited with return code 1
[2024-07-16T16:58:24.230+0000] {taskinstance.py:3312} INFO - 0 downstream tasks scheduled from follow-on schedule check
[2024-07-16T17:06:16.375+0000] {taskinstance.py:1979} INFO - Dependencies all met for dep_context=non-requeueable deps ti=<TaskInstance: staigingtodv.country scheduled__2024-07-15T00:00:00+00:00 [queued]>
[2024-07-16T17:06:16.395+0000] {taskinstance.py:1979} INFO - Dependencies all met for dep_context=requeueable deps ti=<TaskInstance: staigingtodv.country scheduled__2024-07-15T00:00:00+00:00 [queued]>
[2024-07-16T17:06:16.400+0000] {taskinstance.py:2193} INFO - Starting attempt 1 of 1
[2024-07-16T17:06:16.430+0000] {taskinstance.py:2217} INFO - Executing <Task(PythonOperator): country> on 2024-07-15 00:00:00+00:00
[2024-07-16T17:06:16.440+0000] {standard_task_runner.py:60} INFO - Started process 88 to run task
[2024-07-16T17:06:16.457+0000] {standard_task_runner.py:87} INFO - Running: ['***', 'tasks', 'run', 'staigingtodv', 'country', 'scheduled__2024-07-15T00:00:00+00:00', '--job-id', '5', '--raw', '--subdir', 'DAGS_FOLDER/dag.py', '--cfg-path', '/tmp/tmp21rojt2a']
[2024-07-16T17:06:16.477+0000] {standard_task_runner.py:88} INFO - Job 5: Subtask country
[2024-07-16T17:06:16.650+0000] {task_command.py:423} INFO - Running <TaskInstance: staigingtodv.country scheduled__2024-07-15T00:00:00+00:00 [running]> on host d972e0703431
[2024-07-16T17:06:16.865+0000] {taskinstance.py:2513} INFO - Exporting env vars: AIRFLOW_CTX_DAG_OWNER='***' AIRFLOW_CTX_DAG_ID='staigingtodv' AIRFLOW_CTX_TASK_ID='country' AIRFLOW_CTX_EXECUTION_DATE='2024-07-15T00:00:00+00:00' AIRFLOW_CTX_TRY_NUMBER='1' AIRFLOW_CTX_DAG_RUN_ID='scheduled__2024-07-15T00:00:00+00:00'
[2024-07-16T17:06:18.090+0000] {taskinstance.py:2731} ERROR - Task failed with exception
Traceback (most recent call last):
  File "/home/airflow/.local/lib/python3.8/site-packages/airflow/models/taskinstance.py", line 444, in _execute_task
    result = _execute_callable(context=context, **execute_callable_kwargs)
  File "/home/airflow/.local/lib/python3.8/site-packages/airflow/models/taskinstance.py", line 414, in _execute_callable
    return execute_callable(context=context, **execute_callable_kwargs)
  File "/home/airflow/.local/lib/python3.8/site-packages/airflow/operators/python.py", line 200, in execute
    return_value = self.execute_callable()
  File "/home/airflow/.local/lib/python3.8/site-packages/airflow/operators/python.py", line 217, in execute_callable
    return self.python_callable(*self.op_args, **self.op_kwargs)
  File "/opt/airflow/dags/dag.py", line 40, in process_table
    tabletype = get_data_from_conf_table(table,stage)['tabletype'].values[0]
  File "/opt/airflow/dags/dag.py", line 33, in get_data_from_conf_table
    df.columns = [desc[0] for desc in cur.description]
  File "/home/airflow/.local/lib/python3.8/site-packages/pandas/core/generic.py", line 6002, in __setattr__
    return object.__setattr__(self, name, value)
  File "pandas/_libs/properties.pyx", line 69, in pandas._libs.properties.AxisProperty.__set__
  File "/home/airflow/.local/lib/python3.8/site-packages/pandas/core/generic.py", line 730, in _set_axis
    self._mgr.set_axis(axis, labels)
  File "/home/airflow/.local/lib/python3.8/site-packages/pandas/core/internals/managers.py", line 225, in set_axis
    self._validate_set_axis(axis, new_labels)
  File "/home/airflow/.local/lib/python3.8/site-packages/pandas/core/internals/base.py", line 70, in _validate_set_axis
    raise ValueError(
ValueError: Length mismatch: Expected axis has 0 elements, new values have 15 elements
[2024-07-16T17:06:18.128+0000] {taskinstance.py:1149} INFO - Marking task as FAILED. dag_id=staigingtodv, task_id=country, execution_date=20240715T000000, start_date=20240716T170616, end_date=20240716T170618
[2024-07-16T17:06:18.151+0000] {standard_task_runner.py:107} ERROR - Failed to execute job 5 for task country (Length mismatch: Expected axis has 0 elements, new values have 15 elements; 88)
[2024-07-16T17:06:18.183+0000] {local_task_job_runner.py:234} INFO - Task exited with return code 1
[2024-07-16T17:06:18.244+0000] {taskinstance.py:3312} INFO - 0 downstream tasks scheduled from follow-on schedule check
[2024-07-16T17:10:13.474+0000] {taskinstance.py:1979} INFO - Dependencies all met for dep_context=non-requeueable deps ti=<TaskInstance: staigingtodv.country scheduled__2024-07-15T00:00:00+00:00 [queued]>
[2024-07-16T17:10:13.485+0000] {taskinstance.py:1979} INFO - Dependencies all met for dep_context=requeueable deps ti=<TaskInstance: staigingtodv.country scheduled__2024-07-15T00:00:00+00:00 [queued]>
[2024-07-16T17:10:13.485+0000] {taskinstance.py:2193} INFO - Starting attempt 1 of 1
[2024-07-16T17:10:13.532+0000] {taskinstance.py:2217} INFO - Executing <Task(PythonOperator): country> on 2024-07-15 00:00:00+00:00
[2024-07-16T17:10:13.557+0000] {standard_task_runner.py:60} INFO - Started process 95 to run task
[2024-07-16T17:10:13.572+0000] {standard_task_runner.py:87} INFO - Running: ['***', 'tasks', 'run', 'staigingtodv', 'country', 'scheduled__2024-07-15T00:00:00+00:00', '--job-id', '9', '--raw', '--subdir', 'DAGS_FOLDER/dag.py', '--cfg-path', '/tmp/tmpise6hrsj']
[2024-07-16T17:10:13.596+0000] {standard_task_runner.py:88} INFO - Job 9: Subtask country
[2024-07-16T17:10:13.878+0000] {task_command.py:423} INFO - Running <TaskInstance: staigingtodv.country scheduled__2024-07-15T00:00:00+00:00 [running]> on host a8165c4616a2
[2024-07-16T17:10:14.973+0000] {taskinstance.py:2513} INFO - Exporting env vars: AIRFLOW_CTX_DAG_OWNER='***' AIRFLOW_CTX_DAG_ID='staigingtodv' AIRFLOW_CTX_TASK_ID='country' AIRFLOW_CTX_EXECUTION_DATE='2024-07-15T00:00:00+00:00' AIRFLOW_CTX_TRY_NUMBER='1' AIRFLOW_CTX_DAG_RUN_ID='scheduled__2024-07-15T00:00:00+00:00'
[2024-07-16T17:10:15.139+0000] {taskinstance.py:2731} ERROR - Task failed with exception
Traceback (most recent call last):
  File "/home/airflow/.local/lib/python3.8/site-packages/airflow/models/taskinstance.py", line 444, in _execute_task
    result = _execute_callable(context=context, **execute_callable_kwargs)
  File "/home/airflow/.local/lib/python3.8/site-packages/airflow/models/taskinstance.py", line 414, in _execute_callable
    return execute_callable(context=context, **execute_callable_kwargs)
  File "/home/airflow/.local/lib/python3.8/site-packages/airflow/operators/python.py", line 200, in execute
    return_value = self.execute_callable()
  File "/home/airflow/.local/lib/python3.8/site-packages/airflow/operators/python.py", line 217, in execute_callable
    return self.python_callable(*self.op_args, **self.op_kwargs)
  File "/opt/airflow/dags/dag.py", line 40, in process_table
    tabletype = get_data_from_conf_table(table,stage)['tabletype'].values[0]
  File "/opt/airflow/dags/dag.py", line 33, in get_data_from_conf_table
    df.columns = [desc[0] for desc in cur.description]
  File "/home/airflow/.local/lib/python3.8/site-packages/pandas/core/generic.py", line 6002, in __setattr__
    return object.__setattr__(self, name, value)
  File "pandas/_libs/properties.pyx", line 69, in pandas._libs.properties.AxisProperty.__set__
  File "/home/airflow/.local/lib/python3.8/site-packages/pandas/core/generic.py", line 730, in _set_axis
    self._mgr.set_axis(axis, labels)
  File "/home/airflow/.local/lib/python3.8/site-packages/pandas/core/internals/managers.py", line 225, in set_axis
    self._validate_set_axis(axis, new_labels)
  File "/home/airflow/.local/lib/python3.8/site-packages/pandas/core/internals/base.py", line 70, in _validate_set_axis
    raise ValueError(
ValueError: Length mismatch: Expected axis has 0 elements, new values have 15 elements
[2024-07-16T17:10:15.157+0000] {taskinstance.py:1149} INFO - Marking task as FAILED. dag_id=staigingtodv, task_id=country, execution_date=20240715T000000, start_date=20240716T171013, end_date=20240716T171015
[2024-07-16T17:10:15.173+0000] {standard_task_runner.py:107} ERROR - Failed to execute job 9 for task country (Length mismatch: Expected axis has 0 elements, new values have 15 elements; 95)
[2024-07-16T17:10:15.206+0000] {local_task_job_runner.py:234} INFO - Task exited with return code 1
[2024-07-16T17:10:15.300+0000] {taskinstance.py:3312} INFO - 0 downstream tasks scheduled from follow-on schedule check
