[2024-07-16T17:23:42.842+0000] {taskinstance.py:1979} INFO - Dependencies all met for dep_context=non-requeueable deps ti=<TaskInstance: stagingtodv.actor scheduled__2024-07-15T00:00:00+00:00 [queued]>
[2024-07-16T17:23:42.868+0000] {taskinstance.py:1979} INFO - Dependencies all met for dep_context=requeueable deps ti=<TaskInstance: stagingtodv.actor scheduled__2024-07-15T00:00:00+00:00 [queued]>
[2024-07-16T17:23:42.872+0000] {taskinstance.py:2193} INFO - Starting attempt 1 of 1
[2024-07-16T17:23:42.940+0000] {taskinstance.py:2217} INFO - Executing <Task(PythonOperator): actor> on 2024-07-15 00:00:00+00:00
[2024-07-16T17:23:42.959+0000] {standard_task_runner.py:60} INFO - Started process 398 to run task
[2024-07-16T17:23:42.972+0000] {standard_task_runner.py:87} INFO - Running: ['***', 'tasks', 'run', 'stagingtodv', 'actor', 'scheduled__2024-07-15T00:00:00+00:00', '--job-id', '45', '--raw', '--subdir', 'DAGS_FOLDER/dag.py', '--cfg-path', '/tmp/tmpqpw3inlq']
[2024-07-16T17:23:43.001+0000] {standard_task_runner.py:88} INFO - Job 45: Subtask actor
[2024-07-16T17:23:43.227+0000] {task_command.py:423} INFO - Running <TaskInstance: stagingtodv.actor scheduled__2024-07-15T00:00:00+00:00 [running]> on host a8165c4616a2
[2024-07-16T17:23:43.645+0000] {taskinstance.py:2513} INFO - Exporting env vars: AIRFLOW_CTX_DAG_OWNER='***' AIRFLOW_CTX_DAG_ID='stagingtodv' AIRFLOW_CTX_TASK_ID='actor' AIRFLOW_CTX_EXECUTION_DATE='2024-07-15T00:00:00+00:00' AIRFLOW_CTX_TRY_NUMBER='1' AIRFLOW_CTX_DAG_RUN_ID='scheduled__2024-07-15T00:00:00+00:00'
[2024-07-16T17:23:43.649+0000] {logging_mixin.py:188} INFO - -------------------------------------------- select *  from etlconf.Etl_Process_Mapping where SourceTableName = 'actor' and Stage = 'stagingtodv'
[2024-07-16T17:23:43.713+0000] {logging_mixin.py:188} INFO - shemodixar? sasadasfaf
[2024-07-16T17:23:43.719+0000] {logging_mixin.py:188} INFO - select *  from etlconf.Etl_Process_Mapping where SourceTableName = 'actor' and Stage = 'stagingtodv'
[2024-07-16T17:23:43.790+0000] {logging_mixin.py:188} INFO - dasfadfasdasfadsggssfgsahjbfhajvfhasvdasb cn akjsbjhasbc  asjbcajhsbca
[2024-07-16T17:23:44.591+0000] {logging_mixin.py:188} INFO -    id sourcetablename sourcedbname  ... code        stage last_run_date
0  18           actor    DBStaging  ...    1  stagingtodv          None

[1 rows x 15 columns]
[2024-07-16T17:23:44.661+0000] {taskinstance.py:2731} ERROR - Task failed with exception
Traceback (most recent call last):
  File "/home/airflow/.local/lib/python3.8/site-packages/airflow/models/taskinstance.py", line 444, in _execute_task
    result = _execute_callable(context=context, **execute_callable_kwargs)
  File "/home/airflow/.local/lib/python3.8/site-packages/airflow/models/taskinstance.py", line 414, in _execute_callable
    return execute_callable(context=context, **execute_callable_kwargs)
  File "/home/airflow/.local/lib/python3.8/site-packages/airflow/operators/python.py", line 200, in execute
    return_value = self.execute_callable()
  File "/home/airflow/.local/lib/python3.8/site-packages/airflow/operators/python.py", line 217, in execute_callable
    return self.python_callable(*self.op_args, **self.op_kwargs)
  File "/opt/airflow/dags/dag.py", line 45, in process_table
    return  execute(table, stage, tabletype)
  File "/app/main.py", line 31, in execute
    (StagingToDV().create_full().some_function(table, stage))
  File "/app/concretestage/StagingToDV.py", line 39, in some_function
    sourceDF = getDF(sourcedbname,sourcetablename , sourceschema)
  File "/app/myFramework/utils/utils.py", line 27, in getDF
    cur.execute(query)
psycopg2.errors.FeatureNotSupported: cross-database references are not implemented: "dbstaging.dvdrental.actor"
LINE 1: select T.* from DBStaging.dvdrental.actor T
                        ^

[2024-07-16T17:23:44.758+0000] {taskinstance.py:1149} INFO - Marking task as FAILED. dag_id=stagingtodv, task_id=actor, execution_date=20240715T000000, start_date=20240716T172342, end_date=20240716T172344
[2024-07-16T17:23:44.849+0000] {standard_task_runner.py:107} ERROR - Failed to execute job 45 for task actor (cross-database references are not implemented: "dbstaging.dvdrental.actor"
LINE 1: select T.* from DBStaging.dvdrental.actor T
                        ^
; 398)
[2024-07-16T17:23:44.924+0000] {local_task_job_runner.py:234} INFO - Task exited with return code 1
[2024-07-16T17:23:45.001+0000] {taskinstance.py:3312} INFO - 0 downstream tasks scheduled from follow-on schedule check
[2024-07-16T17:33:45.971+0000] {taskinstance.py:1979} INFO - Dependencies all met for dep_context=non-requeueable deps ti=<TaskInstance: stagingtodv.actor scheduled__2024-07-15T00:00:00+00:00 [queued]>
[2024-07-16T17:33:45.990+0000] {taskinstance.py:1979} INFO - Dependencies all met for dep_context=requeueable deps ti=<TaskInstance: stagingtodv.actor scheduled__2024-07-15T00:00:00+00:00 [queued]>
[2024-07-16T17:33:45.991+0000] {taskinstance.py:2193} INFO - Starting attempt 1 of 1
[2024-07-16T17:33:46.029+0000] {taskinstance.py:2217} INFO - Executing <Task(PythonOperator): actor> on 2024-07-15 00:00:00+00:00
[2024-07-16T17:33:46.060+0000] {standard_task_runner.py:60} INFO - Started process 113 to run task
[2024-07-16T17:33:46.088+0000] {standard_task_runner.py:87} INFO - Running: ['***', 'tasks', 'run', 'stagingtodv', 'actor', 'scheduled__2024-07-15T00:00:00+00:00', '--job-id', '5', '--raw', '--subdir', 'DAGS_FOLDER/dag.py', '--cfg-path', '/tmp/tmp4ph4yv7d']
[2024-07-16T17:33:46.096+0000] {standard_task_runner.py:88} INFO - Job 5: Subtask actor
[2024-07-16T17:33:46.334+0000] {task_command.py:423} INFO - Running <TaskInstance: stagingtodv.actor scheduled__2024-07-15T00:00:00+00:00 [running]> on host e9bb94dbac8b
[2024-07-16T17:33:47.486+0000] {taskinstance.py:2513} INFO - Exporting env vars: AIRFLOW_CTX_DAG_OWNER='***' AIRFLOW_CTX_DAG_ID='stagingtodv' AIRFLOW_CTX_TASK_ID='actor' AIRFLOW_CTX_EXECUTION_DATE='2024-07-15T00:00:00+00:00' AIRFLOW_CTX_TRY_NUMBER='1' AIRFLOW_CTX_DAG_RUN_ID='scheduled__2024-07-15T00:00:00+00:00'
[2024-07-16T17:33:47.489+0000] {logging_mixin.py:188} INFO - -------------------------------------------- select *  from etlconf.Etl_Process_Mapping where SourceTableName = 'actor' and Stage = 'stagingtodv'
[2024-07-16T17:33:47.600+0000] {logging_mixin.py:188} INFO - select *  from etlconf.Etl_Process_Mapping where SourceTableName = 'actor' and Stage = 'stagingtodv'
[2024-07-16T17:33:47.717+0000] {logging_mixin.py:188} INFO - 
 DBStaging 
 actor 
 dvdrental
[2024-07-16T17:33:47.720+0000] {python.py:202} INFO - Done. Returned value was: None
[2024-07-16T17:33:47.769+0000] {taskinstance.py:1149} INFO - Marking task as SUCCESS. dag_id=stagingtodv, task_id=actor, execution_date=20240715T000000, start_date=20240716T173345, end_date=20240716T173347
[2024-07-16T17:33:47.866+0000] {local_task_job_runner.py:234} INFO - Task exited with return code 0
[2024-07-16T17:33:47.901+0000] {taskinstance.py:3312} INFO - 0 downstream tasks scheduled from follow-on schedule check
[2024-07-16T17:36:01.249+0000] {taskinstance.py:1979} INFO - Dependencies all met for dep_context=non-requeueable deps ti=<TaskInstance: stagingtodv.actor scheduled__2024-07-15T00:00:00+00:00 [queued]>
[2024-07-16T17:36:01.268+0000] {taskinstance.py:1979} INFO - Dependencies all met for dep_context=requeueable deps ti=<TaskInstance: stagingtodv.actor scheduled__2024-07-15T00:00:00+00:00 [queued]>
[2024-07-16T17:36:01.270+0000] {taskinstance.py:2193} INFO - Starting attempt 1 of 1
[2024-07-16T17:36:01.404+0000] {taskinstance.py:2217} INFO - Executing <Task(PythonOperator): actor> on 2024-07-15 00:00:00+00:00
[2024-07-16T17:36:01.439+0000] {standard_task_runner.py:60} INFO - Started process 103 to run task
[2024-07-16T17:36:01.480+0000] {standard_task_runner.py:87} INFO - Running: ['***', 'tasks', 'run', 'stagingtodv', 'actor', 'scheduled__2024-07-15T00:00:00+00:00', '--job-id', '17', '--raw', '--subdir', 'DAGS_FOLDER/dag.py', '--cfg-path', '/tmp/tmpm8wpdesi']
[2024-07-16T17:36:01.505+0000] {standard_task_runner.py:88} INFO - Job 17: Subtask actor
[2024-07-16T17:36:01.793+0000] {task_command.py:423} INFO - Running <TaskInstance: stagingtodv.actor scheduled__2024-07-15T00:00:00+00:00 [running]> on host e1ba87a2fe19
[2024-07-16T17:36:02.657+0000] {taskinstance.py:2513} INFO - Exporting env vars: AIRFLOW_CTX_DAG_OWNER='***' AIRFLOW_CTX_DAG_ID='stagingtodv' AIRFLOW_CTX_TASK_ID='actor' AIRFLOW_CTX_EXECUTION_DATE='2024-07-15T00:00:00+00:00' AIRFLOW_CTX_TRY_NUMBER='1' AIRFLOW_CTX_DAG_RUN_ID='scheduled__2024-07-15T00:00:00+00:00'
[2024-07-16T17:36:02.671+0000] {logging_mixin.py:188} INFO - -------------------------------------------- select *  from etlconf.Etl_Process_Mapping where SourceTableName = 'actor' and Stage = 'stagingtodv'
[2024-07-16T17:36:02.712+0000] {logging_mixin.py:188} INFO - select *  from etlconf.Etl_Process_Mapping where SourceTableName = 'actor' and Stage = 'stagingtodv'
[2024-07-16T17:36:02.751+0000] {taskinstance.py:2731} ERROR - Task failed with exception
Traceback (most recent call last):
  File "/home/airflow/.local/lib/python3.8/site-packages/airflow/models/taskinstance.py", line 444, in _execute_task
    result = _execute_callable(context=context, **execute_callable_kwargs)
  File "/home/airflow/.local/lib/python3.8/site-packages/airflow/models/taskinstance.py", line 414, in _execute_callable
    return execute_callable(context=context, **execute_callable_kwargs)
  File "/home/airflow/.local/lib/python3.8/site-packages/airflow/operators/python.py", line 200, in execute
    return_value = self.execute_callable()
  File "/home/airflow/.local/lib/python3.8/site-packages/airflow/operators/python.py", line 217, in execute_callable
    return self.python_callable(*self.op_args, **self.op_kwargs)
  File "/opt/airflow/dags/dag.py", line 45, in process_table
    return  execute(table, stage, tabletype)
  File "/app/main.py", line 31, in execute
    (StagingToDV().create_full().some_function(table, stage))
  File "/app/concretestage/StagingToDV.py", line 36, in some_function
    sourceDF = getDF(sourcedbname,sourcetablename , sourceschema)
  File "/app/myFramework/utils/utils.py", line 27, in getDF
    cur.execute(query)
psycopg2.errors.FeatureNotSupported: cross-database references are not implemented: "dbstaging.dvdrental.actor"
LINE 1: select T.* from DBStaging.dvdrental.actor T
                        ^

[2024-07-16T17:36:02.771+0000] {taskinstance.py:1149} INFO - Marking task as FAILED. dag_id=stagingtodv, task_id=actor, execution_date=20240715T000000, start_date=20240716T173601, end_date=20240716T173602
[2024-07-16T17:36:02.815+0000] {standard_task_runner.py:107} ERROR - Failed to execute job 17 for task actor (cross-database references are not implemented: "dbstaging.dvdrental.actor"
LINE 1: select T.* from DBStaging.dvdrental.actor T
                        ^
; 103)
[2024-07-16T17:36:02.834+0000] {local_task_job_runner.py:234} INFO - Task exited with return code 1
[2024-07-16T17:36:02.906+0000] {taskinstance.py:3312} INFO - 0 downstream tasks scheduled from follow-on schedule check
[2024-07-16T17:45:34.793+0000] {taskinstance.py:1979} INFO - Dependencies all met for dep_context=non-requeueable deps ti=<TaskInstance: stagingtodv.actor scheduled__2024-07-15T00:00:00+00:00 [queued]>
[2024-07-16T17:45:34.804+0000] {taskinstance.py:1979} INFO - Dependencies all met for dep_context=requeueable deps ti=<TaskInstance: stagingtodv.actor scheduled__2024-07-15T00:00:00+00:00 [queued]>
[2024-07-16T17:45:34.807+0000] {taskinstance.py:2193} INFO - Starting attempt 1 of 1
[2024-07-16T17:45:34.854+0000] {taskinstance.py:2217} INFO - Executing <Task(PythonOperator): actor> on 2024-07-15 00:00:00+00:00
[2024-07-16T17:45:34.867+0000] {standard_task_runner.py:60} INFO - Started process 89 to run task
[2024-07-16T17:45:34.905+0000] {standard_task_runner.py:87} INFO - Running: ['***', 'tasks', 'run', 'stagingtodv', 'actor', 'scheduled__2024-07-15T00:00:00+00:00', '--job-id', '7', '--raw', '--subdir', 'DAGS_FOLDER/dag.py', '--cfg-path', '/tmp/tmp7_19jajd']
[2024-07-16T17:45:34.909+0000] {standard_task_runner.py:88} INFO - Job 7: Subtask actor
[2024-07-16T17:45:35.110+0000] {task_command.py:423} INFO - Running <TaskInstance: stagingtodv.actor scheduled__2024-07-15T00:00:00+00:00 [running]> on host bba7487a60b5
[2024-07-16T17:45:36.762+0000] {taskinstance.py:2513} INFO - Exporting env vars: AIRFLOW_CTX_DAG_OWNER='***' AIRFLOW_CTX_DAG_ID='stagingtodv' AIRFLOW_CTX_TASK_ID='actor' AIRFLOW_CTX_EXECUTION_DATE='2024-07-15T00:00:00+00:00' AIRFLOW_CTX_TRY_NUMBER='1' AIRFLOW_CTX_DAG_RUN_ID='scheduled__2024-07-15T00:00:00+00:00'
[2024-07-16T17:45:36.769+0000] {logging_mixin.py:188} INFO - -------------------------------------------- select *  from etlconf.Etl_Process_Mapping where SourceTableName = 'actor' and Stage = 'stagingtodv'
[2024-07-16T17:45:36.801+0000] {logging_mixin.py:188} INFO - select *  from etlconf.Etl_Process_Mapping where SourceTableName = 'actor' and Stage = 'stagingtodv'
[2024-07-16T17:45:36.863+0000] {taskinstance.py:2731} ERROR - Task failed with exception
Traceback (most recent call last):
  File "/home/airflow/.local/lib/python3.8/site-packages/airflow/models/taskinstance.py", line 444, in _execute_task
    result = _execute_callable(context=context, **execute_callable_kwargs)
  File "/home/airflow/.local/lib/python3.8/site-packages/airflow/models/taskinstance.py", line 414, in _execute_callable
    return execute_callable(context=context, **execute_callable_kwargs)
  File "/home/airflow/.local/lib/python3.8/site-packages/airflow/operators/python.py", line 200, in execute
    return_value = self.execute_callable()
  File "/home/airflow/.local/lib/python3.8/site-packages/airflow/operators/python.py", line 217, in execute_callable
    return self.python_callable(*self.op_args, **self.op_kwargs)
  File "/opt/airflow/dags/dag.py", line 45, in process_table
    return  execute(table, stage, tabletype)
  File "/app/main.py", line 31, in execute
    (StagingToDV().create_full().some_function(table, stage))
  File "/app/concretestage/StagingToDV.py", line 36, in some_function
    sourceDF = getDF(sourcedbname,sourcetablename , sourceschema)
  File "/app/myFramework/utils/utils.py", line 27, in getDF
    cur.execute(query)
psycopg2.errors.FeatureNotSupported: cross-database references are not implemented: "dbstaging.dvdrental.actor"
LINE 1: select T.* from DBStaging.dvdrental.actor T
                        ^

[2024-07-16T17:45:36.878+0000] {taskinstance.py:1149} INFO - Marking task as FAILED. dag_id=stagingtodv, task_id=actor, execution_date=20240715T000000, start_date=20240716T174534, end_date=20240716T174536
[2024-07-16T17:45:36.900+0000] {standard_task_runner.py:107} ERROR - Failed to execute job 7 for task actor (cross-database references are not implemented: "dbstaging.dvdrental.actor"
LINE 1: select T.* from DBStaging.dvdrental.actor T
                        ^
; 89)
[2024-07-16T17:45:36.940+0000] {local_task_job_runner.py:234} INFO - Task exited with return code 1
[2024-07-16T17:45:37.014+0000] {taskinstance.py:3312} INFO - 0 downstream tasks scheduled from follow-on schedule check
[2024-07-16T17:58:24.694+0000] {taskinstance.py:1979} INFO - Dependencies all met for dep_context=non-requeueable deps ti=<TaskInstance: stagingtodv.actor scheduled__2024-07-15T00:00:00+00:00 [queued]>
[2024-07-16T17:58:24.741+0000] {taskinstance.py:1979} INFO - Dependencies all met for dep_context=requeueable deps ti=<TaskInstance: stagingtodv.actor scheduled__2024-07-15T00:00:00+00:00 [queued]>
[2024-07-16T17:58:24.748+0000] {taskinstance.py:2193} INFO - Starting attempt 1 of 1
[2024-07-16T17:58:24.794+0000] {taskinstance.py:2217} INFO - Executing <Task(PythonOperator): actor> on 2024-07-15 00:00:00+00:00
[2024-07-16T17:58:24.847+0000] {standard_task_runner.py:60} INFO - Started process 91 to run task
[2024-07-16T17:58:24.857+0000] {standard_task_runner.py:87} INFO - Running: ['***', 'tasks', 'run', 'stagingtodv', 'actor', 'scheduled__2024-07-15T00:00:00+00:00', '--job-id', '11', '--raw', '--subdir', 'DAGS_FOLDER/dag.py', '--cfg-path', '/tmp/tmpkkrgoiyf']
[2024-07-16T17:58:24.870+0000] {standard_task_runner.py:88} INFO - Job 11: Subtask actor
[2024-07-16T17:58:25.095+0000] {task_command.py:423} INFO - Running <TaskInstance: stagingtodv.actor scheduled__2024-07-15T00:00:00+00:00 [running]> on host 9d71ede51657
[2024-07-16T17:58:26.406+0000] {taskinstance.py:2513} INFO - Exporting env vars: AIRFLOW_CTX_DAG_OWNER='***' AIRFLOW_CTX_DAG_ID='stagingtodv' AIRFLOW_CTX_TASK_ID='actor' AIRFLOW_CTX_EXECUTION_DATE='2024-07-15T00:00:00+00:00' AIRFLOW_CTX_TRY_NUMBER='1' AIRFLOW_CTX_DAG_RUN_ID='scheduled__2024-07-15T00:00:00+00:00'
[2024-07-16T17:58:26.410+0000] {logging_mixin.py:188} INFO - -------------------------------------------- select *  from etlconf.Etl_Process_Mapping where SourceTableName = 'actor' and Stage = 'stagingtodv'
[2024-07-16T17:58:26.451+0000] {logging_mixin.py:188} INFO - select *  from etlconf.Etl_Process_Mapping where SourceTableName = 'actor' and Stage = 'stagingtodv'
[2024-07-16T17:58:26.501+0000] {taskinstance.py:2731} ERROR - Task failed with exception
Traceback (most recent call last):
  File "/home/airflow/.local/lib/python3.8/site-packages/airflow/models/taskinstance.py", line 444, in _execute_task
    result = _execute_callable(context=context, **execute_callable_kwargs)
  File "/home/airflow/.local/lib/python3.8/site-packages/airflow/models/taskinstance.py", line 414, in _execute_callable
    return execute_callable(context=context, **execute_callable_kwargs)
  File "/home/airflow/.local/lib/python3.8/site-packages/airflow/operators/python.py", line 200, in execute
    return_value = self.execute_callable()
  File "/home/airflow/.local/lib/python3.8/site-packages/airflow/operators/python.py", line 217, in execute_callable
    return self.python_callable(*self.op_args, **self.op_kwargs)
  File "/opt/airflow/dags/dag.py", line 45, in process_table
    return  execute(table, stage, tabletype)
  File "/app/main.py", line 31, in execute
    (StagingToDV().create_full().some_function(table, stage))
  File "/app/concretestage/StagingToDV.py", line 36, in some_function
    sourceDF = getDF(sourcedbname,sourcetablename , sourceschema)
  File "/app/myFramework/utils/utils.py", line 27, in getDF
    cur.execute(query)
psycopg2.errors.FeatureNotSupported: cross-database references are not implemented: "dbstaging.dvdrental.actor"
LINE 1: select T.* from DBStaging.dvdrental.actor T
                        ^

[2024-07-16T17:58:26.513+0000] {taskinstance.py:1149} INFO - Marking task as FAILED. dag_id=stagingtodv, task_id=actor, execution_date=20240715T000000, start_date=20240716T175824, end_date=20240716T175826
[2024-07-16T17:58:26.528+0000] {standard_task_runner.py:107} ERROR - Failed to execute job 11 for task actor (cross-database references are not implemented: "dbstaging.dvdrental.actor"
LINE 1: select T.* from DBStaging.dvdrental.actor T
                        ^
; 91)
[2024-07-16T17:58:26.577+0000] {local_task_job_runner.py:234} INFO - Task exited with return code 1
[2024-07-16T17:58:26.600+0000] {taskinstance.py:3312} INFO - 0 downstream tasks scheduled from follow-on schedule check
[2024-07-16T18:12:19.521+0000] {taskinstance.py:1979} INFO - Dependencies all met for dep_context=non-requeueable deps ti=<TaskInstance: stagingtodv.actor scheduled__2024-07-15T00:00:00+00:00 [queued]>
[2024-07-16T18:12:19.546+0000] {taskinstance.py:1979} INFO - Dependencies all met for dep_context=requeueable deps ti=<TaskInstance: stagingtodv.actor scheduled__2024-07-15T00:00:00+00:00 [queued]>
[2024-07-16T18:12:19.549+0000] {taskinstance.py:2193} INFO - Starting attempt 1 of 1
[2024-07-16T18:12:19.603+0000] {taskinstance.py:2217} INFO - Executing <Task(PythonOperator): actor> on 2024-07-15 00:00:00+00:00
[2024-07-16T18:12:19.611+0000] {standard_task_runner.py:60} INFO - Started process 118 to run task
[2024-07-16T18:12:19.627+0000] {standard_task_runner.py:87} INFO - Running: ['***', 'tasks', 'run', 'stagingtodv', 'actor', 'scheduled__2024-07-15T00:00:00+00:00', '--job-id', '17', '--raw', '--subdir', 'DAGS_FOLDER/dag.py', '--cfg-path', '/tmp/tmp4aew8881']
[2024-07-16T18:12:19.648+0000] {standard_task_runner.py:88} INFO - Job 17: Subtask actor
[2024-07-16T18:12:19.789+0000] {task_command.py:423} INFO - Running <TaskInstance: stagingtodv.actor scheduled__2024-07-15T00:00:00+00:00 [running]> on host 9f18461f6153
[2024-07-16T18:12:21.068+0000] {taskinstance.py:2513} INFO - Exporting env vars: AIRFLOW_CTX_DAG_OWNER='***' AIRFLOW_CTX_DAG_ID='stagingtodv' AIRFLOW_CTX_TASK_ID='actor' AIRFLOW_CTX_EXECUTION_DATE='2024-07-15T00:00:00+00:00' AIRFLOW_CTX_TRY_NUMBER='1' AIRFLOW_CTX_DAG_RUN_ID='scheduled__2024-07-15T00:00:00+00:00'
[2024-07-16T18:12:21.077+0000] {logging_mixin.py:188} INFO - -------------------------------------------- select *  from etlconf.Etl_Process_Mapping where SourceTableName = 'actor' and Stage = 'stagingtodv'
[2024-07-16T18:12:21.191+0000] {logging_mixin.py:188} INFO - select *  from etlconf.Etl_Process_Mapping where SourceTableName = 'actor' and Stage = 'stagingtodv'
[2024-07-16T18:12:21.324+0000] {taskinstance.py:2731} ERROR - Task failed with exception
Traceback (most recent call last):
  File "/home/airflow/.local/lib/python3.8/site-packages/airflow/models/taskinstance.py", line 444, in _execute_task
    result = _execute_callable(context=context, **execute_callable_kwargs)
  File "/home/airflow/.local/lib/python3.8/site-packages/airflow/models/taskinstance.py", line 414, in _execute_callable
    return execute_callable(context=context, **execute_callable_kwargs)
  File "/home/airflow/.local/lib/python3.8/site-packages/airflow/operators/python.py", line 200, in execute
    return_value = self.execute_callable()
  File "/home/airflow/.local/lib/python3.8/site-packages/airflow/operators/python.py", line 217, in execute_callable
    return self.python_callable(*self.op_args, **self.op_kwargs)
  File "/opt/airflow/dags/dag.py", line 45, in process_table
    return  execute(table, stage, tabletype)
  File "/app/main.py", line 31, in execute
    (StagingToDV().create_full().some_function(table, stage))
  File "/app/concretestage/StagingToDV.py", line 36, in some_function
    sourceDF = getDF(sourcedbname,sourcetablename , sourceschema)
  File "/app/myFramework/utils/utils.py", line 26, in getDF
    cur = conn.getCursor(source_dbname)
  File "/app/myFramework/source/posgresql/connect.py", line 9, in getCursor
    conn = psycopg2.connect(database = dbname,
  File "/home/airflow/.local/lib/python3.8/site-packages/psycopg2/__init__.py", line 122, in connect
    conn = _connect(dsn, connection_factory=connection_factory, **kwasync)
psycopg2.OperationalError: connection to server at "postgres_db" (172.28.0.5), port 9999 failed: FATAL:  database "dbstaging" does not exist

[2024-07-16T18:12:21.357+0000] {taskinstance.py:1149} INFO - Marking task as FAILED. dag_id=stagingtodv, task_id=actor, execution_date=20240715T000000, start_date=20240716T181219, end_date=20240716T181221
[2024-07-16T18:12:21.389+0000] {standard_task_runner.py:107} ERROR - Failed to execute job 17 for task actor (connection to server at "postgres_db" (172.28.0.5), port 9999 failed: FATAL:  database "dbstaging" does not exist
; 118)
[2024-07-16T18:12:21.452+0000] {local_task_job_runner.py:234} INFO - Task exited with return code 1
[2024-07-16T18:12:21.535+0000] {taskinstance.py:3312} INFO - 0 downstream tasks scheduled from follow-on schedule check
[2024-07-16T18:29:52.011+0000] {taskinstance.py:1979} INFO - Dependencies all met for dep_context=non-requeueable deps ti=<TaskInstance: stagingtodv.actor scheduled__2024-07-15T00:00:00+00:00 [queued]>
[2024-07-16T18:29:52.096+0000] {taskinstance.py:1979} INFO - Dependencies all met for dep_context=requeueable deps ti=<TaskInstance: stagingtodv.actor scheduled__2024-07-15T00:00:00+00:00 [queued]>
[2024-07-16T18:29:52.115+0000] {taskinstance.py:2193} INFO - Starting attempt 1 of 1
[2024-07-16T18:29:52.314+0000] {taskinstance.py:2217} INFO - Executing <Task(PythonOperator): actor> on 2024-07-15 00:00:00+00:00
[2024-07-16T18:29:52.334+0000] {standard_task_runner.py:60} INFO - Started process 100 to run task
[2024-07-16T18:29:52.409+0000] {standard_task_runner.py:87} INFO - Running: ['***', 'tasks', 'run', 'stagingtodv', 'actor', 'scheduled__2024-07-15T00:00:00+00:00', '--job-id', '17', '--raw', '--subdir', 'DAGS_FOLDER/dag.py', '--cfg-path', '/tmp/tmpctoa76ti']
[2024-07-16T18:29:52.435+0000] {standard_task_runner.py:88} INFO - Job 17: Subtask actor
[2024-07-16T18:29:52.948+0000] {task_command.py:423} INFO - Running <TaskInstance: stagingtodv.actor scheduled__2024-07-15T00:00:00+00:00 [running]> on host 6c99a2e38d27
[2024-07-16T18:29:56.183+0000] {taskinstance.py:2513} INFO - Exporting env vars: AIRFLOW_CTX_DAG_OWNER='***' AIRFLOW_CTX_DAG_ID='stagingtodv' AIRFLOW_CTX_TASK_ID='actor' AIRFLOW_CTX_EXECUTION_DATE='2024-07-15T00:00:00+00:00' AIRFLOW_CTX_TRY_NUMBER='1' AIRFLOW_CTX_DAG_RUN_ID='scheduled__2024-07-15T00:00:00+00:00'
[2024-07-16T18:29:56.211+0000] {logging_mixin.py:188} INFO - -------------------------------------------- select *  from etlconf.Etl_Process_Mapping where SourceTableName = 'actor' and Stage = 'stagingtodv'
[2024-07-16T18:29:56.472+0000] {logging_mixin.py:188} INFO - select *  from etlconf.Etl_Process_Mapping where SourceTableName = 'actor' and Stage = 'stagingtodv'
[2024-07-16T18:29:56.834+0000] {taskinstance.py:2731} ERROR - Task failed with exception
Traceback (most recent call last):
  File "/home/airflow/.local/lib/python3.8/site-packages/airflow/models/taskinstance.py", line 444, in _execute_task
    result = _execute_callable(context=context, **execute_callable_kwargs)
  File "/home/airflow/.local/lib/python3.8/site-packages/airflow/models/taskinstance.py", line 414, in _execute_callable
    return execute_callable(context=context, **execute_callable_kwargs)
  File "/home/airflow/.local/lib/python3.8/site-packages/airflow/operators/python.py", line 200, in execute
    return_value = self.execute_callable()
  File "/home/airflow/.local/lib/python3.8/site-packages/airflow/operators/python.py", line 217, in execute_callable
    return self.python_callable(*self.op_args, **self.op_kwargs)
  File "/opt/airflow/dags/dag.py", line 45, in process_table
    return  execute(table, stage, tabletype)
  File "/app/main.py", line 31, in execute
    (StagingToDV().create_full().some_function(table, stage))
  File "/app/concretestage/StagingToDV.py", line 36, in some_function
    sourceDF = getDF(sourcedbname,sourcetablename , sourceschema)
  File "/app/myFramework/utils/utils.py", line 29, in getDF
    cur.execute(query)
psycopg2.errors.UndefinedTable: missing FROM-clause entry for table "t"
LINE 1: select T.* from dbstaging.public.dada
               ^

[2024-07-16T18:29:56.950+0000] {taskinstance.py:1149} INFO - Marking task as FAILED. dag_id=stagingtodv, task_id=actor, execution_date=20240715T000000, start_date=20240716T182952, end_date=20240716T182956
[2024-07-16T18:29:57.354+0000] {standard_task_runner.py:107} ERROR - Failed to execute job 17 for task actor (missing FROM-clause entry for table "t"
LINE 1: select T.* from dbstaging.public.dada
               ^
; 100)
[2024-07-16T18:29:57.960+0000] {local_task_job_runner.py:234} INFO - Task exited with return code 1
[2024-07-16T18:29:58.163+0000] {taskinstance.py:3312} INFO - 0 downstream tasks scheduled from follow-on schedule check
[2024-07-16T18:33:54.474+0000] {taskinstance.py:1979} INFO - Dependencies all met for dep_context=non-requeueable deps ti=<TaskInstance: stagingtodv.actor scheduled__2024-07-15T00:00:00+00:00 [queued]>
[2024-07-16T18:33:54.490+0000] {taskinstance.py:1979} INFO - Dependencies all met for dep_context=requeueable deps ti=<TaskInstance: stagingtodv.actor scheduled__2024-07-15T00:00:00+00:00 [queued]>
[2024-07-16T18:33:54.496+0000] {taskinstance.py:2193} INFO - Starting attempt 1 of 1
[2024-07-16T18:33:54.557+0000] {taskinstance.py:2217} INFO - Executing <Task(PythonOperator): actor> on 2024-07-15 00:00:00+00:00
[2024-07-16T18:33:54.584+0000] {standard_task_runner.py:60} INFO - Started process 114 to run task
[2024-07-16T18:33:54.591+0000] {standard_task_runner.py:87} INFO - Running: ['***', 'tasks', 'run', 'stagingtodv', 'actor', 'scheduled__2024-07-15T00:00:00+00:00', '--job-id', '14', '--raw', '--subdir', 'DAGS_FOLDER/dag.py', '--cfg-path', '/tmp/tmplyhzhrx5']
[2024-07-16T18:33:54.600+0000] {standard_task_runner.py:88} INFO - Job 14: Subtask actor
[2024-07-16T18:33:54.852+0000] {task_command.py:423} INFO - Running <TaskInstance: stagingtodv.actor scheduled__2024-07-15T00:00:00+00:00 [running]> on host b7021158e377
[2024-07-16T18:33:56.464+0000] {taskinstance.py:2513} INFO - Exporting env vars: AIRFLOW_CTX_DAG_OWNER='***' AIRFLOW_CTX_DAG_ID='stagingtodv' AIRFLOW_CTX_TASK_ID='actor' AIRFLOW_CTX_EXECUTION_DATE='2024-07-15T00:00:00+00:00' AIRFLOW_CTX_TRY_NUMBER='1' AIRFLOW_CTX_DAG_RUN_ID='scheduled__2024-07-15T00:00:00+00:00'
[2024-07-16T18:33:56.468+0000] {logging_mixin.py:188} INFO - -------------------------------------------- select *  from etlconf.Etl_Process_Mapping where SourceTableName = 'actor' and Stage = 'stagingtodv'
[2024-07-16T18:33:56.521+0000] {logging_mixin.py:188} INFO - select *  from etlconf.Etl_Process_Mapping where SourceTableName = 'actor' and Stage = 'stagingtodv'
[2024-07-16T18:33:56.627+0000] {taskinstance.py:2731} ERROR - Task failed with exception
Traceback (most recent call last):
  File "/home/airflow/.local/lib/python3.8/site-packages/airflow/models/taskinstance.py", line 444, in _execute_task
    result = _execute_callable(context=context, **execute_callable_kwargs)
  File "/home/airflow/.local/lib/python3.8/site-packages/airflow/models/taskinstance.py", line 414, in _execute_callable
    return execute_callable(context=context, **execute_callable_kwargs)
  File "/home/airflow/.local/lib/python3.8/site-packages/airflow/operators/python.py", line 200, in execute
    return_value = self.execute_callable()
  File "/home/airflow/.local/lib/python3.8/site-packages/airflow/operators/python.py", line 217, in execute_callable
    return self.python_callable(*self.op_args, **self.op_kwargs)
  File "/opt/airflow/dags/dag.py", line 45, in process_table
    return  execute(table, stage, tabletype)
  File "/app/main.py", line 31, in execute
    (StagingToDV().create_full().some_function(table, stage))
  File "/app/concretestage/StagingToDV.py", line 36, in some_function
    sourceDF = getDF(sourcedbname,sourcetablename , sourceschema)
  File "/app/myFramework/utils/utils.py", line 32, in getDF
    df.columns = [desc[0] for desc in cur.description]
  File "/home/airflow/.local/lib/python3.8/site-packages/pandas/core/generic.py", line 6002, in __setattr__
    return object.__setattr__(self, name, value)
  File "pandas/_libs/properties.pyx", line 69, in pandas._libs.properties.AxisProperty.__set__
  File "/home/airflow/.local/lib/python3.8/site-packages/pandas/core/generic.py", line 730, in _set_axis
    self._mgr.set_axis(axis, labels)
  File "/home/airflow/.local/lib/python3.8/site-packages/pandas/core/internals/managers.py", line 225, in set_axis
    self._validate_set_axis(axis, new_labels)
  File "/home/airflow/.local/lib/python3.8/site-packages/pandas/core/internals/base.py", line 70, in _validate_set_axis
    raise ValueError(
ValueError: Length mismatch: Expected axis has 0 elements, new values have 1 elements
[2024-07-16T18:33:56.653+0000] {taskinstance.py:1149} INFO - Marking task as FAILED. dag_id=stagingtodv, task_id=actor, execution_date=20240715T000000, start_date=20240716T183354, end_date=20240716T183356
[2024-07-16T18:33:56.667+0000] {standard_task_runner.py:107} ERROR - Failed to execute job 14 for task actor (Length mismatch: Expected axis has 0 elements, new values have 1 elements; 114)
[2024-07-16T18:33:56.701+0000] {local_task_job_runner.py:234} INFO - Task exited with return code 1
[2024-07-16T18:33:56.724+0000] {taskinstance.py:3312} INFO - 0 downstream tasks scheduled from follow-on schedule check
[2024-07-16T18:45:23.914+0000] {taskinstance.py:1979} INFO - Dependencies all met for dep_context=non-requeueable deps ti=<TaskInstance: stagingtodv.actor scheduled__2024-07-15T00:00:00+00:00 [queued]>
[2024-07-16T18:45:23.953+0000] {taskinstance.py:1979} INFO - Dependencies all met for dep_context=requeueable deps ti=<TaskInstance: stagingtodv.actor scheduled__2024-07-15T00:00:00+00:00 [queued]>
[2024-07-16T18:45:23.954+0000] {taskinstance.py:2193} INFO - Starting attempt 1 of 1
[2024-07-16T18:45:24.042+0000] {taskinstance.py:2217} INFO - Executing <Task(PythonOperator): actor> on 2024-07-15 00:00:00+00:00
[2024-07-16T18:45:24.083+0000] {standard_task_runner.py:60} INFO - Started process 142 to run task
[2024-07-16T18:45:24.101+0000] {standard_task_runner.py:87} INFO - Running: ['***', 'tasks', 'run', 'stagingtodv', 'actor', 'scheduled__2024-07-15T00:00:00+00:00', '--job-id', '23', '--raw', '--subdir', 'DAGS_FOLDER/dag.py', '--cfg-path', '/tmp/tmp4q42h9ib']
[2024-07-16T18:45:24.111+0000] {standard_task_runner.py:88} INFO - Job 23: Subtask actor
[2024-07-16T18:45:24.364+0000] {task_command.py:423} INFO - Running <TaskInstance: stagingtodv.actor scheduled__2024-07-15T00:00:00+00:00 [running]> on host 2e3dbb9eb862
[2024-07-16T18:45:24.756+0000] {taskinstance.py:2513} INFO - Exporting env vars: AIRFLOW_CTX_DAG_OWNER='***' AIRFLOW_CTX_DAG_ID='stagingtodv' AIRFLOW_CTX_TASK_ID='actor' AIRFLOW_CTX_EXECUTION_DATE='2024-07-15T00:00:00+00:00' AIRFLOW_CTX_TRY_NUMBER='1' AIRFLOW_CTX_DAG_RUN_ID='scheduled__2024-07-15T00:00:00+00:00'
[2024-07-16T18:45:24.769+0000] {logging_mixin.py:188} INFO - -------------------------------------------- select *  from etlconf.Etl_Process_Mapping where SourceTableName = 'actor' and Stage = 'stagingtodv'
[2024-07-16T18:45:24.888+0000] {logging_mixin.py:188} INFO - select *  from etlconf.Etl_Process_Mapping where SourceTableName = 'actor' and Stage = 'stagingtodv'
[2024-07-16T18:45:26.178+0000] {python.py:202} INFO - Done. Returned value was: None
[2024-07-16T18:45:26.192+0000] {taskinstance.py:1149} INFO - Marking task as SUCCESS. dag_id=stagingtodv, task_id=actor, execution_date=20240715T000000, start_date=20240716T184523, end_date=20240716T184526
[2024-07-16T18:45:26.271+0000] {local_task_job_runner.py:234} INFO - Task exited with return code 0
[2024-07-16T18:45:26.307+0000] {taskinstance.py:3312} INFO - 0 downstream tasks scheduled from follow-on schedule check
[2024-07-16T18:56:45.266+0000] {taskinstance.py:1979} INFO - Dependencies all met for dep_context=non-requeueable deps ti=<TaskInstance: stagingtodv.actor scheduled__2024-07-15T00:00:00+00:00 [queued]>
[2024-07-16T18:56:45.323+0000] {taskinstance.py:1979} INFO - Dependencies all met for dep_context=requeueable deps ti=<TaskInstance: stagingtodv.actor scheduled__2024-07-15T00:00:00+00:00 [queued]>
[2024-07-16T18:56:45.329+0000] {taskinstance.py:2193} INFO - Starting attempt 1 of 1
[2024-07-16T18:56:45.387+0000] {taskinstance.py:2217} INFO - Executing <Task(PythonOperator): actor> on 2024-07-15 00:00:00+00:00
[2024-07-16T18:56:45.410+0000] {standard_task_runner.py:60} INFO - Started process 145 to run task
[2024-07-16T18:56:45.416+0000] {standard_task_runner.py:87} INFO - Running: ['***', 'tasks', 'run', 'stagingtodv', 'actor', 'scheduled__2024-07-15T00:00:00+00:00', '--job-id', '20', '--raw', '--subdir', 'DAGS_FOLDER/dag.py', '--cfg-path', '/tmp/tmpa7fqk3hk']
[2024-07-16T18:56:45.424+0000] {standard_task_runner.py:88} INFO - Job 20: Subtask actor
[2024-07-16T18:56:45.565+0000] {task_command.py:423} INFO - Running <TaskInstance: stagingtodv.actor scheduled__2024-07-15T00:00:00+00:00 [running]> on host 1733eeb0def3
[2024-07-16T18:56:45.780+0000] {taskinstance.py:2513} INFO - Exporting env vars: AIRFLOW_CTX_DAG_OWNER='***' AIRFLOW_CTX_DAG_ID='stagingtodv' AIRFLOW_CTX_TASK_ID='actor' AIRFLOW_CTX_EXECUTION_DATE='2024-07-15T00:00:00+00:00' AIRFLOW_CTX_TRY_NUMBER='1' AIRFLOW_CTX_DAG_RUN_ID='scheduled__2024-07-15T00:00:00+00:00'
[2024-07-16T18:56:45.782+0000] {logging_mixin.py:188} INFO - -------------------------------------------- select *  from etlconf.Etl_Process_Mapping where SourceTableName = 'actor' and Stage = 'stagingtodv'
[2024-07-16T18:56:45.845+0000] {logging_mixin.py:188} INFO - select *  from etlconf.Etl_Process_Mapping where SourceTableName = 'actor' and Stage = 'stagingtodv'
[2024-07-16T18:56:46.717+0000] {taskinstance.py:2731} ERROR - Task failed with exception
Traceback (most recent call last):
  File "/home/airflow/.local/lib/python3.8/site-packages/sqlalchemy/engine/base.py", line 3371, in _wrap_pool_connect
    return fn()
  File "/home/airflow/.local/lib/python3.8/site-packages/sqlalchemy/pool/base.py", line 327, in connect
    return _ConnectionFairy._checkout(self)
  File "/home/airflow/.local/lib/python3.8/site-packages/sqlalchemy/pool/base.py", line 894, in _checkout
    fairy = _ConnectionRecord.checkout(pool)
  File "/home/airflow/.local/lib/python3.8/site-packages/sqlalchemy/pool/base.py", line 493, in checkout
    rec = pool._do_get()
  File "/home/airflow/.local/lib/python3.8/site-packages/sqlalchemy/pool/impl.py", line 146, in _do_get
    self._dec_overflow()
  File "/home/airflow/.local/lib/python3.8/site-packages/sqlalchemy/util/langhelpers.py", line 70, in __exit__
    compat.raise_(
  File "/home/airflow/.local/lib/python3.8/site-packages/sqlalchemy/util/compat.py", line 211, in raise_
    raise exception
  File "/home/airflow/.local/lib/python3.8/site-packages/sqlalchemy/pool/impl.py", line 143, in _do_get
    return self._create_connection()
  File "/home/airflow/.local/lib/python3.8/site-packages/sqlalchemy/pool/base.py", line 273, in _create_connection
    return _ConnectionRecord(self)
  File "/home/airflow/.local/lib/python3.8/site-packages/sqlalchemy/pool/base.py", line 388, in __init__
    self.__connect()
  File "/home/airflow/.local/lib/python3.8/site-packages/sqlalchemy/pool/base.py", line 691, in __connect
    pool.logger.debug("Error on connect(): %s", e)
  File "/home/airflow/.local/lib/python3.8/site-packages/sqlalchemy/util/langhelpers.py", line 70, in __exit__
    compat.raise_(
  File "/home/airflow/.local/lib/python3.8/site-packages/sqlalchemy/util/compat.py", line 211, in raise_
    raise exception
  File "/home/airflow/.local/lib/python3.8/site-packages/sqlalchemy/pool/base.py", line 686, in __connect
    self.dbapi_connection = connection = pool._invoke_creator(self)
  File "/home/airflow/.local/lib/python3.8/site-packages/sqlalchemy/engine/create.py", line 574, in connect
    return dialect.connect(*cargs, **cparams)
  File "/home/airflow/.local/lib/python3.8/site-packages/sqlalchemy/engine/default.py", line 598, in connect
    return self.dbapi.connect(*cargs, **cparams)
  File "/home/airflow/.local/lib/python3.8/site-packages/psycopg2/__init__.py", line 122, in connect
    conn = _connect(dsn, connection_factory=connection_factory, **kwasync)
psycopg2.OperationalError: connection to server at "postgres_db" (192.168.48.5), port 9999 failed: FATAL:  database "DBDV" does not exist


The above exception was the direct cause of the following exception:

Traceback (most recent call last):
  File "/home/airflow/.local/lib/python3.8/site-packages/airflow/models/taskinstance.py", line 444, in _execute_task
    result = _execute_callable(context=context, **execute_callable_kwargs)
  File "/home/airflow/.local/lib/python3.8/site-packages/airflow/models/taskinstance.py", line 414, in _execute_callable
    return execute_callable(context=context, **execute_callable_kwargs)
  File "/home/airflow/.local/lib/python3.8/site-packages/airflow/operators/python.py", line 200, in execute
    return_value = self.execute_callable()
  File "/home/airflow/.local/lib/python3.8/site-packages/airflow/operators/python.py", line 217, in execute_callable
    return self.python_callable(*self.op_args, **self.op_kwargs)
  File "/opt/airflow/dags/dag.py", line 45, in process_table
    return  execute(table, stage, tabletype)
  File "/app/main.py", line 31, in execute
    (StagingToDV().create_full().some_function(table, stage))
  File "/app/concretestage/StagingToDV.py", line 39, in some_function
    fillPosgres(sourceDF, DestDBName, DestSchema, DestTableName, InsertionType)
  File "/app/myFramework/utils/utils.py", line 36, in fillPosgres
    df.to_sql(tablename, conn.getEngine(dst_dbname)
  File "/home/airflow/.local/lib/python3.8/site-packages/pandas/core/generic.py", line 2878, in to_sql
    return sql.to_sql(
  File "/home/airflow/.local/lib/python3.8/site-packages/pandas/io/sql.py", line 768, in to_sql
    with pandasSQL_builder(con, schema=schema, need_transaction=True) as pandas_sql:
  File "/home/airflow/.local/lib/python3.8/site-packages/pandas/io/sql.py", line 832, in pandasSQL_builder
    return SQLDatabase(con, schema, need_transaction)
  File "/home/airflow/.local/lib/python3.8/site-packages/pandas/io/sql.py", line 1539, in __init__
    con = self.exit_stack.enter_context(con.connect())
  File "/home/airflow/.local/lib/python3.8/site-packages/sqlalchemy/engine/base.py", line 3325, in connect
    return self._connection_cls(self, close_with_result=close_with_result)
  File "/home/airflow/.local/lib/python3.8/site-packages/sqlalchemy/engine/base.py", line 96, in __init__
    else engine.raw_connection()
  File "/home/airflow/.local/lib/python3.8/site-packages/sqlalchemy/engine/base.py", line 3404, in raw_connection
    return self._wrap_pool_connect(self.pool.connect, _connection)
  File "/home/airflow/.local/lib/python3.8/site-packages/sqlalchemy/engine/base.py", line 3374, in _wrap_pool_connect
    Connection._handle_dbapi_exception_noconnection(
  File "/home/airflow/.local/lib/python3.8/site-packages/sqlalchemy/engine/base.py", line 2208, in _handle_dbapi_exception_noconnection
    util.raise_(
  File "/home/airflow/.local/lib/python3.8/site-packages/sqlalchemy/util/compat.py", line 211, in raise_
    raise exception
  File "/home/airflow/.local/lib/python3.8/site-packages/sqlalchemy/engine/base.py", line 3371, in _wrap_pool_connect
    return fn()
  File "/home/airflow/.local/lib/python3.8/site-packages/sqlalchemy/pool/base.py", line 327, in connect
    return _ConnectionFairy._checkout(self)
  File "/home/airflow/.local/lib/python3.8/site-packages/sqlalchemy/pool/base.py", line 894, in _checkout
    fairy = _ConnectionRecord.checkout(pool)
  File "/home/airflow/.local/lib/python3.8/site-packages/sqlalchemy/pool/base.py", line 493, in checkout
    rec = pool._do_get()
  File "/home/airflow/.local/lib/python3.8/site-packages/sqlalchemy/pool/impl.py", line 146, in _do_get
    self._dec_overflow()
  File "/home/airflow/.local/lib/python3.8/site-packages/sqlalchemy/util/langhelpers.py", line 70, in __exit__
    compat.raise_(
  File "/home/airflow/.local/lib/python3.8/site-packages/sqlalchemy/util/compat.py", line 211, in raise_
    raise exception
  File "/home/airflow/.local/lib/python3.8/site-packages/sqlalchemy/pool/impl.py", line 143, in _do_get
    return self._create_connection()
  File "/home/airflow/.local/lib/python3.8/site-packages/sqlalchemy/pool/base.py", line 273, in _create_connection
    return _ConnectionRecord(self)
  File "/home/airflow/.local/lib/python3.8/site-packages/sqlalchemy/pool/base.py", line 388, in __init__
    self.__connect()
  File "/home/airflow/.local/lib/python3.8/site-packages/sqlalchemy/pool/base.py", line 691, in __connect
    pool.logger.debug("Error on connect(): %s", e)
  File "/home/airflow/.local/lib/python3.8/site-packages/sqlalchemy/util/langhelpers.py", line 70, in __exit__
    compat.raise_(
  File "/home/airflow/.local/lib/python3.8/site-packages/sqlalchemy/util/compat.py", line 211, in raise_
    raise exception
  File "/home/airflow/.local/lib/python3.8/site-packages/sqlalchemy/pool/base.py", line 686, in __connect
    self.dbapi_connection = connection = pool._invoke_creator(self)
  File "/home/airflow/.local/lib/python3.8/site-packages/sqlalchemy/engine/create.py", line 574, in connect
    return dialect.connect(*cargs, **cparams)
  File "/home/airflow/.local/lib/python3.8/site-packages/sqlalchemy/engine/default.py", line 598, in connect
    return self.dbapi.connect(*cargs, **cparams)
  File "/home/airflow/.local/lib/python3.8/site-packages/psycopg2/__init__.py", line 122, in connect
    conn = _connect(dsn, connection_factory=connection_factory, **kwasync)
sqlalchemy.exc.OperationalError: (psycopg2.OperationalError) connection to server at "postgres_db" (192.168.48.5), port 9999 failed: FATAL:  database "DBDV" does not exist

(Background on this error at: https://sqlalche.me/e/14/e3q8)
[2024-07-16T18:56:46.785+0000] {taskinstance.py:1149} INFO - Marking task as FAILED. dag_id=stagingtodv, task_id=actor, execution_date=20240715T000000, start_date=20240716T185645, end_date=20240716T185646
[2024-07-16T18:56:46.827+0000] {standard_task_runner.py:107} ERROR - Failed to execute job 20 for task actor ((psycopg2.OperationalError) connection to server at "postgres_db" (192.168.48.5), port 9999 failed: FATAL:  database "DBDV" does not exist

(Background on this error at: https://sqlalche.me/e/14/e3q8); 145)
[2024-07-16T18:56:46.889+0000] {local_task_job_runner.py:234} INFO - Task exited with return code 1
[2024-07-16T18:56:46.930+0000] {taskinstance.py:3312} INFO - 0 downstream tasks scheduled from follow-on schedule check
[2024-07-16T19:01:11.866+0000] {taskinstance.py:1979} INFO - Dependencies all met for dep_context=non-requeueable deps ti=<TaskInstance: stagingtodv.actor scheduled__2024-07-15T00:00:00+00:00 [queued]>
[2024-07-16T19:01:11.891+0000] {taskinstance.py:1979} INFO - Dependencies all met for dep_context=requeueable deps ti=<TaskInstance: stagingtodv.actor scheduled__2024-07-15T00:00:00+00:00 [queued]>
[2024-07-16T19:01:11.894+0000] {taskinstance.py:2193} INFO - Starting attempt 1 of 1
[2024-07-16T19:01:11.948+0000] {taskinstance.py:2217} INFO - Executing <Task(PythonOperator): actor> on 2024-07-15 00:00:00+00:00
[2024-07-16T19:01:11.963+0000] {standard_task_runner.py:60} INFO - Started process 84 to run task
[2024-07-16T19:01:11.992+0000] {standard_task_runner.py:87} INFO - Running: ['***', 'tasks', 'run', 'stagingtodv', 'actor', 'scheduled__2024-07-15T00:00:00+00:00', '--job-id', '4', '--raw', '--subdir', 'DAGS_FOLDER/dag.py', '--cfg-path', '/tmp/tmptjbvfux_']
[2024-07-16T19:01:12.030+0000] {standard_task_runner.py:88} INFO - Job 4: Subtask actor
[2024-07-16T19:01:12.245+0000] {task_command.py:423} INFO - Running <TaskInstance: stagingtodv.actor scheduled__2024-07-15T00:00:00+00:00 [running]> on host ef8b8dee6045
[2024-07-16T19:01:13.164+0000] {taskinstance.py:2513} INFO - Exporting env vars: AIRFLOW_CTX_DAG_OWNER='***' AIRFLOW_CTX_DAG_ID='stagingtodv' AIRFLOW_CTX_TASK_ID='actor' AIRFLOW_CTX_EXECUTION_DATE='2024-07-15T00:00:00+00:00' AIRFLOW_CTX_TRY_NUMBER='1' AIRFLOW_CTX_DAG_RUN_ID='scheduled__2024-07-15T00:00:00+00:00'
[2024-07-16T19:01:13.174+0000] {logging_mixin.py:188} INFO - -------------------------------------------- select *  from etlconf.Etl_Process_Mapping where SourceTableName = 'actor' and Stage = 'stagingtodv'
[2024-07-16T19:01:13.259+0000] {logging_mixin.py:188} INFO - select *  from etlconf.Etl_Process_Mapping where SourceTableName = 'actor' and Stage = 'stagingtodv'
[2024-07-16T19:01:13.765+0000] {logging_mixin.py:188} INFO - update etlconf.Etl_Process_Mapping T set last_run_date = current_timestamp where destdbname='dbdv' and destschema='dvdrental' and desttablename='actor';
[2024-07-16T19:01:13.811+0000] {python.py:202} INFO - Done. Returned value was: None
[2024-07-16T19:01:13.828+0000] {taskinstance.py:1149} INFO - Marking task as SUCCESS. dag_id=stagingtodv, task_id=actor, execution_date=20240715T000000, start_date=20240716T190111, end_date=20240716T190113
[2024-07-16T19:01:13.870+0000] {local_task_job_runner.py:234} INFO - Task exited with return code 0
[2024-07-16T19:01:13.888+0000] {taskinstance.py:3312} INFO - 0 downstream tasks scheduled from follow-on schedule check
