[2024-07-16T17:23:42.782+0000] {taskinstance.py:1979} INFO - Dependencies all met for dep_context=non-requeueable deps ti=<TaskInstance: stagingtodv.store scheduled__2024-07-15T00:00:00+00:00 [queued]>
[2024-07-16T17:23:42.807+0000] {taskinstance.py:1979} INFO - Dependencies all met for dep_context=requeueable deps ti=<TaskInstance: stagingtodv.store scheduled__2024-07-15T00:00:00+00:00 [queued]>
[2024-07-16T17:23:42.813+0000] {taskinstance.py:2193} INFO - Starting attempt 1 of 1
[2024-07-16T17:23:42.893+0000] {taskinstance.py:2217} INFO - Executing <Task(PythonOperator): store> on 2024-07-15 00:00:00+00:00
[2024-07-16T17:23:42.931+0000] {standard_task_runner.py:87} INFO - Running: ['***', 'tasks', 'run', 'stagingtodv', 'store', 'scheduled__2024-07-15T00:00:00+00:00', '--job-id', '43', '--raw', '--subdir', 'DAGS_FOLDER/dag.py', '--cfg-path', '/tmp/tmpvyqtiaw9']
[2024-07-16T17:23:42.954+0000] {standard_task_runner.py:88} INFO - Job 43: Subtask store
[2024-07-16T17:23:42.927+0000] {standard_task_runner.py:60} INFO - Started process 396 to run task
[2024-07-16T17:23:43.145+0000] {task_command.py:423} INFO - Running <TaskInstance: stagingtodv.store scheduled__2024-07-15T00:00:00+00:00 [running]> on host a8165c4616a2
[2024-07-16T17:23:43.556+0000] {taskinstance.py:2513} INFO - Exporting env vars: AIRFLOW_CTX_DAG_OWNER='***' AIRFLOW_CTX_DAG_ID='stagingtodv' AIRFLOW_CTX_TASK_ID='store' AIRFLOW_CTX_EXECUTION_DATE='2024-07-15T00:00:00+00:00' AIRFLOW_CTX_TRY_NUMBER='1' AIRFLOW_CTX_DAG_RUN_ID='scheduled__2024-07-15T00:00:00+00:00'
[2024-07-16T17:23:43.588+0000] {logging_mixin.py:188} INFO - -------------------------------------------- select *  from etlconf.Etl_Process_Mapping where SourceTableName = 'store' and Stage = 'stagingtodv'
[2024-07-16T17:23:44.973+0000] {taskinstance.py:2731} ERROR - Task failed with exception
Traceback (most recent call last):
  File "/home/airflow/.local/lib/python3.8/site-packages/airflow/models/taskinstance.py", line 444, in _execute_task
    result = _execute_callable(context=context, **execute_callable_kwargs)
  File "/home/airflow/.local/lib/python3.8/site-packages/airflow/models/taskinstance.py", line 414, in _execute_callable
    return execute_callable(context=context, **execute_callable_kwargs)
  File "/home/airflow/.local/lib/python3.8/site-packages/airflow/operators/python.py", line 200, in execute
    return_value = self.execute_callable()
  File "/home/airflow/.local/lib/python3.8/site-packages/airflow/operators/python.py", line 217, in execute_callable
    return self.python_callable(*self.op_args, **self.op_kwargs)
  File "/opt/airflow/dags/dag.py", line 41, in process_table
    tabletype = get_data_from_conf_table(table,stage)['tabletype'].values[0]
  File "/opt/airflow/dags/dag.py", line 34, in get_data_from_conf_table
    df.columns = [desc[0] for desc in cur.description]
  File "/home/airflow/.local/lib/python3.8/site-packages/pandas/core/generic.py", line 6002, in __setattr__
    return object.__setattr__(self, name, value)
  File "pandas/_libs/properties.pyx", line 69, in pandas._libs.properties.AxisProperty.__set__
  File "/home/airflow/.local/lib/python3.8/site-packages/pandas/core/generic.py", line 730, in _set_axis
    self._mgr.set_axis(axis, labels)
  File "/home/airflow/.local/lib/python3.8/site-packages/pandas/core/internals/managers.py", line 225, in set_axis
    self._validate_set_axis(axis, new_labels)
  File "/home/airflow/.local/lib/python3.8/site-packages/pandas/core/internals/base.py", line 70, in _validate_set_axis
    raise ValueError(
ValueError: Length mismatch: Expected axis has 0 elements, new values have 15 elements
[2024-07-16T17:23:44.992+0000] {taskinstance.py:1149} INFO - Marking task as FAILED. dag_id=stagingtodv, task_id=store, execution_date=20240715T000000, start_date=20240716T172342, end_date=20240716T172344
[2024-07-16T17:23:45.052+0000] {standard_task_runner.py:107} ERROR - Failed to execute job 43 for task store (Length mismatch: Expected axis has 0 elements, new values have 15 elements; 396)
[2024-07-16T17:23:45.089+0000] {local_task_job_runner.py:234} INFO - Task exited with return code 1
[2024-07-16T17:23:45.118+0000] {taskinstance.py:3312} INFO - 0 downstream tasks scheduled from follow-on schedule check
[2024-07-16T17:33:46.117+0000] {taskinstance.py:1979} INFO - Dependencies all met for dep_context=non-requeueable deps ti=<TaskInstance: stagingtodv.store scheduled__2024-07-15T00:00:00+00:00 [queued]>
[2024-07-16T17:33:46.156+0000] {taskinstance.py:1979} INFO - Dependencies all met for dep_context=requeueable deps ti=<TaskInstance: stagingtodv.store scheduled__2024-07-15T00:00:00+00:00 [queued]>
[2024-07-16T17:33:46.163+0000] {taskinstance.py:2193} INFO - Starting attempt 1 of 1
[2024-07-16T17:33:46.198+0000] {taskinstance.py:2217} INFO - Executing <Task(PythonOperator): store> on 2024-07-15 00:00:00+00:00
[2024-07-16T17:33:46.208+0000] {standard_task_runner.py:60} INFO - Started process 125 to run task
[2024-07-16T17:33:46.222+0000] {standard_task_runner.py:87} INFO - Running: ['***', 'tasks', 'run', 'stagingtodv', 'store', 'scheduled__2024-07-15T00:00:00+00:00', '--job-id', '17', '--raw', '--subdir', 'DAGS_FOLDER/dag.py', '--cfg-path', '/tmp/tmpl0bi2gx3']
[2024-07-16T17:33:46.236+0000] {standard_task_runner.py:88} INFO - Job 17: Subtask store
[2024-07-16T17:33:46.460+0000] {task_command.py:423} INFO - Running <TaskInstance: stagingtodv.store scheduled__2024-07-15T00:00:00+00:00 [running]> on host e9bb94dbac8b
[2024-07-16T17:33:47.988+0000] {taskinstance.py:2513} INFO - Exporting env vars: AIRFLOW_CTX_DAG_OWNER='***' AIRFLOW_CTX_DAG_ID='stagingtodv' AIRFLOW_CTX_TASK_ID='store' AIRFLOW_CTX_EXECUTION_DATE='2024-07-15T00:00:00+00:00' AIRFLOW_CTX_TRY_NUMBER='1' AIRFLOW_CTX_DAG_RUN_ID='scheduled__2024-07-15T00:00:00+00:00'
[2024-07-16T17:33:47.996+0000] {logging_mixin.py:188} INFO - -------------------------------------------- select *  from etlconf.Etl_Process_Mapping where SourceTableName = 'store' and Stage = 'stagingtodv'
[2024-07-16T17:33:48.046+0000] {taskinstance.py:2731} ERROR - Task failed with exception
Traceback (most recent call last):
  File "/home/airflow/.local/lib/python3.8/site-packages/airflow/models/taskinstance.py", line 444, in _execute_task
    result = _execute_callable(context=context, **execute_callable_kwargs)
  File "/home/airflow/.local/lib/python3.8/site-packages/airflow/models/taskinstance.py", line 414, in _execute_callable
    return execute_callable(context=context, **execute_callable_kwargs)
  File "/home/airflow/.local/lib/python3.8/site-packages/airflow/operators/python.py", line 200, in execute
    return_value = self.execute_callable()
  File "/home/airflow/.local/lib/python3.8/site-packages/airflow/operators/python.py", line 217, in execute_callable
    return self.python_callable(*self.op_args, **self.op_kwargs)
  File "/opt/airflow/dags/dag.py", line 41, in process_table
    tabletype = get_data_from_conf_table(table,stage)['tabletype'].values[0]
  File "/opt/airflow/dags/dag.py", line 34, in get_data_from_conf_table
    df.columns = [desc[0] for desc in cur.description]
  File "/home/airflow/.local/lib/python3.8/site-packages/pandas/core/generic.py", line 6002, in __setattr__
    return object.__setattr__(self, name, value)
  File "pandas/_libs/properties.pyx", line 69, in pandas._libs.properties.AxisProperty.__set__
  File "/home/airflow/.local/lib/python3.8/site-packages/pandas/core/generic.py", line 730, in _set_axis
    self._mgr.set_axis(axis, labels)
  File "/home/airflow/.local/lib/python3.8/site-packages/pandas/core/internals/managers.py", line 225, in set_axis
    self._validate_set_axis(axis, new_labels)
  File "/home/airflow/.local/lib/python3.8/site-packages/pandas/core/internals/base.py", line 70, in _validate_set_axis
    raise ValueError(
ValueError: Length mismatch: Expected axis has 0 elements, new values have 15 elements
[2024-07-16T17:33:48.057+0000] {taskinstance.py:1149} INFO - Marking task as FAILED. dag_id=stagingtodv, task_id=store, execution_date=20240715T000000, start_date=20240716T173346, end_date=20240716T173348
[2024-07-16T17:33:48.091+0000] {standard_task_runner.py:107} ERROR - Failed to execute job 17 for task store (Length mismatch: Expected axis has 0 elements, new values have 15 elements; 125)
[2024-07-16T17:33:48.128+0000] {local_task_job_runner.py:234} INFO - Task exited with return code 1
[2024-07-16T17:33:48.149+0000] {taskinstance.py:3312} INFO - 0 downstream tasks scheduled from follow-on schedule check
[2024-07-16T17:36:00.968+0000] {taskinstance.py:1979} INFO - Dependencies all met for dep_context=non-requeueable deps ti=<TaskInstance: stagingtodv.store scheduled__2024-07-15T00:00:00+00:00 [queued]>
[2024-07-16T17:36:00.988+0000] {taskinstance.py:1979} INFO - Dependencies all met for dep_context=requeueable deps ti=<TaskInstance: stagingtodv.store scheduled__2024-07-15T00:00:00+00:00 [queued]>
[2024-07-16T17:36:00.994+0000] {taskinstance.py:2193} INFO - Starting attempt 1 of 1
[2024-07-16T17:36:01.034+0000] {taskinstance.py:2217} INFO - Executing <Task(PythonOperator): store> on 2024-07-15 00:00:00+00:00
[2024-07-16T17:36:01.043+0000] {standard_task_runner.py:60} INFO - Started process 89 to run task
[2024-07-16T17:36:01.049+0000] {standard_task_runner.py:87} INFO - Running: ['***', 'tasks', 'run', 'stagingtodv', 'store', 'scheduled__2024-07-15T00:00:00+00:00', '--job-id', '3', '--raw', '--subdir', 'DAGS_FOLDER/dag.py', '--cfg-path', '/tmp/tmp1xgpxn_8']
[2024-07-16T17:36:01.067+0000] {standard_task_runner.py:88} INFO - Job 3: Subtask store
[2024-07-16T17:36:01.192+0000] {task_command.py:423} INFO - Running <TaskInstance: stagingtodv.store scheduled__2024-07-15T00:00:00+00:00 [running]> on host e1ba87a2fe19
[2024-07-16T17:36:02.624+0000] {taskinstance.py:2513} INFO - Exporting env vars: AIRFLOW_CTX_DAG_OWNER='***' AIRFLOW_CTX_DAG_ID='stagingtodv' AIRFLOW_CTX_TASK_ID='store' AIRFLOW_CTX_EXECUTION_DATE='2024-07-15T00:00:00+00:00' AIRFLOW_CTX_TRY_NUMBER='1' AIRFLOW_CTX_DAG_RUN_ID='scheduled__2024-07-15T00:00:00+00:00'
[2024-07-16T17:36:02.632+0000] {logging_mixin.py:188} INFO - -------------------------------------------- select *  from etlconf.Etl_Process_Mapping where SourceTableName = 'store' and Stage = 'stagingtodv'
[2024-07-16T17:36:02.672+0000] {taskinstance.py:2731} ERROR - Task failed with exception
Traceback (most recent call last):
  File "/home/airflow/.local/lib/python3.8/site-packages/airflow/models/taskinstance.py", line 444, in _execute_task
    result = _execute_callable(context=context, **execute_callable_kwargs)
  File "/home/airflow/.local/lib/python3.8/site-packages/airflow/models/taskinstance.py", line 414, in _execute_callable
    return execute_callable(context=context, **execute_callable_kwargs)
  File "/home/airflow/.local/lib/python3.8/site-packages/airflow/operators/python.py", line 200, in execute
    return_value = self.execute_callable()
  File "/home/airflow/.local/lib/python3.8/site-packages/airflow/operators/python.py", line 217, in execute_callable
    return self.python_callable(*self.op_args, **self.op_kwargs)
  File "/opt/airflow/dags/dag.py", line 41, in process_table
    tabletype = get_data_from_conf_table(table,stage)['tabletype'].values[0]
  File "/opt/airflow/dags/dag.py", line 34, in get_data_from_conf_table
    df.columns = [desc[0] for desc in cur.description]
  File "/home/airflow/.local/lib/python3.8/site-packages/pandas/core/generic.py", line 6002, in __setattr__
    return object.__setattr__(self, name, value)
  File "pandas/_libs/properties.pyx", line 69, in pandas._libs.properties.AxisProperty.__set__
  File "/home/airflow/.local/lib/python3.8/site-packages/pandas/core/generic.py", line 730, in _set_axis
    self._mgr.set_axis(axis, labels)
  File "/home/airflow/.local/lib/python3.8/site-packages/pandas/core/internals/managers.py", line 225, in set_axis
    self._validate_set_axis(axis, new_labels)
  File "/home/airflow/.local/lib/python3.8/site-packages/pandas/core/internals/base.py", line 70, in _validate_set_axis
    raise ValueError(
ValueError: Length mismatch: Expected axis has 0 elements, new values have 15 elements
[2024-07-16T17:36:02.692+0000] {taskinstance.py:1149} INFO - Marking task as FAILED. dag_id=stagingtodv, task_id=store, execution_date=20240715T000000, start_date=20240716T173600, end_date=20240716T173602
[2024-07-16T17:36:02.718+0000] {standard_task_runner.py:107} ERROR - Failed to execute job 3 for task store (Length mismatch: Expected axis has 0 elements, new values have 15 elements; 89)
[2024-07-16T17:36:02.775+0000] {local_task_job_runner.py:234} INFO - Task exited with return code 1
[2024-07-16T17:36:02.842+0000] {taskinstance.py:3312} INFO - 0 downstream tasks scheduled from follow-on schedule check
[2024-07-16T17:45:35.160+0000] {taskinstance.py:1979} INFO - Dependencies all met for dep_context=non-requeueable deps ti=<TaskInstance: stagingtodv.store scheduled__2024-07-15T00:00:00+00:00 [queued]>
[2024-07-16T17:45:35.191+0000] {taskinstance.py:1979} INFO - Dependencies all met for dep_context=requeueable deps ti=<TaskInstance: stagingtodv.store scheduled__2024-07-15T00:00:00+00:00 [queued]>
[2024-07-16T17:45:35.193+0000] {taskinstance.py:2193} INFO - Starting attempt 1 of 1
[2024-07-16T17:45:35.228+0000] {taskinstance.py:2217} INFO - Executing <Task(PythonOperator): store> on 2024-07-15 00:00:00+00:00
[2024-07-16T17:45:35.241+0000] {standard_task_runner.py:60} INFO - Started process 102 to run task
[2024-07-16T17:45:35.255+0000] {standard_task_runner.py:87} INFO - Running: ['***', 'tasks', 'run', 'stagingtodv', 'store', 'scheduled__2024-07-15T00:00:00+00:00', '--job-id', '17', '--raw', '--subdir', 'DAGS_FOLDER/dag.py', '--cfg-path', '/tmp/tmpsdj3k4d5']
[2024-07-16T17:45:35.271+0000] {standard_task_runner.py:88} INFO - Job 17: Subtask store
[2024-07-16T17:45:35.530+0000] {task_command.py:423} INFO - Running <TaskInstance: stagingtodv.store scheduled__2024-07-15T00:00:00+00:00 [running]> on host bba7487a60b5
[2024-07-16T17:45:36.626+0000] {taskinstance.py:2513} INFO - Exporting env vars: AIRFLOW_CTX_DAG_OWNER='***' AIRFLOW_CTX_DAG_ID='stagingtodv' AIRFLOW_CTX_TASK_ID='store' AIRFLOW_CTX_EXECUTION_DATE='2024-07-15T00:00:00+00:00' AIRFLOW_CTX_TRY_NUMBER='1' AIRFLOW_CTX_DAG_RUN_ID='scheduled__2024-07-15T00:00:00+00:00'
[2024-07-16T17:45:36.632+0000] {logging_mixin.py:188} INFO - -------------------------------------------- select *  from etlconf.Etl_Process_Mapping where SourceTableName = 'store' and Stage = 'stagingtodv'
[2024-07-16T17:45:36.696+0000] {taskinstance.py:2731} ERROR - Task failed with exception
Traceback (most recent call last):
  File "/home/airflow/.local/lib/python3.8/site-packages/airflow/models/taskinstance.py", line 444, in _execute_task
    result = _execute_callable(context=context, **execute_callable_kwargs)
  File "/home/airflow/.local/lib/python3.8/site-packages/airflow/models/taskinstance.py", line 414, in _execute_callable
    return execute_callable(context=context, **execute_callable_kwargs)
  File "/home/airflow/.local/lib/python3.8/site-packages/airflow/operators/python.py", line 200, in execute
    return_value = self.execute_callable()
  File "/home/airflow/.local/lib/python3.8/site-packages/airflow/operators/python.py", line 217, in execute_callable
    return self.python_callable(*self.op_args, **self.op_kwargs)
  File "/opt/airflow/dags/dag.py", line 41, in process_table
    tabletype = get_data_from_conf_table(table,stage)['tabletype'].values[0]
  File "/opt/airflow/dags/dag.py", line 34, in get_data_from_conf_table
    df.columns = [desc[0] for desc in cur.description]
  File "/home/airflow/.local/lib/python3.8/site-packages/pandas/core/generic.py", line 6002, in __setattr__
    return object.__setattr__(self, name, value)
  File "pandas/_libs/properties.pyx", line 69, in pandas._libs.properties.AxisProperty.__set__
  File "/home/airflow/.local/lib/python3.8/site-packages/pandas/core/generic.py", line 730, in _set_axis
    self._mgr.set_axis(axis, labels)
  File "/home/airflow/.local/lib/python3.8/site-packages/pandas/core/internals/managers.py", line 225, in set_axis
    self._validate_set_axis(axis, new_labels)
  File "/home/airflow/.local/lib/python3.8/site-packages/pandas/core/internals/base.py", line 70, in _validate_set_axis
    raise ValueError(
ValueError: Length mismatch: Expected axis has 0 elements, new values have 15 elements
[2024-07-16T17:45:36.724+0000] {taskinstance.py:1149} INFO - Marking task as FAILED. dag_id=stagingtodv, task_id=store, execution_date=20240715T000000, start_date=20240716T174535, end_date=20240716T174536
[2024-07-16T17:45:36.762+0000] {standard_task_runner.py:107} ERROR - Failed to execute job 17 for task store (Length mismatch: Expected axis has 0 elements, new values have 15 elements; 102)
[2024-07-16T17:45:36.816+0000] {local_task_job_runner.py:234} INFO - Task exited with return code 1
[2024-07-16T17:45:36.904+0000] {taskinstance.py:3312} INFO - 0 downstream tasks scheduled from follow-on schedule check
[2024-07-16T17:58:24.675+0000] {taskinstance.py:1979} INFO - Dependencies all met for dep_context=non-requeueable deps ti=<TaskInstance: stagingtodv.store scheduled__2024-07-15T00:00:00+00:00 [queued]>
[2024-07-16T17:58:24.734+0000] {taskinstance.py:1979} INFO - Dependencies all met for dep_context=requeueable deps ti=<TaskInstance: stagingtodv.store scheduled__2024-07-15T00:00:00+00:00 [queued]>
[2024-07-16T17:58:24.736+0000] {taskinstance.py:2193} INFO - Starting attempt 1 of 1
[2024-07-16T17:58:24.770+0000] {taskinstance.py:2217} INFO - Executing <Task(PythonOperator): store> on 2024-07-15 00:00:00+00:00
[2024-07-16T17:58:24.809+0000] {standard_task_runner.py:60} INFO - Started process 90 to run task
[2024-07-16T17:58:24.829+0000] {standard_task_runner.py:87} INFO - Running: ['***', 'tasks', 'run', 'stagingtodv', 'store', 'scheduled__2024-07-15T00:00:00+00:00', '--job-id', '12', '--raw', '--subdir', 'DAGS_FOLDER/dag.py', '--cfg-path', '/tmp/tmp0nx2ktko']
[2024-07-16T17:58:24.838+0000] {standard_task_runner.py:88} INFO - Job 12: Subtask store
[2024-07-16T17:58:25.007+0000] {task_command.py:423} INFO - Running <TaskInstance: stagingtodv.store scheduled__2024-07-15T00:00:00+00:00 [running]> on host 9d71ede51657
[2024-07-16T17:58:26.323+0000] {taskinstance.py:2513} INFO - Exporting env vars: AIRFLOW_CTX_DAG_OWNER='***' AIRFLOW_CTX_DAG_ID='stagingtodv' AIRFLOW_CTX_TASK_ID='store' AIRFLOW_CTX_EXECUTION_DATE='2024-07-15T00:00:00+00:00' AIRFLOW_CTX_TRY_NUMBER='1' AIRFLOW_CTX_DAG_RUN_ID='scheduled__2024-07-15T00:00:00+00:00'
[2024-07-16T17:58:26.326+0000] {logging_mixin.py:188} INFO - -------------------------------------------- select *  from etlconf.Etl_Process_Mapping where SourceTableName = 'store' and Stage = 'stagingtodv'
[2024-07-16T17:58:26.420+0000] {taskinstance.py:2731} ERROR - Task failed with exception
Traceback (most recent call last):
  File "/home/airflow/.local/lib/python3.8/site-packages/airflow/models/taskinstance.py", line 444, in _execute_task
    result = _execute_callable(context=context, **execute_callable_kwargs)
  File "/home/airflow/.local/lib/python3.8/site-packages/airflow/models/taskinstance.py", line 414, in _execute_callable
    return execute_callable(context=context, **execute_callable_kwargs)
  File "/home/airflow/.local/lib/python3.8/site-packages/airflow/operators/python.py", line 200, in execute
    return_value = self.execute_callable()
  File "/home/airflow/.local/lib/python3.8/site-packages/airflow/operators/python.py", line 217, in execute_callable
    return self.python_callable(*self.op_args, **self.op_kwargs)
  File "/opt/airflow/dags/dag.py", line 41, in process_table
    tabletype = get_data_from_conf_table(table,stage)['tabletype'].values[0]
  File "/opt/airflow/dags/dag.py", line 34, in get_data_from_conf_table
    df.columns = [desc[0] for desc in cur.description]
  File "/home/airflow/.local/lib/python3.8/site-packages/pandas/core/generic.py", line 6002, in __setattr__
    return object.__setattr__(self, name, value)
  File "pandas/_libs/properties.pyx", line 69, in pandas._libs.properties.AxisProperty.__set__
  File "/home/airflow/.local/lib/python3.8/site-packages/pandas/core/generic.py", line 730, in _set_axis
    self._mgr.set_axis(axis, labels)
  File "/home/airflow/.local/lib/python3.8/site-packages/pandas/core/internals/managers.py", line 225, in set_axis
    self._validate_set_axis(axis, new_labels)
  File "/home/airflow/.local/lib/python3.8/site-packages/pandas/core/internals/base.py", line 70, in _validate_set_axis
    raise ValueError(
ValueError: Length mismatch: Expected axis has 0 elements, new values have 15 elements
[2024-07-16T17:58:26.440+0000] {taskinstance.py:1149} INFO - Marking task as FAILED. dag_id=stagingtodv, task_id=store, execution_date=20240715T000000, start_date=20240716T175824, end_date=20240716T175826
[2024-07-16T17:58:26.461+0000] {standard_task_runner.py:107} ERROR - Failed to execute job 12 for task store (Length mismatch: Expected axis has 0 elements, new values have 15 elements; 90)
[2024-07-16T17:58:26.519+0000] {local_task_job_runner.py:234} INFO - Task exited with return code 1
[2024-07-16T17:58:26.539+0000] {taskinstance.py:3312} INFO - 0 downstream tasks scheduled from follow-on schedule check
[2024-07-16T18:12:19.518+0000] {taskinstance.py:1979} INFO - Dependencies all met for dep_context=non-requeueable deps ti=<TaskInstance: stagingtodv.store scheduled__2024-07-15T00:00:00+00:00 [queued]>
[2024-07-16T18:12:19.539+0000] {taskinstance.py:1979} INFO - Dependencies all met for dep_context=requeueable deps ti=<TaskInstance: stagingtodv.store scheduled__2024-07-15T00:00:00+00:00 [queued]>
[2024-07-16T18:12:19.542+0000] {taskinstance.py:2193} INFO - Starting attempt 1 of 1
[2024-07-16T18:12:19.609+0000] {taskinstance.py:2217} INFO - Executing <Task(PythonOperator): store> on 2024-07-15 00:00:00+00:00
[2024-07-16T18:12:19.625+0000] {standard_task_runner.py:60} INFO - Started process 119 to run task
[2024-07-16T18:12:19.655+0000] {standard_task_runner.py:87} INFO - Running: ['***', 'tasks', 'run', 'stagingtodv', 'store', 'scheduled__2024-07-15T00:00:00+00:00', '--job-id', '16', '--raw', '--subdir', 'DAGS_FOLDER/dag.py', '--cfg-path', '/tmp/tmp0tqlamiz']
[2024-07-16T18:12:19.668+0000] {standard_task_runner.py:88} INFO - Job 16: Subtask store
[2024-07-16T18:12:19.889+0000] {task_command.py:423} INFO - Running <TaskInstance: stagingtodv.store scheduled__2024-07-15T00:00:00+00:00 [running]> on host 9f18461f6153
[2024-07-16T18:12:21.406+0000] {taskinstance.py:2513} INFO - Exporting env vars: AIRFLOW_CTX_DAG_OWNER='***' AIRFLOW_CTX_DAG_ID='stagingtodv' AIRFLOW_CTX_TASK_ID='store' AIRFLOW_CTX_EXECUTION_DATE='2024-07-15T00:00:00+00:00' AIRFLOW_CTX_TRY_NUMBER='1' AIRFLOW_CTX_DAG_RUN_ID='scheduled__2024-07-15T00:00:00+00:00'
[2024-07-16T18:12:21.427+0000] {logging_mixin.py:188} INFO - -------------------------------------------- select *  from etlconf.Etl_Process_Mapping where SourceTableName = 'store' and Stage = 'stagingtodv'
[2024-07-16T18:12:21.480+0000] {taskinstance.py:2731} ERROR - Task failed with exception
Traceback (most recent call last):
  File "/home/airflow/.local/lib/python3.8/site-packages/airflow/models/taskinstance.py", line 444, in _execute_task
    result = _execute_callable(context=context, **execute_callable_kwargs)
  File "/home/airflow/.local/lib/python3.8/site-packages/airflow/models/taskinstance.py", line 414, in _execute_callable
    return execute_callable(context=context, **execute_callable_kwargs)
  File "/home/airflow/.local/lib/python3.8/site-packages/airflow/operators/python.py", line 200, in execute
    return_value = self.execute_callable()
  File "/home/airflow/.local/lib/python3.8/site-packages/airflow/operators/python.py", line 217, in execute_callable
    return self.python_callable(*self.op_args, **self.op_kwargs)
  File "/opt/airflow/dags/dag.py", line 41, in process_table
    tabletype = get_data_from_conf_table(table,stage)['tabletype'].values[0]
  File "/opt/airflow/dags/dag.py", line 34, in get_data_from_conf_table
    df.columns = [desc[0] for desc in cur.description]
  File "/home/airflow/.local/lib/python3.8/site-packages/pandas/core/generic.py", line 6002, in __setattr__
    return object.__setattr__(self, name, value)
  File "pandas/_libs/properties.pyx", line 69, in pandas._libs.properties.AxisProperty.__set__
  File "/home/airflow/.local/lib/python3.8/site-packages/pandas/core/generic.py", line 730, in _set_axis
    self._mgr.set_axis(axis, labels)
  File "/home/airflow/.local/lib/python3.8/site-packages/pandas/core/internals/managers.py", line 225, in set_axis
    self._validate_set_axis(axis, new_labels)
  File "/home/airflow/.local/lib/python3.8/site-packages/pandas/core/internals/base.py", line 70, in _validate_set_axis
    raise ValueError(
ValueError: Length mismatch: Expected axis has 0 elements, new values have 15 elements
[2024-07-16T18:12:21.505+0000] {taskinstance.py:1149} INFO - Marking task as FAILED. dag_id=stagingtodv, task_id=store, execution_date=20240715T000000, start_date=20240716T181219, end_date=20240716T181221
[2024-07-16T18:12:21.527+0000] {standard_task_runner.py:107} ERROR - Failed to execute job 16 for task store (Length mismatch: Expected axis has 0 elements, new values have 15 elements; 119)
[2024-07-16T18:12:21.569+0000] {local_task_job_runner.py:234} INFO - Task exited with return code 1
[2024-07-16T18:12:21.600+0000] {taskinstance.py:3312} INFO - 0 downstream tasks scheduled from follow-on schedule check
[2024-07-16T18:29:52.085+0000] {taskinstance.py:1979} INFO - Dependencies all met for dep_context=non-requeueable deps ti=<TaskInstance: stagingtodv.store scheduled__2024-07-15T00:00:00+00:00 [queued]>
[2024-07-16T18:29:52.139+0000] {taskinstance.py:1979} INFO - Dependencies all met for dep_context=requeueable deps ti=<TaskInstance: stagingtodv.store scheduled__2024-07-15T00:00:00+00:00 [queued]>
[2024-07-16T18:29:52.238+0000] {taskinstance.py:2193} INFO - Starting attempt 1 of 1
[2024-07-16T18:29:52.336+0000] {taskinstance.py:2217} INFO - Executing <Task(PythonOperator): store> on 2024-07-15 00:00:00+00:00
[2024-07-16T18:29:52.376+0000] {standard_task_runner.py:60} INFO - Started process 102 to run task
[2024-07-16T18:29:52.399+0000] {standard_task_runner.py:87} INFO - Running: ['***', 'tasks', 'run', 'stagingtodv', 'store', 'scheduled__2024-07-15T00:00:00+00:00', '--job-id', '15', '--raw', '--subdir', 'DAGS_FOLDER/dag.py', '--cfg-path', '/tmp/tmpx_44721w']
[2024-07-16T18:29:52.413+0000] {standard_task_runner.py:88} INFO - Job 15: Subtask store
[2024-07-16T18:29:52.732+0000] {task_command.py:423} INFO - Running <TaskInstance: stagingtodv.store scheduled__2024-07-15T00:00:00+00:00 [running]> on host 6c99a2e38d27
[2024-07-16T18:29:53.363+0000] {taskinstance.py:2513} INFO - Exporting env vars: AIRFLOW_CTX_DAG_OWNER='***' AIRFLOW_CTX_DAG_ID='stagingtodv' AIRFLOW_CTX_TASK_ID='store' AIRFLOW_CTX_EXECUTION_DATE='2024-07-15T00:00:00+00:00' AIRFLOW_CTX_TRY_NUMBER='1' AIRFLOW_CTX_DAG_RUN_ID='scheduled__2024-07-15T00:00:00+00:00'
[2024-07-16T18:29:53.394+0000] {logging_mixin.py:188} INFO - -------------------------------------------- select *  from etlconf.Etl_Process_Mapping where SourceTableName = 'store' and Stage = 'stagingtodv'
[2024-07-16T18:29:58.598+0000] {taskinstance.py:2731} ERROR - Task failed with exception
Traceback (most recent call last):
  File "/home/airflow/.local/lib/python3.8/site-packages/airflow/models/taskinstance.py", line 444, in _execute_task
    result = _execute_callable(context=context, **execute_callable_kwargs)
  File "/home/airflow/.local/lib/python3.8/site-packages/airflow/models/taskinstance.py", line 414, in _execute_callable
    return execute_callable(context=context, **execute_callable_kwargs)
  File "/home/airflow/.local/lib/python3.8/site-packages/airflow/operators/python.py", line 200, in execute
    return_value = self.execute_callable()
  File "/home/airflow/.local/lib/python3.8/site-packages/airflow/operators/python.py", line 217, in execute_callable
    return self.python_callable(*self.op_args, **self.op_kwargs)
  File "/opt/airflow/dags/dag.py", line 41, in process_table
    tabletype = get_data_from_conf_table(table,stage)['tabletype'].values[0]
  File "/opt/airflow/dags/dag.py", line 34, in get_data_from_conf_table
    df.columns = [desc[0] for desc in cur.description]
  File "/home/airflow/.local/lib/python3.8/site-packages/pandas/core/generic.py", line 6002, in __setattr__
    return object.__setattr__(self, name, value)
  File "pandas/_libs/properties.pyx", line 69, in pandas._libs.properties.AxisProperty.__set__
  File "/home/airflow/.local/lib/python3.8/site-packages/pandas/core/generic.py", line 730, in _set_axis
    self._mgr.set_axis(axis, labels)
  File "/home/airflow/.local/lib/python3.8/site-packages/pandas/core/internals/managers.py", line 225, in set_axis
    self._validate_set_axis(axis, new_labels)
  File "/home/airflow/.local/lib/python3.8/site-packages/pandas/core/internals/base.py", line 70, in _validate_set_axis
    raise ValueError(
ValueError: Length mismatch: Expected axis has 0 elements, new values have 15 elements
[2024-07-16T18:29:58.696+0000] {taskinstance.py:1149} INFO - Marking task as FAILED. dag_id=stagingtodv, task_id=store, execution_date=20240715T000000, start_date=20240716T182952, end_date=20240716T182958
[2024-07-16T18:29:58.889+0000] {standard_task_runner.py:107} ERROR - Failed to execute job 15 for task store (Length mismatch: Expected axis has 0 elements, new values have 15 elements; 102)
[2024-07-16T18:29:59.188+0000] {local_task_job_runner.py:234} INFO - Task exited with return code 1
[2024-07-16T18:29:59.699+0000] {taskinstance.py:3312} INFO - 0 downstream tasks scheduled from follow-on schedule check
[2024-07-16T18:33:54.496+0000] {taskinstance.py:1979} INFO - Dependencies all met for dep_context=non-requeueable deps ti=<TaskInstance: stagingtodv.store scheduled__2024-07-15T00:00:00+00:00 [queued]>
[2024-07-16T18:33:54.543+0000] {taskinstance.py:1979} INFO - Dependencies all met for dep_context=requeueable deps ti=<TaskInstance: stagingtodv.store scheduled__2024-07-15T00:00:00+00:00 [queued]>
[2024-07-16T18:33:54.555+0000] {taskinstance.py:2193} INFO - Starting attempt 1 of 1
[2024-07-16T18:33:54.597+0000] {taskinstance.py:2217} INFO - Executing <Task(PythonOperator): store> on 2024-07-15 00:00:00+00:00
[2024-07-16T18:33:54.645+0000] {standard_task_runner.py:60} INFO - Started process 117 to run task
[2024-07-16T18:33:54.674+0000] {standard_task_runner.py:87} INFO - Running: ['***', 'tasks', 'run', 'stagingtodv', 'store', 'scheduled__2024-07-15T00:00:00+00:00', '--job-id', '10', '--raw', '--subdir', 'DAGS_FOLDER/dag.py', '--cfg-path', '/tmp/tmphud3vn_k']
[2024-07-16T18:33:54.704+0000] {standard_task_runner.py:88} INFO - Job 10: Subtask store
[2024-07-16T18:33:54.924+0000] {task_command.py:423} INFO - Running <TaskInstance: stagingtodv.store scheduled__2024-07-15T00:00:00+00:00 [running]> on host b7021158e377
[2024-07-16T18:33:56.593+0000] {taskinstance.py:2513} INFO - Exporting env vars: AIRFLOW_CTX_DAG_OWNER='***' AIRFLOW_CTX_DAG_ID='stagingtodv' AIRFLOW_CTX_TASK_ID='store' AIRFLOW_CTX_EXECUTION_DATE='2024-07-15T00:00:00+00:00' AIRFLOW_CTX_TRY_NUMBER='1' AIRFLOW_CTX_DAG_RUN_ID='scheduled__2024-07-15T00:00:00+00:00'
[2024-07-16T18:33:56.596+0000] {logging_mixin.py:188} INFO - -------------------------------------------- select *  from etlconf.Etl_Process_Mapping where SourceTableName = 'store' and Stage = 'stagingtodv'
[2024-07-16T18:33:56.636+0000] {taskinstance.py:2731} ERROR - Task failed with exception
Traceback (most recent call last):
  File "/home/airflow/.local/lib/python3.8/site-packages/airflow/models/taskinstance.py", line 444, in _execute_task
    result = _execute_callable(context=context, **execute_callable_kwargs)
  File "/home/airflow/.local/lib/python3.8/site-packages/airflow/models/taskinstance.py", line 414, in _execute_callable
    return execute_callable(context=context, **execute_callable_kwargs)
  File "/home/airflow/.local/lib/python3.8/site-packages/airflow/operators/python.py", line 200, in execute
    return_value = self.execute_callable()
  File "/home/airflow/.local/lib/python3.8/site-packages/airflow/operators/python.py", line 217, in execute_callable
    return self.python_callable(*self.op_args, **self.op_kwargs)
  File "/opt/airflow/dags/dag.py", line 41, in process_table
    tabletype = get_data_from_conf_table(table,stage)['tabletype'].values[0]
  File "/opt/airflow/dags/dag.py", line 34, in get_data_from_conf_table
    df.columns = [desc[0] for desc in cur.description]
  File "/home/airflow/.local/lib/python3.8/site-packages/pandas/core/generic.py", line 6002, in __setattr__
    return object.__setattr__(self, name, value)
  File "pandas/_libs/properties.pyx", line 69, in pandas._libs.properties.AxisProperty.__set__
  File "/home/airflow/.local/lib/python3.8/site-packages/pandas/core/generic.py", line 730, in _set_axis
    self._mgr.set_axis(axis, labels)
  File "/home/airflow/.local/lib/python3.8/site-packages/pandas/core/internals/managers.py", line 225, in set_axis
    self._validate_set_axis(axis, new_labels)
  File "/home/airflow/.local/lib/python3.8/site-packages/pandas/core/internals/base.py", line 70, in _validate_set_axis
    raise ValueError(
ValueError: Length mismatch: Expected axis has 0 elements, new values have 15 elements
[2024-07-16T18:33:56.668+0000] {taskinstance.py:1149} INFO - Marking task as FAILED. dag_id=stagingtodv, task_id=store, execution_date=20240715T000000, start_date=20240716T183354, end_date=20240716T183356
[2024-07-16T18:33:56.704+0000] {standard_task_runner.py:107} ERROR - Failed to execute job 10 for task store (Length mismatch: Expected axis has 0 elements, new values have 15 elements; 117)
[2024-07-16T18:33:56.744+0000] {local_task_job_runner.py:234} INFO - Task exited with return code 1
[2024-07-16T18:33:56.795+0000] {taskinstance.py:3312} INFO - 0 downstream tasks scheduled from follow-on schedule check
[2024-07-16T18:45:23.881+0000] {taskinstance.py:1979} INFO - Dependencies all met for dep_context=non-requeueable deps ti=<TaskInstance: stagingtodv.store scheduled__2024-07-15T00:00:00+00:00 [queued]>
[2024-07-16T18:45:23.905+0000] {taskinstance.py:1979} INFO - Dependencies all met for dep_context=requeueable deps ti=<TaskInstance: stagingtodv.store scheduled__2024-07-15T00:00:00+00:00 [queued]>
[2024-07-16T18:45:23.906+0000] {taskinstance.py:2193} INFO - Starting attempt 1 of 1
[2024-07-16T18:45:23.954+0000] {taskinstance.py:2217} INFO - Executing <Task(PythonOperator): store> on 2024-07-15 00:00:00+00:00
[2024-07-16T18:45:23.967+0000] {standard_task_runner.py:60} INFO - Started process 139 to run task
[2024-07-16T18:45:24.000+0000] {standard_task_runner.py:87} INFO - Running: ['***', 'tasks', 'run', 'stagingtodv', 'store', 'scheduled__2024-07-15T00:00:00+00:00', '--job-id', '24', '--raw', '--subdir', 'DAGS_FOLDER/dag.py', '--cfg-path', '/tmp/tmpubrvdwak']
[2024-07-16T18:45:24.017+0000] {standard_task_runner.py:88} INFO - Job 24: Subtask store
[2024-07-16T18:45:24.149+0000] {task_command.py:423} INFO - Running <TaskInstance: stagingtodv.store scheduled__2024-07-15T00:00:00+00:00 [running]> on host 2e3dbb9eb862
[2024-07-16T18:45:24.593+0000] {taskinstance.py:2513} INFO - Exporting env vars: AIRFLOW_CTX_DAG_OWNER='***' AIRFLOW_CTX_DAG_ID='stagingtodv' AIRFLOW_CTX_TASK_ID='store' AIRFLOW_CTX_EXECUTION_DATE='2024-07-15T00:00:00+00:00' AIRFLOW_CTX_TRY_NUMBER='1' AIRFLOW_CTX_DAG_RUN_ID='scheduled__2024-07-15T00:00:00+00:00'
[2024-07-16T18:45:24.600+0000] {logging_mixin.py:188} INFO - -------------------------------------------- select *  from etlconf.Etl_Process_Mapping where SourceTableName = 'store' and Stage = 'stagingtodv'
[2024-07-16T18:45:24.759+0000] {taskinstance.py:2731} ERROR - Task failed with exception
Traceback (most recent call last):
  File "/home/airflow/.local/lib/python3.8/site-packages/airflow/models/taskinstance.py", line 444, in _execute_task
    result = _execute_callable(context=context, **execute_callable_kwargs)
  File "/home/airflow/.local/lib/python3.8/site-packages/airflow/models/taskinstance.py", line 414, in _execute_callable
    return execute_callable(context=context, **execute_callable_kwargs)
  File "/home/airflow/.local/lib/python3.8/site-packages/airflow/operators/python.py", line 200, in execute
    return_value = self.execute_callable()
  File "/home/airflow/.local/lib/python3.8/site-packages/airflow/operators/python.py", line 217, in execute_callable
    return self.python_callable(*self.op_args, **self.op_kwargs)
  File "/opt/airflow/dags/dag.py", line 41, in process_table
    tabletype = get_data_from_conf_table(table,stage)['tabletype'].values[0]
  File "/opt/airflow/dags/dag.py", line 34, in get_data_from_conf_table
    df.columns = [desc[0] for desc in cur.description]
  File "/home/airflow/.local/lib/python3.8/site-packages/pandas/core/generic.py", line 6002, in __setattr__
    return object.__setattr__(self, name, value)
  File "pandas/_libs/properties.pyx", line 69, in pandas._libs.properties.AxisProperty.__set__
  File "/home/airflow/.local/lib/python3.8/site-packages/pandas/core/generic.py", line 730, in _set_axis
    self._mgr.set_axis(axis, labels)
  File "/home/airflow/.local/lib/python3.8/site-packages/pandas/core/internals/managers.py", line 225, in set_axis
    self._validate_set_axis(axis, new_labels)
  File "/home/airflow/.local/lib/python3.8/site-packages/pandas/core/internals/base.py", line 70, in _validate_set_axis
    raise ValueError(
ValueError: Length mismatch: Expected axis has 0 elements, new values have 15 elements
[2024-07-16T18:45:26.127+0000] {taskinstance.py:1149} INFO - Marking task as FAILED. dag_id=stagingtodv, task_id=store, execution_date=20240715T000000, start_date=20240716T184523, end_date=20240716T184526
[2024-07-16T18:45:26.158+0000] {standard_task_runner.py:107} ERROR - Failed to execute job 24 for task store (Length mismatch: Expected axis has 0 elements, new values have 15 elements; 139)
[2024-07-16T18:45:26.194+0000] {local_task_job_runner.py:234} INFO - Task exited with return code 1
[2024-07-16T18:45:26.263+0000] {taskinstance.py:3312} INFO - 0 downstream tasks scheduled from follow-on schedule check
[2024-07-16T18:56:45.932+0000] {taskinstance.py:1979} INFO - Dependencies all met for dep_context=non-requeueable deps ti=<TaskInstance: stagingtodv.store scheduled__2024-07-15T00:00:00+00:00 [queued]>
[2024-07-16T18:56:46.006+0000] {taskinstance.py:1979} INFO - Dependencies all met for dep_context=requeueable deps ti=<TaskInstance: stagingtodv.store scheduled__2024-07-15T00:00:00+00:00 [queued]>
[2024-07-16T18:56:46.013+0000] {taskinstance.py:2193} INFO - Starting attempt 1 of 1
[2024-07-16T18:56:46.052+0000] {taskinstance.py:2217} INFO - Executing <Task(PythonOperator): store> on 2024-07-15 00:00:00+00:00
[2024-07-16T18:56:46.063+0000] {standard_task_runner.py:60} INFO - Started process 150 to run task
[2024-07-16T18:56:46.071+0000] {standard_task_runner.py:87} INFO - Running: ['***', 'tasks', 'run', 'stagingtodv', 'store', 'scheduled__2024-07-15T00:00:00+00:00', '--job-id', '26', '--raw', '--subdir', 'DAGS_FOLDER/dag.py', '--cfg-path', '/tmp/tmph5e0sudg']
[2024-07-16T18:56:46.103+0000] {standard_task_runner.py:88} INFO - Job 26: Subtask store
[2024-07-16T18:56:46.363+0000] {task_command.py:423} INFO - Running <TaskInstance: stagingtodv.store scheduled__2024-07-15T00:00:00+00:00 [running]> on host 1733eeb0def3
[2024-07-16T18:56:46.642+0000] {taskinstance.py:2513} INFO - Exporting env vars: AIRFLOW_CTX_DAG_OWNER='***' AIRFLOW_CTX_DAG_ID='stagingtodv' AIRFLOW_CTX_TASK_ID='store' AIRFLOW_CTX_EXECUTION_DATE='2024-07-15T00:00:00+00:00' AIRFLOW_CTX_TRY_NUMBER='1' AIRFLOW_CTX_DAG_RUN_ID='scheduled__2024-07-15T00:00:00+00:00'
[2024-07-16T18:56:46.653+0000] {logging_mixin.py:188} INFO - -------------------------------------------- select *  from etlconf.Etl_Process_Mapping where SourceTableName = 'store' and Stage = 'stagingtodv'
[2024-07-16T18:56:47.169+0000] {taskinstance.py:2731} ERROR - Task failed with exception
Traceback (most recent call last):
  File "/home/airflow/.local/lib/python3.8/site-packages/airflow/models/taskinstance.py", line 444, in _execute_task
    result = _execute_callable(context=context, **execute_callable_kwargs)
  File "/home/airflow/.local/lib/python3.8/site-packages/airflow/models/taskinstance.py", line 414, in _execute_callable
    return execute_callable(context=context, **execute_callable_kwargs)
  File "/home/airflow/.local/lib/python3.8/site-packages/airflow/operators/python.py", line 200, in execute
    return_value = self.execute_callable()
  File "/home/airflow/.local/lib/python3.8/site-packages/airflow/operators/python.py", line 217, in execute_callable
    return self.python_callable(*self.op_args, **self.op_kwargs)
  File "/opt/airflow/dags/dag.py", line 41, in process_table
    tabletype = get_data_from_conf_table(table,stage)['tabletype'].values[0]
  File "/opt/airflow/dags/dag.py", line 34, in get_data_from_conf_table
    df.columns = [desc[0] for desc in cur.description]
  File "/home/airflow/.local/lib/python3.8/site-packages/pandas/core/generic.py", line 6002, in __setattr__
    return object.__setattr__(self, name, value)
  File "pandas/_libs/properties.pyx", line 69, in pandas._libs.properties.AxisProperty.__set__
  File "/home/airflow/.local/lib/python3.8/site-packages/pandas/core/generic.py", line 730, in _set_axis
    self._mgr.set_axis(axis, labels)
  File "/home/airflow/.local/lib/python3.8/site-packages/pandas/core/internals/managers.py", line 225, in set_axis
    self._validate_set_axis(axis, new_labels)
  File "/home/airflow/.local/lib/python3.8/site-packages/pandas/core/internals/base.py", line 70, in _validate_set_axis
    raise ValueError(
ValueError: Length mismatch: Expected axis has 0 elements, new values have 15 elements
[2024-07-16T18:56:47.183+0000] {taskinstance.py:1149} INFO - Marking task as FAILED. dag_id=stagingtodv, task_id=store, execution_date=20240715T000000, start_date=20240716T185645, end_date=20240716T185647
[2024-07-16T18:56:47.195+0000] {standard_task_runner.py:107} ERROR - Failed to execute job 26 for task store (Length mismatch: Expected axis has 0 elements, new values have 15 elements; 150)
[2024-07-16T18:56:47.217+0000] {local_task_job_runner.py:234} INFO - Task exited with return code 1
[2024-07-16T18:56:47.255+0000] {taskinstance.py:3312} INFO - 0 downstream tasks scheduled from follow-on schedule check
[2024-07-16T19:01:11.918+0000] {taskinstance.py:1979} INFO - Dependencies all met for dep_context=non-requeueable deps ti=<TaskInstance: stagingtodv.store scheduled__2024-07-15T00:00:00+00:00 [queued]>
[2024-07-16T19:01:11.944+0000] {taskinstance.py:1979} INFO - Dependencies all met for dep_context=requeueable deps ti=<TaskInstance: stagingtodv.store scheduled__2024-07-15T00:00:00+00:00 [queued]>
[2024-07-16T19:01:11.947+0000] {taskinstance.py:2193} INFO - Starting attempt 1 of 1
[2024-07-16T19:01:12.028+0000] {taskinstance.py:2217} INFO - Executing <Task(PythonOperator): store> on 2024-07-15 00:00:00+00:00
[2024-07-16T19:01:12.039+0000] {standard_task_runner.py:60} INFO - Started process 87 to run task
[2024-07-16T19:01:12.052+0000] {standard_task_runner.py:87} INFO - Running: ['***', 'tasks', 'run', 'stagingtodv', 'store', 'scheduled__2024-07-15T00:00:00+00:00', '--job-id', '9', '--raw', '--subdir', 'DAGS_FOLDER/dag.py', '--cfg-path', '/tmp/tmp5lfnwps6']
[2024-07-16T19:01:12.078+0000] {standard_task_runner.py:88} INFO - Job 9: Subtask store
[2024-07-16T19:01:12.294+0000] {task_command.py:423} INFO - Running <TaskInstance: stagingtodv.store scheduled__2024-07-15T00:00:00+00:00 [running]> on host ef8b8dee6045
[2024-07-16T19:01:12.755+0000] {taskinstance.py:2513} INFO - Exporting env vars: AIRFLOW_CTX_DAG_OWNER='***' AIRFLOW_CTX_DAG_ID='stagingtodv' AIRFLOW_CTX_TASK_ID='store' AIRFLOW_CTX_EXECUTION_DATE='2024-07-15T00:00:00+00:00' AIRFLOW_CTX_TRY_NUMBER='1' AIRFLOW_CTX_DAG_RUN_ID='scheduled__2024-07-15T00:00:00+00:00'
[2024-07-16T19:01:12.761+0000] {logging_mixin.py:188} INFO - -------------------------------------------- select *  from etlconf.Etl_Process_Mapping where SourceTableName = 'store' and Stage = 'stagingtodv'
[2024-07-16T19:01:13.656+0000] {taskinstance.py:2731} ERROR - Task failed with exception
Traceback (most recent call last):
  File "/home/airflow/.local/lib/python3.8/site-packages/airflow/models/taskinstance.py", line 444, in _execute_task
    result = _execute_callable(context=context, **execute_callable_kwargs)
  File "/home/airflow/.local/lib/python3.8/site-packages/airflow/models/taskinstance.py", line 414, in _execute_callable
    return execute_callable(context=context, **execute_callable_kwargs)
  File "/home/airflow/.local/lib/python3.8/site-packages/airflow/operators/python.py", line 200, in execute
    return_value = self.execute_callable()
  File "/home/airflow/.local/lib/python3.8/site-packages/airflow/operators/python.py", line 217, in execute_callable
    return self.python_callable(*self.op_args, **self.op_kwargs)
  File "/opt/airflow/dags/dag.py", line 41, in process_table
    tabletype = get_data_from_conf_table(table,stage)['tabletype'].values[0]
  File "/opt/airflow/dags/dag.py", line 34, in get_data_from_conf_table
    df.columns = [desc[0] for desc in cur.description]
  File "/home/airflow/.local/lib/python3.8/site-packages/pandas/core/generic.py", line 6002, in __setattr__
    return object.__setattr__(self, name, value)
  File "pandas/_libs/properties.pyx", line 69, in pandas._libs.properties.AxisProperty.__set__
  File "/home/airflow/.local/lib/python3.8/site-packages/pandas/core/generic.py", line 730, in _set_axis
    self._mgr.set_axis(axis, labels)
  File "/home/airflow/.local/lib/python3.8/site-packages/pandas/core/internals/managers.py", line 225, in set_axis
    self._validate_set_axis(axis, new_labels)
  File "/home/airflow/.local/lib/python3.8/site-packages/pandas/core/internals/base.py", line 70, in _validate_set_axis
    raise ValueError(
ValueError: Length mismatch: Expected axis has 0 elements, new values have 15 elements
[2024-07-16T19:01:13.687+0000] {taskinstance.py:1149} INFO - Marking task as FAILED. dag_id=stagingtodv, task_id=store, execution_date=20240715T000000, start_date=20240716T190111, end_date=20240716T190113
[2024-07-16T19:01:13.702+0000] {standard_task_runner.py:107} ERROR - Failed to execute job 9 for task store (Length mismatch: Expected axis has 0 elements, new values have 15 elements; 87)
[2024-07-16T19:01:13.756+0000] {local_task_job_runner.py:234} INFO - Task exited with return code 1
[2024-07-16T19:01:13.771+0000] {taskinstance.py:3312} INFO - 0 downstream tasks scheduled from follow-on schedule check
