[2024-07-16T17:21:56.518+0000] {taskinstance.py:1979} INFO - Dependencies all met for dep_context=non-requeueable deps ti=<TaskInstance: staigingtodv.country manual__2024-07-16T17:21:53.849457+00:00 [queued]>
[2024-07-16T17:21:56.545+0000] {taskinstance.py:1979} INFO - Dependencies all met for dep_context=requeueable deps ti=<TaskInstance: staigingtodv.country manual__2024-07-16T17:21:53.849457+00:00 [queued]>
[2024-07-16T17:21:56.552+0000] {taskinstance.py:2193} INFO - Starting attempt 1 of 1
[2024-07-16T17:21:56.593+0000] {taskinstance.py:2217} INFO - Executing <Task(PythonOperator): country> on 2024-07-16 17:21:53.849457+00:00
[2024-07-16T17:21:56.628+0000] {standard_task_runner.py:60} INFO - Started process 313 to run task
[2024-07-16T17:21:56.636+0000] {standard_task_runner.py:87} INFO - Running: ['***', 'tasks', 'run', 'staigingtodv', 'country', 'manual__2024-07-16T17:21:53.849457+00:00', '--job-id', '23', '--raw', '--subdir', 'DAGS_FOLDER/dag.py', '--cfg-path', '/tmp/tmpuahl2e5c']
[2024-07-16T17:21:56.642+0000] {standard_task_runner.py:88} INFO - Job 23: Subtask country
[2024-07-16T17:21:56.838+0000] {task_command.py:423} INFO - Running <TaskInstance: staigingtodv.country manual__2024-07-16T17:21:53.849457+00:00 [running]> on host a8165c4616a2
[2024-07-16T17:21:57.115+0000] {taskinstance.py:2513} INFO - Exporting env vars: AIRFLOW_CTX_DAG_OWNER='***' AIRFLOW_CTX_DAG_ID='staigingtodv' AIRFLOW_CTX_TASK_ID='country' AIRFLOW_CTX_EXECUTION_DATE='2024-07-16T17:21:53.849457+00:00' AIRFLOW_CTX_TRY_NUMBER='1' AIRFLOW_CTX_DAG_RUN_ID='manual__2024-07-16T17:21:53.849457+00:00'
[2024-07-16T17:21:57.133+0000] {logging_mixin.py:188} INFO - -------------------------------------------- select *  from etlconf.Etl_Process_Mapping where SourceTableName = 'country' and Stage = 'staigingtodv'
[2024-07-16T17:21:57.210+0000] {taskinstance.py:2731} ERROR - Task failed with exception
Traceback (most recent call last):
  File "/home/airflow/.local/lib/python3.8/site-packages/airflow/models/taskinstance.py", line 444, in _execute_task
    result = _execute_callable(context=context, **execute_callable_kwargs)
  File "/home/airflow/.local/lib/python3.8/site-packages/airflow/models/taskinstance.py", line 414, in _execute_callable
    return execute_callable(context=context, **execute_callable_kwargs)
  File "/home/airflow/.local/lib/python3.8/site-packages/airflow/operators/python.py", line 200, in execute
    return_value = self.execute_callable()
  File "/home/airflow/.local/lib/python3.8/site-packages/airflow/operators/python.py", line 217, in execute_callable
    return self.python_callable(*self.op_args, **self.op_kwargs)
  File "/opt/airflow/dags/dag.py", line 41, in process_table
    tabletype = get_data_from_conf_table(table,stage)['tabletype'].values[0]
  File "/opt/airflow/dags/dag.py", line 34, in get_data_from_conf_table
    df.columns = [desc[0] for desc in cur.description]
  File "/home/airflow/.local/lib/python3.8/site-packages/pandas/core/generic.py", line 6002, in __setattr__
    return object.__setattr__(self, name, value)
  File "pandas/_libs/properties.pyx", line 69, in pandas._libs.properties.AxisProperty.__set__
  File "/home/airflow/.local/lib/python3.8/site-packages/pandas/core/generic.py", line 730, in _set_axis
    self._mgr.set_axis(axis, labels)
  File "/home/airflow/.local/lib/python3.8/site-packages/pandas/core/internals/managers.py", line 225, in set_axis
    self._validate_set_axis(axis, new_labels)
  File "/home/airflow/.local/lib/python3.8/site-packages/pandas/core/internals/base.py", line 70, in _validate_set_axis
    raise ValueError(
ValueError: Length mismatch: Expected axis has 0 elements, new values have 15 elements
[2024-07-16T17:21:57.974+0000] {taskinstance.py:1149} INFO - Marking task as FAILED. dag_id=staigingtodv, task_id=country, execution_date=20240716T172153, start_date=20240716T172156, end_date=20240716T172157
[2024-07-16T17:21:58.017+0000] {standard_task_runner.py:107} ERROR - Failed to execute job 23 for task country (Length mismatch: Expected axis has 0 elements, new values have 15 elements; 313)
[2024-07-16T17:21:58.101+0000] {local_task_job_runner.py:234} INFO - Task exited with return code 1
[2024-07-16T17:21:58.179+0000] {taskinstance.py:3312} INFO - 0 downstream tasks scheduled from follow-on schedule check
