[2024-07-16T17:23:41.978+0000] {taskinstance.py:1979} INFO - Dependencies all met for dep_context=non-requeueable deps ti=<TaskInstance: stagingtodv.city scheduled__2024-07-15T00:00:00+00:00 [queued]>
[2024-07-16T17:23:42.009+0000] {taskinstance.py:1979} INFO - Dependencies all met for dep_context=requeueable deps ti=<TaskInstance: stagingtodv.city scheduled__2024-07-15T00:00:00+00:00 [queued]>
[2024-07-16T17:23:42.012+0000] {taskinstance.py:2193} INFO - Starting attempt 1 of 1
[2024-07-16T17:23:42.063+0000] {taskinstance.py:2217} INFO - Executing <Task(PythonOperator): city> on 2024-07-15 00:00:00+00:00
[2024-07-16T17:23:42.075+0000] {standard_task_runner.py:60} INFO - Started process 386 to run task
[2024-07-16T17:23:42.102+0000] {standard_task_runner.py:87} INFO - Running: ['***', 'tasks', 'run', 'stagingtodv', 'city', 'scheduled__2024-07-15T00:00:00+00:00', '--job-id', '33', '--raw', '--subdir', 'DAGS_FOLDER/dag.py', '--cfg-path', '/tmp/tmpduy6i0b1']
[2024-07-16T17:23:42.113+0000] {standard_task_runner.py:88} INFO - Job 33: Subtask city
[2024-07-16T17:23:42.272+0000] {task_command.py:423} INFO - Running <TaskInstance: stagingtodv.city scheduled__2024-07-15T00:00:00+00:00 [running]> on host a8165c4616a2
[2024-07-16T17:23:42.539+0000] {taskinstance.py:2513} INFO - Exporting env vars: AIRFLOW_CTX_DAG_OWNER='***' AIRFLOW_CTX_DAG_ID='stagingtodv' AIRFLOW_CTX_TASK_ID='city' AIRFLOW_CTX_EXECUTION_DATE='2024-07-15T00:00:00+00:00' AIRFLOW_CTX_TRY_NUMBER='1' AIRFLOW_CTX_DAG_RUN_ID='scheduled__2024-07-15T00:00:00+00:00'
[2024-07-16T17:23:42.546+0000] {logging_mixin.py:188} INFO - -------------------------------------------- select *  from etlconf.Etl_Process_Mapping where SourceTableName = 'city' and Stage = 'stagingtodv'
[2024-07-16T17:23:42.651+0000] {logging_mixin.py:188} INFO - shemodixar? sasadasfaf
[2024-07-16T17:23:42.654+0000] {logging_mixin.py:188} INFO - select *  from etlconf.Etl_Process_Mapping where SourceTableName = 'city' and Stage = 'stagingtodv'
[2024-07-16T17:23:42.708+0000] {logging_mixin.py:188} INFO - dasfadfasdasfadsggssfgsahjbfhajvfhasvdasb cn akjsbjhasbc  asjbcajhsbca
[2024-07-16T17:23:43.871+0000] {logging_mixin.py:188} INFO -    id sourcetablename sourcedbname  ... code        stage last_run_date
0  19            city    DBStaging  ...    1  stagingtodv          None

[1 rows x 15 columns]
[2024-07-16T17:23:43.945+0000] {taskinstance.py:2731} ERROR - Task failed with exception
Traceback (most recent call last):
  File "/home/airflow/.local/lib/python3.8/site-packages/airflow/models/taskinstance.py", line 444, in _execute_task
    result = _execute_callable(context=context, **execute_callable_kwargs)
  File "/home/airflow/.local/lib/python3.8/site-packages/airflow/models/taskinstance.py", line 414, in _execute_callable
    return execute_callable(context=context, **execute_callable_kwargs)
  File "/home/airflow/.local/lib/python3.8/site-packages/airflow/operators/python.py", line 200, in execute
    return_value = self.execute_callable()
  File "/home/airflow/.local/lib/python3.8/site-packages/airflow/operators/python.py", line 217, in execute_callable
    return self.python_callable(*self.op_args, **self.op_kwargs)
  File "/opt/airflow/dags/dag.py", line 45, in process_table
    return  execute(table, stage, tabletype)
  File "/app/main.py", line 31, in execute
    (StagingToDV().create_full().some_function(table, stage))
  File "/app/concretestage/StagingToDV.py", line 39, in some_function
    sourceDF = getDF(sourcedbname,sourcetablename , sourceschema)
  File "/app/myFramework/utils/utils.py", line 27, in getDF
    cur.execute(query)
psycopg2.errors.FeatureNotSupported: cross-database references are not implemented: "dbstaging.dvdrental.city"
LINE 1: select T.* from DBStaging.dvdrental.city T
                        ^

[2024-07-16T17:23:44.122+0000] {taskinstance.py:1149} INFO - Marking task as FAILED. dag_id=stagingtodv, task_id=city, execution_date=20240715T000000, start_date=20240716T172341, end_date=20240716T172344
[2024-07-16T17:23:44.316+0000] {standard_task_runner.py:107} ERROR - Failed to execute job 33 for task city (cross-database references are not implemented: "dbstaging.dvdrental.city"
LINE 1: select T.* from DBStaging.dvdrental.city T
                        ^
; 386)
[2024-07-16T17:23:44.424+0000] {local_task_job_runner.py:234} INFO - Task exited with return code 1
[2024-07-16T17:23:44.563+0000] {taskinstance.py:3312} INFO - 0 downstream tasks scheduled from follow-on schedule check
[2024-07-16T17:33:46.061+0000] {taskinstance.py:1979} INFO - Dependencies all met for dep_context=non-requeueable deps ti=<TaskInstance: stagingtodv.city scheduled__2024-07-15T00:00:00+00:00 [queued]>
[2024-07-16T17:33:46.086+0000] {taskinstance.py:1979} INFO - Dependencies all met for dep_context=requeueable deps ti=<TaskInstance: stagingtodv.city scheduled__2024-07-15T00:00:00+00:00 [queued]>
[2024-07-16T17:33:46.090+0000] {taskinstance.py:2193} INFO - Starting attempt 1 of 1
[2024-07-16T17:33:46.152+0000] {taskinstance.py:2217} INFO - Executing <Task(PythonOperator): city> on 2024-07-15 00:00:00+00:00
[2024-07-16T17:33:46.163+0000] {standard_task_runner.py:60} INFO - Started process 123 to run task
[2024-07-16T17:33:46.183+0000] {standard_task_runner.py:87} INFO - Running: ['***', 'tasks', 'run', 'stagingtodv', 'city', 'scheduled__2024-07-15T00:00:00+00:00', '--job-id', '9', '--raw', '--subdir', 'DAGS_FOLDER/dag.py', '--cfg-path', '/tmp/tmp6qwz34gt']
[2024-07-16T17:33:46.215+0000] {standard_task_runner.py:88} INFO - Job 9: Subtask city
[2024-07-16T17:33:46.445+0000] {task_command.py:423} INFO - Running <TaskInstance: stagingtodv.city scheduled__2024-07-15T00:00:00+00:00 [running]> on host e9bb94dbac8b
[2024-07-16T17:33:47.876+0000] {taskinstance.py:2513} INFO - Exporting env vars: AIRFLOW_CTX_DAG_OWNER='***' AIRFLOW_CTX_DAG_ID='stagingtodv' AIRFLOW_CTX_TASK_ID='city' AIRFLOW_CTX_EXECUTION_DATE='2024-07-15T00:00:00+00:00' AIRFLOW_CTX_TRY_NUMBER='1' AIRFLOW_CTX_DAG_RUN_ID='scheduled__2024-07-15T00:00:00+00:00'
[2024-07-16T17:33:47.885+0000] {logging_mixin.py:188} INFO - -------------------------------------------- select *  from etlconf.Etl_Process_Mapping where SourceTableName = 'city' and Stage = 'stagingtodv'
[2024-07-16T17:33:47.950+0000] {logging_mixin.py:188} INFO - select *  from etlconf.Etl_Process_Mapping where SourceTableName = 'city' and Stage = 'stagingtodv'
[2024-07-16T17:33:48.017+0000] {logging_mixin.py:188} INFO - 
 DBStaging 
 city 
 dvdrental
[2024-07-16T17:33:48.025+0000] {python.py:202} INFO - Done. Returned value was: None
[2024-07-16T17:33:48.043+0000] {taskinstance.py:1149} INFO - Marking task as SUCCESS. dag_id=stagingtodv, task_id=city, execution_date=20240715T000000, start_date=20240716T173346, end_date=20240716T173348
[2024-07-16T17:33:48.075+0000] {local_task_job_runner.py:234} INFO - Task exited with return code 0
[2024-07-16T17:33:48.116+0000] {taskinstance.py:3312} INFO - 0 downstream tasks scheduled from follow-on schedule check
[2024-07-16T17:36:01.275+0000] {taskinstance.py:1979} INFO - Dependencies all met for dep_context=non-requeueable deps ti=<TaskInstance: stagingtodv.city scheduled__2024-07-15T00:00:00+00:00 [queued]>
[2024-07-16T17:36:01.309+0000] {taskinstance.py:1979} INFO - Dependencies all met for dep_context=requeueable deps ti=<TaskInstance: stagingtodv.city scheduled__2024-07-15T00:00:00+00:00 [queued]>
[2024-07-16T17:36:01.311+0000] {taskinstance.py:2193} INFO - Starting attempt 1 of 1
[2024-07-16T17:36:01.335+0000] {taskinstance.py:2217} INFO - Executing <Task(PythonOperator): city> on 2024-07-15 00:00:00+00:00
[2024-07-16T17:36:01.354+0000] {standard_task_runner.py:60} INFO - Started process 101 to run task
[2024-07-16T17:36:01.367+0000] {standard_task_runner.py:87} INFO - Running: ['***', 'tasks', 'run', 'stagingtodv', 'city', 'scheduled__2024-07-15T00:00:00+00:00', '--job-id', '16', '--raw', '--subdir', 'DAGS_FOLDER/dag.py', '--cfg-path', '/tmp/tmp49yg7sz_']
[2024-07-16T17:36:01.378+0000] {standard_task_runner.py:88} INFO - Job 16: Subtask city
[2024-07-16T17:36:01.637+0000] {task_command.py:423} INFO - Running <TaskInstance: stagingtodv.city scheduled__2024-07-15T00:00:00+00:00 [running]> on host e1ba87a2fe19
[2024-07-16T17:36:02.810+0000] {taskinstance.py:2513} INFO - Exporting env vars: AIRFLOW_CTX_DAG_OWNER='***' AIRFLOW_CTX_DAG_ID='stagingtodv' AIRFLOW_CTX_TASK_ID='city' AIRFLOW_CTX_EXECUTION_DATE='2024-07-15T00:00:00+00:00' AIRFLOW_CTX_TRY_NUMBER='1' AIRFLOW_CTX_DAG_RUN_ID='scheduled__2024-07-15T00:00:00+00:00'
[2024-07-16T17:36:02.812+0000] {logging_mixin.py:188} INFO - -------------------------------------------- select *  from etlconf.Etl_Process_Mapping where SourceTableName = 'city' and Stage = 'stagingtodv'
[2024-07-16T17:36:02.848+0000] {logging_mixin.py:188} INFO - select *  from etlconf.Etl_Process_Mapping where SourceTableName = 'city' and Stage = 'stagingtodv'
[2024-07-16T17:36:02.883+0000] {taskinstance.py:2731} ERROR - Task failed with exception
Traceback (most recent call last):
  File "/home/airflow/.local/lib/python3.8/site-packages/airflow/models/taskinstance.py", line 444, in _execute_task
    result = _execute_callable(context=context, **execute_callable_kwargs)
  File "/home/airflow/.local/lib/python3.8/site-packages/airflow/models/taskinstance.py", line 414, in _execute_callable
    return execute_callable(context=context, **execute_callable_kwargs)
  File "/home/airflow/.local/lib/python3.8/site-packages/airflow/operators/python.py", line 200, in execute
    return_value = self.execute_callable()
  File "/home/airflow/.local/lib/python3.8/site-packages/airflow/operators/python.py", line 217, in execute_callable
    return self.python_callable(*self.op_args, **self.op_kwargs)
  File "/opt/airflow/dags/dag.py", line 45, in process_table
    return  execute(table, stage, tabletype)
  File "/app/main.py", line 31, in execute
    (StagingToDV().create_full().some_function(table, stage))
  File "/app/concretestage/StagingToDV.py", line 36, in some_function
    sourceDF = getDF(sourcedbname,sourcetablename , sourceschema)
  File "/app/myFramework/utils/utils.py", line 27, in getDF
    cur.execute(query)
psycopg2.errors.FeatureNotSupported: cross-database references are not implemented: "dbstaging.dvdrental.city"
LINE 1: select T.* from DBStaging.dvdrental.city T
                        ^

[2024-07-16T17:36:02.898+0000] {taskinstance.py:1149} INFO - Marking task as FAILED. dag_id=stagingtodv, task_id=city, execution_date=20240715T000000, start_date=20240716T173601, end_date=20240716T173602
[2024-07-16T17:36:02.909+0000] {standard_task_runner.py:107} ERROR - Failed to execute job 16 for task city (cross-database references are not implemented: "dbstaging.dvdrental.city"
LINE 1: select T.* from DBStaging.dvdrental.city T
                        ^
; 101)
[2024-07-16T17:36:02.958+0000] {local_task_job_runner.py:234} INFO - Task exited with return code 1
[2024-07-16T17:36:02.976+0000] {taskinstance.py:3312} INFO - 0 downstream tasks scheduled from follow-on schedule check
[2024-07-16T17:45:35.082+0000] {taskinstance.py:1979} INFO - Dependencies all met for dep_context=non-requeueable deps ti=<TaskInstance: stagingtodv.city scheduled__2024-07-15T00:00:00+00:00 [queued]>
[2024-07-16T17:45:35.098+0000] {taskinstance.py:1979} INFO - Dependencies all met for dep_context=requeueable deps ti=<TaskInstance: stagingtodv.city scheduled__2024-07-15T00:00:00+00:00 [queued]>
[2024-07-16T17:45:35.101+0000] {taskinstance.py:2193} INFO - Starting attempt 1 of 1
[2024-07-16T17:45:35.160+0000] {taskinstance.py:2217} INFO - Executing <Task(PythonOperator): city> on 2024-07-15 00:00:00+00:00
[2024-07-16T17:45:35.195+0000] {standard_task_runner.py:60} INFO - Started process 101 to run task
[2024-07-16T17:45:35.203+0000] {standard_task_runner.py:87} INFO - Running: ['***', 'tasks', 'run', 'stagingtodv', 'city', 'scheduled__2024-07-15T00:00:00+00:00', '--job-id', '16', '--raw', '--subdir', 'DAGS_FOLDER/dag.py', '--cfg-path', '/tmp/tmp2we617hp']
[2024-07-16T17:45:35.207+0000] {standard_task_runner.py:88} INFO - Job 16: Subtask city
[2024-07-16T17:45:35.439+0000] {task_command.py:423} INFO - Running <TaskInstance: stagingtodv.city scheduled__2024-07-15T00:00:00+00:00 [running]> on host bba7487a60b5
[2024-07-16T17:45:36.527+0000] {taskinstance.py:2513} INFO - Exporting env vars: AIRFLOW_CTX_DAG_OWNER='***' AIRFLOW_CTX_DAG_ID='stagingtodv' AIRFLOW_CTX_TASK_ID='city' AIRFLOW_CTX_EXECUTION_DATE='2024-07-15T00:00:00+00:00' AIRFLOW_CTX_TRY_NUMBER='1' AIRFLOW_CTX_DAG_RUN_ID='scheduled__2024-07-15T00:00:00+00:00'
[2024-07-16T17:45:36.534+0000] {logging_mixin.py:188} INFO - -------------------------------------------- select *  from etlconf.Etl_Process_Mapping where SourceTableName = 'city' and Stage = 'stagingtodv'
[2024-07-16T17:45:36.648+0000] {logging_mixin.py:188} INFO - select *  from etlconf.Etl_Process_Mapping where SourceTableName = 'city' and Stage = 'stagingtodv'
[2024-07-16T17:45:36.728+0000] {taskinstance.py:2731} ERROR - Task failed with exception
Traceback (most recent call last):
  File "/home/airflow/.local/lib/python3.8/site-packages/airflow/models/taskinstance.py", line 444, in _execute_task
    result = _execute_callable(context=context, **execute_callable_kwargs)
  File "/home/airflow/.local/lib/python3.8/site-packages/airflow/models/taskinstance.py", line 414, in _execute_callable
    return execute_callable(context=context, **execute_callable_kwargs)
  File "/home/airflow/.local/lib/python3.8/site-packages/airflow/operators/python.py", line 200, in execute
    return_value = self.execute_callable()
  File "/home/airflow/.local/lib/python3.8/site-packages/airflow/operators/python.py", line 217, in execute_callable
    return self.python_callable(*self.op_args, **self.op_kwargs)
  File "/opt/airflow/dags/dag.py", line 45, in process_table
    return  execute(table, stage, tabletype)
  File "/app/main.py", line 31, in execute
    (StagingToDV().create_full().some_function(table, stage))
  File "/app/concretestage/StagingToDV.py", line 36, in some_function
    sourceDF = getDF(sourcedbname,sourcetablename , sourceschema)
  File "/app/myFramework/utils/utils.py", line 27, in getDF
    cur.execute(query)
psycopg2.errors.FeatureNotSupported: cross-database references are not implemented: "dbstaging.dvdrental.city"
LINE 1: select T.* from DBStaging.dvdrental.city T
                        ^

[2024-07-16T17:45:36.746+0000] {taskinstance.py:1149} INFO - Marking task as FAILED. dag_id=stagingtodv, task_id=city, execution_date=20240715T000000, start_date=20240716T174535, end_date=20240716T174536
[2024-07-16T17:45:36.770+0000] {standard_task_runner.py:107} ERROR - Failed to execute job 16 for task city (cross-database references are not implemented: "dbstaging.dvdrental.city"
LINE 1: select T.* from DBStaging.dvdrental.city T
                        ^
; 101)
[2024-07-16T17:45:36.801+0000] {local_task_job_runner.py:234} INFO - Task exited with return code 1
[2024-07-16T17:45:36.888+0000] {taskinstance.py:3312} INFO - 0 downstream tasks scheduled from follow-on schedule check
[2024-07-16T17:58:24.675+0000] {taskinstance.py:1979} INFO - Dependencies all met for dep_context=non-requeueable deps ti=<TaskInstance: stagingtodv.city scheduled__2024-07-15T00:00:00+00:00 [queued]>
[2024-07-16T17:58:24.706+0000] {taskinstance.py:1979} INFO - Dependencies all met for dep_context=requeueable deps ti=<TaskInstance: stagingtodv.city scheduled__2024-07-15T00:00:00+00:00 [queued]>
[2024-07-16T17:58:24.711+0000] {taskinstance.py:2193} INFO - Starting attempt 1 of 1
[2024-07-16T17:58:24.757+0000] {taskinstance.py:2217} INFO - Executing <Task(PythonOperator): city> on 2024-07-15 00:00:00+00:00
[2024-07-16T17:58:24.769+0000] {standard_task_runner.py:60} INFO - Started process 88 to run task
[2024-07-16T17:58:24.778+0000] {standard_task_runner.py:87} INFO - Running: ['***', 'tasks', 'run', 'stagingtodv', 'city', 'scheduled__2024-07-15T00:00:00+00:00', '--job-id', '10', '--raw', '--subdir', 'DAGS_FOLDER/dag.py', '--cfg-path', '/tmp/tmpfyho4ip5']
[2024-07-16T17:58:24.792+0000] {standard_task_runner.py:88} INFO - Job 10: Subtask city
[2024-07-16T17:58:25.028+0000] {task_command.py:423} INFO - Running <TaskInstance: stagingtodv.city scheduled__2024-07-15T00:00:00+00:00 [running]> on host 9d71ede51657
[2024-07-16T17:58:26.405+0000] {taskinstance.py:2513} INFO - Exporting env vars: AIRFLOW_CTX_DAG_OWNER='***' AIRFLOW_CTX_DAG_ID='stagingtodv' AIRFLOW_CTX_TASK_ID='city' AIRFLOW_CTX_EXECUTION_DATE='2024-07-15T00:00:00+00:00' AIRFLOW_CTX_TRY_NUMBER='1' AIRFLOW_CTX_DAG_RUN_ID='scheduled__2024-07-15T00:00:00+00:00'
[2024-07-16T17:58:26.411+0000] {logging_mixin.py:188} INFO - -------------------------------------------- select *  from etlconf.Etl_Process_Mapping where SourceTableName = 'city' and Stage = 'stagingtodv'
[2024-07-16T17:58:26.457+0000] {logging_mixin.py:188} INFO - select *  from etlconf.Etl_Process_Mapping where SourceTableName = 'city' and Stage = 'stagingtodv'
[2024-07-16T17:58:26.507+0000] {taskinstance.py:2731} ERROR - Task failed with exception
Traceback (most recent call last):
  File "/home/airflow/.local/lib/python3.8/site-packages/airflow/models/taskinstance.py", line 444, in _execute_task
    result = _execute_callable(context=context, **execute_callable_kwargs)
  File "/home/airflow/.local/lib/python3.8/site-packages/airflow/models/taskinstance.py", line 414, in _execute_callable
    return execute_callable(context=context, **execute_callable_kwargs)
  File "/home/airflow/.local/lib/python3.8/site-packages/airflow/operators/python.py", line 200, in execute
    return_value = self.execute_callable()
  File "/home/airflow/.local/lib/python3.8/site-packages/airflow/operators/python.py", line 217, in execute_callable
    return self.python_callable(*self.op_args, **self.op_kwargs)
  File "/opt/airflow/dags/dag.py", line 45, in process_table
    return  execute(table, stage, tabletype)
  File "/app/main.py", line 31, in execute
    (StagingToDV().create_full().some_function(table, stage))
  File "/app/concretestage/StagingToDV.py", line 36, in some_function
    sourceDF = getDF(sourcedbname,sourcetablename , sourceschema)
  File "/app/myFramework/utils/utils.py", line 27, in getDF
    cur.execute(query)
psycopg2.errors.FeatureNotSupported: cross-database references are not implemented: "dbstaging.dvdrental.city"
LINE 1: select T.* from DBStaging.dvdrental.city T
                        ^

[2024-07-16T17:58:26.513+0000] {taskinstance.py:1149} INFO - Marking task as FAILED. dag_id=stagingtodv, task_id=city, execution_date=20240715T000000, start_date=20240716T175824, end_date=20240716T175826
[2024-07-16T17:58:26.527+0000] {standard_task_runner.py:107} ERROR - Failed to execute job 10 for task city (cross-database references are not implemented: "dbstaging.dvdrental.city"
LINE 1: select T.* from DBStaging.dvdrental.city T
                        ^
; 88)
[2024-07-16T17:58:26.538+0000] {local_task_job_runner.py:234} INFO - Task exited with return code 1
[2024-07-16T17:58:26.571+0000] {taskinstance.py:3312} INFO - 0 downstream tasks scheduled from follow-on schedule check
[2024-07-16T18:12:19.432+0000] {taskinstance.py:1979} INFO - Dependencies all met for dep_context=non-requeueable deps ti=<TaskInstance: stagingtodv.city scheduled__2024-07-15T00:00:00+00:00 [queued]>
[2024-07-16T18:12:19.464+0000] {taskinstance.py:1979} INFO - Dependencies all met for dep_context=requeueable deps ti=<TaskInstance: stagingtodv.city scheduled__2024-07-15T00:00:00+00:00 [queued]>
[2024-07-16T18:12:19.467+0000] {taskinstance.py:2193} INFO - Starting attempt 1 of 1
[2024-07-16T18:12:19.501+0000] {taskinstance.py:2217} INFO - Executing <Task(PythonOperator): city> on 2024-07-15 00:00:00+00:00
[2024-07-16T18:12:19.530+0000] {standard_task_runner.py:60} INFO - Started process 113 to run task
[2024-07-16T18:12:19.537+0000] {standard_task_runner.py:87} INFO - Running: ['***', 'tasks', 'run', 'stagingtodv', 'city', 'scheduled__2024-07-15T00:00:00+00:00', '--job-id', '9', '--raw', '--subdir', 'DAGS_FOLDER/dag.py', '--cfg-path', '/tmp/tmpeamzws6y']
[2024-07-16T18:12:19.553+0000] {standard_task_runner.py:88} INFO - Job 9: Subtask city
[2024-07-16T18:12:19.763+0000] {task_command.py:423} INFO - Running <TaskInstance: stagingtodv.city scheduled__2024-07-15T00:00:00+00:00 [running]> on host 9f18461f6153
[2024-07-16T18:12:21.263+0000] {taskinstance.py:2513} INFO - Exporting env vars: AIRFLOW_CTX_DAG_OWNER='***' AIRFLOW_CTX_DAG_ID='stagingtodv' AIRFLOW_CTX_TASK_ID='city' AIRFLOW_CTX_EXECUTION_DATE='2024-07-15T00:00:00+00:00' AIRFLOW_CTX_TRY_NUMBER='1' AIRFLOW_CTX_DAG_RUN_ID='scheduled__2024-07-15T00:00:00+00:00'
[2024-07-16T18:12:21.267+0000] {logging_mixin.py:188} INFO - -------------------------------------------- select *  from etlconf.Etl_Process_Mapping where SourceTableName = 'city' and Stage = 'stagingtodv'
[2024-07-16T18:12:21.303+0000] {logging_mixin.py:188} INFO - select *  from etlconf.Etl_Process_Mapping where SourceTableName = 'city' and Stage = 'stagingtodv'
[2024-07-16T18:12:21.362+0000] {taskinstance.py:2731} ERROR - Task failed with exception
Traceback (most recent call last):
  File "/home/airflow/.local/lib/python3.8/site-packages/airflow/models/taskinstance.py", line 444, in _execute_task
    result = _execute_callable(context=context, **execute_callable_kwargs)
  File "/home/airflow/.local/lib/python3.8/site-packages/airflow/models/taskinstance.py", line 414, in _execute_callable
    return execute_callable(context=context, **execute_callable_kwargs)
  File "/home/airflow/.local/lib/python3.8/site-packages/airflow/operators/python.py", line 200, in execute
    return_value = self.execute_callable()
  File "/home/airflow/.local/lib/python3.8/site-packages/airflow/operators/python.py", line 217, in execute_callable
    return self.python_callable(*self.op_args, **self.op_kwargs)
  File "/opt/airflow/dags/dag.py", line 45, in process_table
    return  execute(table, stage, tabletype)
  File "/app/main.py", line 31, in execute
    (StagingToDV().create_full().some_function(table, stage))
  File "/app/concretestage/StagingToDV.py", line 36, in some_function
    sourceDF = getDF(sourcedbname,sourcetablename , sourceschema)
  File "/app/myFramework/utils/utils.py", line 26, in getDF
    cur = conn.getCursor(source_dbname)
  File "/app/myFramework/source/posgresql/connect.py", line 9, in getCursor
    conn = psycopg2.connect(database = dbname,
  File "/home/airflow/.local/lib/python3.8/site-packages/psycopg2/__init__.py", line 122, in connect
    conn = _connect(dsn, connection_factory=connection_factory, **kwasync)
psycopg2.OperationalError: connection to server at "postgres_db" (172.28.0.5), port 9999 failed: FATAL:  database "dbstaging" does not exist

[2024-07-16T18:12:21.374+0000] {taskinstance.py:1149} INFO - Marking task as FAILED. dag_id=stagingtodv, task_id=city, execution_date=20240715T000000, start_date=20240716T181219, end_date=20240716T181221
[2024-07-16T18:12:21.392+0000] {standard_task_runner.py:107} ERROR - Failed to execute job 9 for task city (connection to server at "postgres_db" (172.28.0.5), port 9999 failed: FATAL:  database "dbstaging" does not exist
; 113)
[2024-07-16T18:12:21.455+0000] {local_task_job_runner.py:234} INFO - Task exited with return code 1
[2024-07-16T18:12:21.548+0000] {taskinstance.py:3312} INFO - 0 downstream tasks scheduled from follow-on schedule check
[2024-07-16T18:29:51.894+0000] {taskinstance.py:1979} INFO - Dependencies all met for dep_context=non-requeueable deps ti=<TaskInstance: stagingtodv.city scheduled__2024-07-15T00:00:00+00:00 [queued]>
[2024-07-16T18:29:51.938+0000] {taskinstance.py:1979} INFO - Dependencies all met for dep_context=requeueable deps ti=<TaskInstance: stagingtodv.city scheduled__2024-07-15T00:00:00+00:00 [queued]>
[2024-07-16T18:29:51.940+0000] {taskinstance.py:2193} INFO - Starting attempt 1 of 1
[2024-07-16T18:29:51.985+0000] {taskinstance.py:2217} INFO - Executing <Task(PythonOperator): city> on 2024-07-15 00:00:00+00:00
[2024-07-16T18:29:52.023+0000] {standard_task_runner.py:60} INFO - Started process 93 to run task
[2024-07-16T18:29:52.065+0000] {standard_task_runner.py:87} INFO - Running: ['***', 'tasks', 'run', 'stagingtodv', 'city', 'scheduled__2024-07-15T00:00:00+00:00', '--job-id', '10', '--raw', '--subdir', 'DAGS_FOLDER/dag.py', '--cfg-path', '/tmp/tmp2mrrhmch']
[2024-07-16T18:29:52.083+0000] {standard_task_runner.py:88} INFO - Job 10: Subtask city
[2024-07-16T18:29:52.538+0000] {task_command.py:423} INFO - Running <TaskInstance: stagingtodv.city scheduled__2024-07-15T00:00:00+00:00 [running]> on host 6c99a2e38d27
[2024-07-16T18:29:59.762+0000] {taskinstance.py:2513} INFO - Exporting env vars: AIRFLOW_CTX_DAG_OWNER='***' AIRFLOW_CTX_DAG_ID='stagingtodv' AIRFLOW_CTX_TASK_ID='city' AIRFLOW_CTX_EXECUTION_DATE='2024-07-15T00:00:00+00:00' AIRFLOW_CTX_TRY_NUMBER='1' AIRFLOW_CTX_DAG_RUN_ID='scheduled__2024-07-15T00:00:00+00:00'
[2024-07-16T18:29:59.843+0000] {logging_mixin.py:188} INFO - -------------------------------------------- select *  from etlconf.Etl_Process_Mapping where SourceTableName = 'city' and Stage = 'stagingtodv'
[2024-07-16T18:29:59.938+0000] {logging_mixin.py:188} INFO - select *  from etlconf.Etl_Process_Mapping where SourceTableName = 'city' and Stage = 'stagingtodv'
[2024-07-16T18:30:00.095+0000] {taskinstance.py:2731} ERROR - Task failed with exception
Traceback (most recent call last):
  File "/home/airflow/.local/lib/python3.8/site-packages/airflow/models/taskinstance.py", line 444, in _execute_task
    result = _execute_callable(context=context, **execute_callable_kwargs)
  File "/home/airflow/.local/lib/python3.8/site-packages/airflow/models/taskinstance.py", line 414, in _execute_callable
    return execute_callable(context=context, **execute_callable_kwargs)
  File "/home/airflow/.local/lib/python3.8/site-packages/airflow/operators/python.py", line 200, in execute
    return_value = self.execute_callable()
  File "/home/airflow/.local/lib/python3.8/site-packages/airflow/operators/python.py", line 217, in execute_callable
    return self.python_callable(*self.op_args, **self.op_kwargs)
  File "/opt/airflow/dags/dag.py", line 45, in process_table
    return  execute(table, stage, tabletype)
  File "/app/main.py", line 31, in execute
    (StagingToDV().create_full().some_function(table, stage))
  File "/app/concretestage/StagingToDV.py", line 36, in some_function
    sourceDF = getDF(sourcedbname,sourcetablename , sourceschema)
  File "/app/myFramework/utils/utils.py", line 29, in getDF
    cur.execute(query)
psycopg2.errors.UndefinedTable: missing FROM-clause entry for table "t"
LINE 1: select T.* from dbstaging.public.dada
               ^

[2024-07-16T18:30:00.198+0000] {taskinstance.py:1149} INFO - Marking task as FAILED. dag_id=stagingtodv, task_id=city, execution_date=20240715T000000, start_date=20240716T182951, end_date=20240716T183000
[2024-07-16T18:30:00.246+0000] {standard_task_runner.py:107} ERROR - Failed to execute job 10 for task city (missing FROM-clause entry for table "t"
LINE 1: select T.* from dbstaging.public.dada
               ^
; 93)
[2024-07-16T18:30:00.283+0000] {local_task_job_runner.py:234} INFO - Task exited with return code 1
[2024-07-16T18:30:00.341+0000] {taskinstance.py:3312} INFO - 0 downstream tasks scheduled from follow-on schedule check
[2024-07-16T18:33:54.314+0000] {taskinstance.py:1979} INFO - Dependencies all met for dep_context=non-requeueable deps ti=<TaskInstance: stagingtodv.city scheduled__2024-07-15T00:00:00+00:00 [queued]>
[2024-07-16T18:33:54.328+0000] {taskinstance.py:1979} INFO - Dependencies all met for dep_context=requeueable deps ti=<TaskInstance: stagingtodv.city scheduled__2024-07-15T00:00:00+00:00 [queued]>
[2024-07-16T18:33:54.341+0000] {taskinstance.py:2193} INFO - Starting attempt 1 of 1
[2024-07-16T18:33:54.402+0000] {taskinstance.py:2217} INFO - Executing <Task(PythonOperator): city> on 2024-07-15 00:00:00+00:00
[2024-07-16T18:33:54.474+0000] {standard_task_runner.py:60} INFO - Started process 107 to run task
[2024-07-16T18:33:54.474+0000] {standard_task_runner.py:87} INFO - Running: ['***', 'tasks', 'run', 'stagingtodv', 'city', 'scheduled__2024-07-15T00:00:00+00:00', '--job-id', '3', '--raw', '--subdir', 'DAGS_FOLDER/dag.py', '--cfg-path', '/tmp/tmppvjcvf7m']
[2024-07-16T18:33:54.503+0000] {standard_task_runner.py:88} INFO - Job 3: Subtask city
[2024-07-16T18:33:54.746+0000] {task_command.py:423} INFO - Running <TaskInstance: stagingtodv.city scheduled__2024-07-15T00:00:00+00:00 [running]> on host b7021158e377
[2024-07-16T18:33:56.470+0000] {taskinstance.py:2513} INFO - Exporting env vars: AIRFLOW_CTX_DAG_OWNER='***' AIRFLOW_CTX_DAG_ID='stagingtodv' AIRFLOW_CTX_TASK_ID='city' AIRFLOW_CTX_EXECUTION_DATE='2024-07-15T00:00:00+00:00' AIRFLOW_CTX_TRY_NUMBER='1' AIRFLOW_CTX_DAG_RUN_ID='scheduled__2024-07-15T00:00:00+00:00'
[2024-07-16T18:33:56.473+0000] {logging_mixin.py:188} INFO - -------------------------------------------- select *  from etlconf.Etl_Process_Mapping where SourceTableName = 'city' and Stage = 'stagingtodv'
[2024-07-16T18:33:56.503+0000] {logging_mixin.py:188} INFO - select *  from etlconf.Etl_Process_Mapping where SourceTableName = 'city' and Stage = 'stagingtodv'
[2024-07-16T18:33:56.612+0000] {taskinstance.py:2731} ERROR - Task failed with exception
Traceback (most recent call last):
  File "/home/airflow/.local/lib/python3.8/site-packages/airflow/models/taskinstance.py", line 444, in _execute_task
    result = _execute_callable(context=context, **execute_callable_kwargs)
  File "/home/airflow/.local/lib/python3.8/site-packages/airflow/models/taskinstance.py", line 414, in _execute_callable
    return execute_callable(context=context, **execute_callable_kwargs)
  File "/home/airflow/.local/lib/python3.8/site-packages/airflow/operators/python.py", line 200, in execute
    return_value = self.execute_callable()
  File "/home/airflow/.local/lib/python3.8/site-packages/airflow/operators/python.py", line 217, in execute_callable
    return self.python_callable(*self.op_args, **self.op_kwargs)
  File "/opt/airflow/dags/dag.py", line 45, in process_table
    return  execute(table, stage, tabletype)
  File "/app/main.py", line 31, in execute
    (StagingToDV().create_full().some_function(table, stage))
  File "/app/concretestage/StagingToDV.py", line 36, in some_function
    sourceDF = getDF(sourcedbname,sourcetablename , sourceschema)
  File "/app/myFramework/utils/utils.py", line 32, in getDF
    df.columns = [desc[0] for desc in cur.description]
  File "/home/airflow/.local/lib/python3.8/site-packages/pandas/core/generic.py", line 6002, in __setattr__
    return object.__setattr__(self, name, value)
  File "pandas/_libs/properties.pyx", line 69, in pandas._libs.properties.AxisProperty.__set__
  File "/home/airflow/.local/lib/python3.8/site-packages/pandas/core/generic.py", line 730, in _set_axis
    self._mgr.set_axis(axis, labels)
  File "/home/airflow/.local/lib/python3.8/site-packages/pandas/core/internals/managers.py", line 225, in set_axis
    self._validate_set_axis(axis, new_labels)
  File "/home/airflow/.local/lib/python3.8/site-packages/pandas/core/internals/base.py", line 70, in _validate_set_axis
    raise ValueError(
ValueError: Length mismatch: Expected axis has 0 elements, new values have 1 elements
[2024-07-16T18:33:56.647+0000] {taskinstance.py:1149} INFO - Marking task as FAILED. dag_id=stagingtodv, task_id=city, execution_date=20240715T000000, start_date=20240716T183354, end_date=20240716T183356
[2024-07-16T18:33:56.663+0000] {standard_task_runner.py:107} ERROR - Failed to execute job 3 for task city (Length mismatch: Expected axis has 0 elements, new values have 1 elements; 107)
[2024-07-16T18:33:56.703+0000] {local_task_job_runner.py:234} INFO - Task exited with return code 1
[2024-07-16T18:33:56.771+0000] {taskinstance.py:3312} INFO - 0 downstream tasks scheduled from follow-on schedule check
[2024-07-16T18:45:24.061+0000] {taskinstance.py:1979} INFO - Dependencies all met for dep_context=non-requeueable deps ti=<TaskInstance: stagingtodv.city scheduled__2024-07-15T00:00:00+00:00 [queued]>
[2024-07-16T18:45:24.104+0000] {taskinstance.py:1979} INFO - Dependencies all met for dep_context=requeueable deps ti=<TaskInstance: stagingtodv.city scheduled__2024-07-15T00:00:00+00:00 [queued]>
[2024-07-16T18:45:24.107+0000] {taskinstance.py:2193} INFO - Starting attempt 1 of 1
[2024-07-16T18:45:24.140+0000] {taskinstance.py:2217} INFO - Executing <Task(PythonOperator): city> on 2024-07-15 00:00:00+00:00
[2024-07-16T18:45:24.171+0000] {standard_task_runner.py:60} INFO - Started process 145 to run task
[2024-07-16T18:45:24.195+0000] {standard_task_runner.py:87} INFO - Running: ['***', 'tasks', 'run', 'stagingtodv', 'city', 'scheduled__2024-07-15T00:00:00+00:00', '--job-id', '31', '--raw', '--subdir', 'DAGS_FOLDER/dag.py', '--cfg-path', '/tmp/tmp97v1o089']
[2024-07-16T18:45:24.203+0000] {standard_task_runner.py:88} INFO - Job 31: Subtask city
[2024-07-16T18:45:24.448+0000] {task_command.py:423} INFO - Running <TaskInstance: stagingtodv.city scheduled__2024-07-15T00:00:00+00:00 [running]> on host 2e3dbb9eb862
[2024-07-16T18:45:25.114+0000] {taskinstance.py:2513} INFO - Exporting env vars: AIRFLOW_CTX_DAG_OWNER='***' AIRFLOW_CTX_DAG_ID='stagingtodv' AIRFLOW_CTX_TASK_ID='city' AIRFLOW_CTX_EXECUTION_DATE='2024-07-15T00:00:00+00:00' AIRFLOW_CTX_TRY_NUMBER='1' AIRFLOW_CTX_DAG_RUN_ID='scheduled__2024-07-15T00:00:00+00:00'
[2024-07-16T18:45:25.139+0000] {logging_mixin.py:188} INFO - -------------------------------------------- select *  from etlconf.Etl_Process_Mapping where SourceTableName = 'city' and Stage = 'stagingtodv'
[2024-07-16T18:45:25.260+0000] {logging_mixin.py:188} INFO - select *  from etlconf.Etl_Process_Mapping where SourceTableName = 'city' and Stage = 'stagingtodv'
[2024-07-16T18:45:25.915+0000] {python.py:202} INFO - Done. Returned value was: None
[2024-07-16T18:45:25.939+0000] {taskinstance.py:1149} INFO - Marking task as SUCCESS. dag_id=stagingtodv, task_id=city, execution_date=20240715T000000, start_date=20240716T184524, end_date=20240716T184525
[2024-07-16T18:45:26.035+0000] {local_task_job_runner.py:234} INFO - Task exited with return code 0
[2024-07-16T18:45:26.125+0000] {taskinstance.py:3312} INFO - 0 downstream tasks scheduled from follow-on schedule check
[2024-07-16T18:56:46.647+0000] {taskinstance.py:1979} INFO - Dependencies all met for dep_context=non-requeueable deps ti=<TaskInstance: stagingtodv.city scheduled__2024-07-15T00:00:00+00:00 [queued]>
[2024-07-16T18:56:46.670+0000] {taskinstance.py:1979} INFO - Dependencies all met for dep_context=requeueable deps ti=<TaskInstance: stagingtodv.city scheduled__2024-07-15T00:00:00+00:00 [queued]>
[2024-07-16T18:56:46.679+0000] {taskinstance.py:2193} INFO - Starting attempt 1 of 1
[2024-07-16T18:56:46.780+0000] {taskinstance.py:2217} INFO - Executing <Task(PythonOperator): city> on 2024-07-15 00:00:00+00:00
[2024-07-16T18:56:46.800+0000] {standard_task_runner.py:60} INFO - Started process 154 to run task
[2024-07-16T18:56:46.818+0000] {standard_task_runner.py:87} INFO - Running: ['***', 'tasks', 'run', 'stagingtodv', 'city', 'scheduled__2024-07-15T00:00:00+00:00', '--job-id', '30', '--raw', '--subdir', 'DAGS_FOLDER/dag.py', '--cfg-path', '/tmp/tmp067hm1no']
[2024-07-16T18:56:46.826+0000] {standard_task_runner.py:88} INFO - Job 30: Subtask city
[2024-07-16T18:56:46.907+0000] {task_command.py:423} INFO - Running <TaskInstance: stagingtodv.city scheduled__2024-07-15T00:00:00+00:00 [running]> on host 1733eeb0def3
[2024-07-16T18:56:47.142+0000] {taskinstance.py:2513} INFO - Exporting env vars: AIRFLOW_CTX_DAG_OWNER='***' AIRFLOW_CTX_DAG_ID='stagingtodv' AIRFLOW_CTX_TASK_ID='city' AIRFLOW_CTX_EXECUTION_DATE='2024-07-15T00:00:00+00:00' AIRFLOW_CTX_TRY_NUMBER='1' AIRFLOW_CTX_DAG_RUN_ID='scheduled__2024-07-15T00:00:00+00:00'
[2024-07-16T18:56:47.148+0000] {logging_mixin.py:188} INFO - -------------------------------------------- select *  from etlconf.Etl_Process_Mapping where SourceTableName = 'city' and Stage = 'stagingtodv'
[2024-07-16T18:56:47.184+0000] {logging_mixin.py:188} INFO - select *  from etlconf.Etl_Process_Mapping where SourceTableName = 'city' and Stage = 'stagingtodv'
[2024-07-16T18:56:47.530+0000] {taskinstance.py:2731} ERROR - Task failed with exception
Traceback (most recent call last):
  File "/home/airflow/.local/lib/python3.8/site-packages/sqlalchemy/engine/base.py", line 3371, in _wrap_pool_connect
    return fn()
  File "/home/airflow/.local/lib/python3.8/site-packages/sqlalchemy/pool/base.py", line 327, in connect
    return _ConnectionFairy._checkout(self)
  File "/home/airflow/.local/lib/python3.8/site-packages/sqlalchemy/pool/base.py", line 894, in _checkout
    fairy = _ConnectionRecord.checkout(pool)
  File "/home/airflow/.local/lib/python3.8/site-packages/sqlalchemy/pool/base.py", line 493, in checkout
    rec = pool._do_get()
  File "/home/airflow/.local/lib/python3.8/site-packages/sqlalchemy/pool/impl.py", line 146, in _do_get
    self._dec_overflow()
  File "/home/airflow/.local/lib/python3.8/site-packages/sqlalchemy/util/langhelpers.py", line 70, in __exit__
    compat.raise_(
  File "/home/airflow/.local/lib/python3.8/site-packages/sqlalchemy/util/compat.py", line 211, in raise_
    raise exception
  File "/home/airflow/.local/lib/python3.8/site-packages/sqlalchemy/pool/impl.py", line 143, in _do_get
    return self._create_connection()
  File "/home/airflow/.local/lib/python3.8/site-packages/sqlalchemy/pool/base.py", line 273, in _create_connection
    return _ConnectionRecord(self)
  File "/home/airflow/.local/lib/python3.8/site-packages/sqlalchemy/pool/base.py", line 388, in __init__
    self.__connect()
  File "/home/airflow/.local/lib/python3.8/site-packages/sqlalchemy/pool/base.py", line 691, in __connect
    pool.logger.debug("Error on connect(): %s", e)
  File "/home/airflow/.local/lib/python3.8/site-packages/sqlalchemy/util/langhelpers.py", line 70, in __exit__
    compat.raise_(
  File "/home/airflow/.local/lib/python3.8/site-packages/sqlalchemy/util/compat.py", line 211, in raise_
    raise exception
  File "/home/airflow/.local/lib/python3.8/site-packages/sqlalchemy/pool/base.py", line 686, in __connect
    self.dbapi_connection = connection = pool._invoke_creator(self)
  File "/home/airflow/.local/lib/python3.8/site-packages/sqlalchemy/engine/create.py", line 574, in connect
    return dialect.connect(*cargs, **cparams)
  File "/home/airflow/.local/lib/python3.8/site-packages/sqlalchemy/engine/default.py", line 598, in connect
    return self.dbapi.connect(*cargs, **cparams)
  File "/home/airflow/.local/lib/python3.8/site-packages/psycopg2/__init__.py", line 122, in connect
    conn = _connect(dsn, connection_factory=connection_factory, **kwasync)
psycopg2.OperationalError: connection to server at "postgres_db" (192.168.48.5), port 9999 failed: FATAL:  database "DBDV" does not exist


The above exception was the direct cause of the following exception:

Traceback (most recent call last):
  File "/home/airflow/.local/lib/python3.8/site-packages/airflow/models/taskinstance.py", line 444, in _execute_task
    result = _execute_callable(context=context, **execute_callable_kwargs)
  File "/home/airflow/.local/lib/python3.8/site-packages/airflow/models/taskinstance.py", line 414, in _execute_callable
    return execute_callable(context=context, **execute_callable_kwargs)
  File "/home/airflow/.local/lib/python3.8/site-packages/airflow/operators/python.py", line 200, in execute
    return_value = self.execute_callable()
  File "/home/airflow/.local/lib/python3.8/site-packages/airflow/operators/python.py", line 217, in execute_callable
    return self.python_callable(*self.op_args, **self.op_kwargs)
  File "/opt/airflow/dags/dag.py", line 45, in process_table
    return  execute(table, stage, tabletype)
  File "/app/main.py", line 31, in execute
    (StagingToDV().create_full().some_function(table, stage))
  File "/app/concretestage/StagingToDV.py", line 39, in some_function
    fillPosgres(sourceDF, DestDBName, DestSchema, DestTableName, InsertionType)
  File "/app/myFramework/utils/utils.py", line 36, in fillPosgres
    df.to_sql(tablename, conn.getEngine(dst_dbname)
  File "/home/airflow/.local/lib/python3.8/site-packages/pandas/core/generic.py", line 2878, in to_sql
    return sql.to_sql(
  File "/home/airflow/.local/lib/python3.8/site-packages/pandas/io/sql.py", line 768, in to_sql
    with pandasSQL_builder(con, schema=schema, need_transaction=True) as pandas_sql:
  File "/home/airflow/.local/lib/python3.8/site-packages/pandas/io/sql.py", line 832, in pandasSQL_builder
    return SQLDatabase(con, schema, need_transaction)
  File "/home/airflow/.local/lib/python3.8/site-packages/pandas/io/sql.py", line 1539, in __init__
    con = self.exit_stack.enter_context(con.connect())
  File "/home/airflow/.local/lib/python3.8/site-packages/sqlalchemy/engine/base.py", line 3325, in connect
    return self._connection_cls(self, close_with_result=close_with_result)
  File "/home/airflow/.local/lib/python3.8/site-packages/sqlalchemy/engine/base.py", line 96, in __init__
    else engine.raw_connection()
  File "/home/airflow/.local/lib/python3.8/site-packages/sqlalchemy/engine/base.py", line 3404, in raw_connection
    return self._wrap_pool_connect(self.pool.connect, _connection)
  File "/home/airflow/.local/lib/python3.8/site-packages/sqlalchemy/engine/base.py", line 3374, in _wrap_pool_connect
    Connection._handle_dbapi_exception_noconnection(
  File "/home/airflow/.local/lib/python3.8/site-packages/sqlalchemy/engine/base.py", line 2208, in _handle_dbapi_exception_noconnection
    util.raise_(
  File "/home/airflow/.local/lib/python3.8/site-packages/sqlalchemy/util/compat.py", line 211, in raise_
    raise exception
  File "/home/airflow/.local/lib/python3.8/site-packages/sqlalchemy/engine/base.py", line 3371, in _wrap_pool_connect
    return fn()
  File "/home/airflow/.local/lib/python3.8/site-packages/sqlalchemy/pool/base.py", line 327, in connect
    return _ConnectionFairy._checkout(self)
  File "/home/airflow/.local/lib/python3.8/site-packages/sqlalchemy/pool/base.py", line 894, in _checkout
    fairy = _ConnectionRecord.checkout(pool)
  File "/home/airflow/.local/lib/python3.8/site-packages/sqlalchemy/pool/base.py", line 493, in checkout
    rec = pool._do_get()
  File "/home/airflow/.local/lib/python3.8/site-packages/sqlalchemy/pool/impl.py", line 146, in _do_get
    self._dec_overflow()
  File "/home/airflow/.local/lib/python3.8/site-packages/sqlalchemy/util/langhelpers.py", line 70, in __exit__
    compat.raise_(
  File "/home/airflow/.local/lib/python3.8/site-packages/sqlalchemy/util/compat.py", line 211, in raise_
    raise exception
  File "/home/airflow/.local/lib/python3.8/site-packages/sqlalchemy/pool/impl.py", line 143, in _do_get
    return self._create_connection()
  File "/home/airflow/.local/lib/python3.8/site-packages/sqlalchemy/pool/base.py", line 273, in _create_connection
    return _ConnectionRecord(self)
  File "/home/airflow/.local/lib/python3.8/site-packages/sqlalchemy/pool/base.py", line 388, in __init__
    self.__connect()
  File "/home/airflow/.local/lib/python3.8/site-packages/sqlalchemy/pool/base.py", line 691, in __connect
    pool.logger.debug("Error on connect(): %s", e)
  File "/home/airflow/.local/lib/python3.8/site-packages/sqlalchemy/util/langhelpers.py", line 70, in __exit__
    compat.raise_(
  File "/home/airflow/.local/lib/python3.8/site-packages/sqlalchemy/util/compat.py", line 211, in raise_
    raise exception
  File "/home/airflow/.local/lib/python3.8/site-packages/sqlalchemy/pool/base.py", line 686, in __connect
    self.dbapi_connection = connection = pool._invoke_creator(self)
  File "/home/airflow/.local/lib/python3.8/site-packages/sqlalchemy/engine/create.py", line 574, in connect
    return dialect.connect(*cargs, **cparams)
  File "/home/airflow/.local/lib/python3.8/site-packages/sqlalchemy/engine/default.py", line 598, in connect
    return self.dbapi.connect(*cargs, **cparams)
  File "/home/airflow/.local/lib/python3.8/site-packages/psycopg2/__init__.py", line 122, in connect
    conn = _connect(dsn, connection_factory=connection_factory, **kwasync)
sqlalchemy.exc.OperationalError: (psycopg2.OperationalError) connection to server at "postgres_db" (192.168.48.5), port 9999 failed: FATAL:  database "DBDV" does not exist

(Background on this error at: https://sqlalche.me/e/14/e3q8)
[2024-07-16T18:56:47.539+0000] {taskinstance.py:1149} INFO - Marking task as FAILED. dag_id=stagingtodv, task_id=city, execution_date=20240715T000000, start_date=20240716T185646, end_date=20240716T185647
[2024-07-16T18:56:47.547+0000] {standard_task_runner.py:107} ERROR - Failed to execute job 30 for task city ((psycopg2.OperationalError) connection to server at "postgres_db" (192.168.48.5), port 9999 failed: FATAL:  database "DBDV" does not exist

(Background on this error at: https://sqlalche.me/e/14/e3q8); 154)
[2024-07-16T18:56:47.580+0000] {local_task_job_runner.py:234} INFO - Task exited with return code 1
[2024-07-16T18:56:47.590+0000] {taskinstance.py:3312} INFO - 0 downstream tasks scheduled from follow-on schedule check
[2024-07-16T19:01:11.860+0000] {taskinstance.py:1979} INFO - Dependencies all met for dep_context=non-requeueable deps ti=<TaskInstance: stagingtodv.city scheduled__2024-07-15T00:00:00+00:00 [queued]>
[2024-07-16T19:01:11.886+0000] {taskinstance.py:1979} INFO - Dependencies all met for dep_context=requeueable deps ti=<TaskInstance: stagingtodv.city scheduled__2024-07-15T00:00:00+00:00 [queued]>
[2024-07-16T19:01:11.890+0000] {taskinstance.py:2193} INFO - Starting attempt 1 of 1
[2024-07-16T19:01:11.920+0000] {taskinstance.py:2217} INFO - Executing <Task(PythonOperator): city> on 2024-07-15 00:00:00+00:00
[2024-07-16T19:01:11.941+0000] {standard_task_runner.py:60} INFO - Started process 82 to run task
[2024-07-16T19:01:11.952+0000] {standard_task_runner.py:87} INFO - Running: ['***', 'tasks', 'run', 'stagingtodv', 'city', 'scheduled__2024-07-15T00:00:00+00:00', '--job-id', '5', '--raw', '--subdir', 'DAGS_FOLDER/dag.py', '--cfg-path', '/tmp/tmphfd6xwc0']
[2024-07-16T19:01:11.966+0000] {standard_task_runner.py:88} INFO - Job 5: Subtask city
[2024-07-16T19:01:12.180+0000] {task_command.py:423} INFO - Running <TaskInstance: stagingtodv.city scheduled__2024-07-15T00:00:00+00:00 [running]> on host ef8b8dee6045
[2024-07-16T19:01:13.561+0000] {taskinstance.py:2513} INFO - Exporting env vars: AIRFLOW_CTX_DAG_OWNER='***' AIRFLOW_CTX_DAG_ID='stagingtodv' AIRFLOW_CTX_TASK_ID='city' AIRFLOW_CTX_EXECUTION_DATE='2024-07-15T00:00:00+00:00' AIRFLOW_CTX_TRY_NUMBER='1' AIRFLOW_CTX_DAG_RUN_ID='scheduled__2024-07-15T00:00:00+00:00'
[2024-07-16T19:01:13.566+0000] {logging_mixin.py:188} INFO - -------------------------------------------- select *  from etlconf.Etl_Process_Mapping where SourceTableName = 'city' and Stage = 'stagingtodv'
[2024-07-16T19:01:13.662+0000] {logging_mixin.py:188} INFO - select *  from etlconf.Etl_Process_Mapping where SourceTableName = 'city' and Stage = 'stagingtodv'
[2024-07-16T19:01:13.852+0000] {logging_mixin.py:188} INFO - update etlconf.Etl_Process_Mapping T set last_run_date = current_timestamp where destdbname='dbdv' and destschema='dvdrental' and desttablename='city';
[2024-07-16T19:01:13.868+0000] {python.py:202} INFO - Done. Returned value was: None
[2024-07-16T19:01:13.877+0000] {taskinstance.py:1149} INFO - Marking task as SUCCESS. dag_id=stagingtodv, task_id=city, execution_date=20240715T000000, start_date=20240716T190111, end_date=20240716T190113
[2024-07-16T19:01:13.897+0000] {local_task_job_runner.py:234} INFO - Task exited with return code 0
[2024-07-16T19:01:13.921+0000] {taskinstance.py:3312} INFO - 0 downstream tasks scheduled from follow-on schedule check
